Workbook

Sheet I.S
A1: ($ in millions, except per share) | B1: 2021 | C1: =B1+1 -> 2022 | D1: =C1+1 -> 2023 | E1: =D1+1 -> 2024 | F1: =E1+1 -> 2025 | G1: =F1+1 -> 2026 | H1: =G1+1 -> 2027 | I1: =H1+1 -> 2028 | J1: =I1+1 -> 2029 | K1: =J1+1 -> 2030 | N1: 4yr CAGR
A2: Revenue | B2: 365817 | C2: 394328 | D2: 383285 | E2: 391035 | F2: 416161 | G2: =F2*(1+G3) -> 476920.51 | H2: =G2*(1+H3) -> 505535.74 | I2: =H2*(1+I3) -> 533340.2 | J2: =I2*(1+J3) -> 560007.21 | K2: =J2*(1+K3) -> 585207.54 | N2: =IFERROR((F2/B2)^(1/4)-1,"") -> 0.032759916
A3: % Growth | C3: =C2/B2-1 -> 0.077937876 | D3: =D2/C2-1 -> -0.028004605 | E3: =E2/D2-1 -> 0.020219941 | F3: =F2/E2-1 -> 0.064255118 | G3: 0.146 | H3: 0.06 | I3: 0.055 | J3: 0.05 | K3: 0.045
A4: Cost of sales | B4: -212981 | C4: -223546 | D4: -214137 | E4: -210352 | F4: -220960 | G4: =-(G2*G5) -> -245137.14 | H4: =-(H2*H5) -> -265406.26 | I4: =-(I2*I5) -> -280003.61 | J4: =-(J2*J5) -> -294003.79 | K4: =-(K2*K5) -> -307233.96
A5: % of Revenue | B5: =-B4/B2 -> 0.5822064 | C5: =-C4/C2 -> 0.56690369 | D5: =-D4/D2 -> 0.5586887 | E5: =-E4/E2 -> 0.5379365 | F5: =-F4/F2 -> 0.53094836 | G5: 0.514 | H5: 0.525 | I5: 0.525 | J5: 0.525 | K5: 0.525
A6: Gross margin | B6: =B2+B4 -> 152836 | C6: =C2+C4 -> 170782 | D6: =D2+D4 -> 169148 | E6: =E2+E4 -> 180683 | F6: =F2+F4 -> 195201 | G6: =G2+G4 -> 231783.37 | H6: =H2+H4 -> 240129.47 | I6: =I2+I4 -> 253336.6 | ... K6: =K2+K4 -> 277973.58
A7: % of Revenue | B7: =B6/B2 -> 0.4177936 | C7: =C6/C2 -> 0.43309631 | D7: =D6/D2 -> 0.4413113 | E7: =E6/E2 -> 0.4620635 | F7: =F6/F2 -> 0.46905164 | G7: =G6/G2 -> 0.486 | H7: =H6/H2 -> 0.475 | I7: =I6/I2 -> 0.475 | ... K7: =K6/K2 -> 0.475
A9: Research and development | B9: -21914 | C9: -26251 | D9: -29915 | E9: -31370 | F9: -34550 | G9: =-(G2*G10) -> -44353.607 | H9: =-(H2*H10) -> -47014.823 | I9: =-(I2*I10) -> -49600.639 | J9: =-(J2*J10) -> -52080.671 | K9: =-(K2*K10) -> -54424.301 | N9: =IFERROR((F9/B9)^(1/4)-1,"") -> 0.12055093
A10: % of Revenue | B10: =-B9/B2 -> 0.059904269 | C10: =-C9/C2 -> 0.066571484 | D10: =-D9/D2 -> 0.078048971 | E10: =-E9/E2 -> 0.080222998 | F10: =-F9/F2 -> 0.083020754 | G10: 0.093 | H10: 0.093 | I10: 0.093 | J10: 0.093 | K10: 0.093
A11: Selling, general and administrative | B11: -21973 | C11: -25094 | D11: -24932 | E11: -26097 | F11: -27601 | G11: =-(G2*G12) -> -30999.833 | H11: =-(H2*H12) -> -32859.823 | I11: =-(I2*I12) -> -34667.113 | J11: =-(J2*J12) -> -36400.469 | K11: =-(K2*K12) -> -38038.49 | N11: =IFERROR((F11/B11)^(1/4)-1,"") -> 0.058665756
A12: % of Revenue | B12: =-B11/B2 -> 0.060065552 | C12: =-C11/C2 -> 0.063637378 | D12: =-D11/D2 -> 0.065048202 | E12: =-E11/E2 -> 0.066738272 | F12: =-F11/F2 -> 0.066322889 | G12: 0.065 | H12: 0.065 | I12: 0.065 | J12: 0.065 | K12: 0.065
A13: Total Operating Expenses | B13: =B9+B11 -> -43887 | C13: =C9+C11 -> -51345 | D13: =D9+D11 -> -54847 | E13: =E9+E11 -> -57467 | F13: =F9+F11 -> -62151 | G13: =G9+G11 -> -75353.44 | H13: =H9+H11 -> -79874.646 | I13: =I9+I11 -> -84267.752 | ... K13: =K9+K11 -> -92462.791
A14: % of Revenue | B14: =-B13/B2 -> 0.11996982 | C14: =-C13/C2 -> 0.13020886 | D14: =-D13/D2 -> 0.14309717 | E14: =-E13/E2 -> 0.14696127 | F14: =-F13/F2 -> 0.14934364 | G14: =-G13/G2 -> 0.158 | H14: =-H13/H2 -> 0.158 | I14: =-I13/I2 -> 0.158 | ... K14: =-K13/K2 -> 0.158
A15: EBIT (Operating income) | B15: =B6+B13 -> 108949 | C15: =C6+C13 -> 119437 | D15: =D6+D13 -> 114301 | E15: =E6+E13 -> 123216 | F15: =F6+F13 -> 133050 | G15: =G6+G13 -> 156429.93 | H15: =H6+H13 -> 160254.83 | I15: =I6+I13 -> 169068.84 | ... K15: =K6+K13 -> 185510.79 | N15: =IFERROR((F15/B15)^(1/4)-1,"") -> 0.051230391
A16: % of Revenue | B16: =B15/B2 -> 0.29782378 | C16: =C15/C2 -> 0.30288744 | D16: =D15/D2 -> 0.29821412 | E16: =E15/E2 -> 0.31510223 | F16: =F15/F2 -> 0.319708 | G16: =G15/G2 -> 0.328 | H16: =H15/H2 -> 0.317 | I16: =I15/I2 -> 0.317 | ... K16: =K15/K2 -> 0.317
A18: Depreciation & amortization (embedded in costs above) | B18: ='C.S'!B4 -> 11284 | C18: ='C.S'!C4 -> 11104 | D18: ='C.S'!D4 -> 11519 | E18: ='C.S'!E4 -> 11445 | F18: ='C.S'!F4 -> 11698 | G18: ='C.S'!G4 -> 11450.553 | H18: ='C.S'!H4 -> 13135.672 | I18: ='C.S'!I4 -> 14913.472 | ... K18: ='C.S'!K4 -> 18730.855
A19: % of Revenue | B19: =B18/B2 -> 0.030846024 | C19: =C18/C2 -> 0.028159299 | D19: =D18/D2 -> 0.030053355 | E19: =E18/E2 -> 0.02926848 | F19: =F18/F2 -> 0.028109313 | G19: =G18/G2 -> 0.024009353 | H19: =H18/H2 -> 0.025983666 | I19: =I18/I2 -> 0.027962401 | ... K19: =K18/K2 -> 0.032007201
A20: EBITDA (EBIT + D&A) | B20: =B15+B18 -> 120233 | C20: =C15+C18 -> 130541 | D20: =D15+D18 -> 125820 | E20: =E15+E18 -> 134661 | F20: =F15+F18 -> 144748 | G20: =G15+G18 -> 167880.48 | H20: =H15+H18 -> 173390.5 | I20: =I15+I18 -> 183982.32 | ... K20: =K15+K18 -> 204241.64
A21: % of Revenue | B21: =B20/B2 -> 0.3286698 | C21: =C20/C2 -> 0.33104674 | D21: =D20/D2 -> 0.32826748 | E21: =E20/E2 -> 0.34437071 | F21: =F20/F2 -> 0.34781731 | G21: =G20/G2 -> 0.35200935 | H21: =H20/H2 -> 0.34298367 | I21: =I20/I2 -> 0.3449624 | ... K21: =K20/K2 -> 0.3490072
A23: Other income/(expense), net | B23: 258 | C23: -334 | D23: -565 | E23: 269 | F23: -321 | G23: ='Debt Schedule'!G30-'Debt Schedule'!G28 -> 1224.3135 | H23: ='Debt Schedule'!H30-'Debt Schedule'!H28 -> 1572.3481 | I23: ='Debt Schedule'!I30-'Debt Schedule'!I28 -> 2064.5731 | J23: ='Debt Schedule'!J30-'Debt Schedule'!J28 -> 2585.2548 | K23: ='Debt Schedule'!K30-'Debt Schedule'!K28 -> 3135.5174
A24: INCOME BEFORE PROVISION FOR INCOME TAXES | B24: =B15+B23 -> 109207 | C24: =C15+C23 -> 119103 | D24: =D15+D23 -> 113736 | E24: =E15+E23 -> 123485 | F24: =F15+F23 -> 132729 | G24: =G15+G23 -> 157654.24 | H24: =H15+H23 -> 161827.18 | I24: =I15+I23 -> 171133.42 | ... K24: =K15+K23 -> 188646.31
A25: % of Revenue | B25: =B24/B2 -> 0.29852905 | C25: =C24/C2 -> 0.30204043 | D25: =D24/D2 -> 0.29674002 | E25: =E24/E2 -> 0.31579015 | F25: =F24/F2 -> 0.31893666 | G25: =G24/G2 -> 0.33056712 | H25: =H24/H2 -> 0.32011026 | I25: =I24/I2 -> 0.32087102 | ... K25: =K24/K2 -> 0.32235796
A27: PROVISION FOR INCOME TAXES | B27: -14527 | C27: -19300 | D27: -16741 | E27: -29749 | F27: -20719 | G27: =-(G28*G24) -> -26801.221 | H27: =-(H28*H24) -> -27510.62 | I27: =-(I28*I24) -> -29092.681 | J27: =-(J28*J24) -> -30618.282 | K27: =-(K28*K24) -> -32069.872
A28: Tax Rate | B28: =-B27/B24 -> 0.13302261 | C28: =-C27/C24 -> 0.16204462 | D28: =-D27/D24 -> 0.14719174 | E28: =-E27/E24 -> 0.24091185 | F28: =-F27/F24 -> 0.15610002 | G28: 0.17 | H28: 0.17 | I28: 0.17 | J28: 0.17 | K28: 0.17
A29: NET INCOME | B29: =B24+B27 -> 94680 | C29: =C24+C27 -> 99803 | D29: =D24+D27 -> 96995 | E29: =E24+E27 -> 93736 | F29: =F24+F27 -> 112010 | G29: =G24+G27 -> 130853.02 | H29: =H24+H27 -> 134316.56 | I29: =I24+I27 -> 142040.74 | ... K29: =K24+K27 -> 156576.43 | N29: =IFERROR((F29/B29)^(1/4)-1,"") -> 0.042916737
A30: % of Revenue | B30: =B29/B2 -> 0.25881793 | C30: =C29/C2 -> 0.25309641 | D30: =D29/D2 -> 0.25306234 | E30: =E29/E2 -> 0.23971256 | F30: =F29/F2 -> 0.26915064 | G30: =G29/G2 -> 0.27437071 | H30: =H29/H2 -> 0.26569152 | I30: =I29/I2 -> 0.26632295 | ... K30: =K29/K2 -> 0.26755711
A32: EARNINGS PER SHARE ($)
A33: Basic | B33: =B29/B37 -> 5.6691216 | C33: =C29/C37 -> 6.1546004 | D33: =D29/D37 -> 6.1607597 | E33: =E29/E37 -> 6.1089677 | F33: =F29/F37 -> 7.4928089 | G33: =G29/G37 -> 8.9502002 | H33: =H29/H37 -> 9.3937651 | I33: =I29/I37 -> 10.157439 | ... K33: =K29/K37 -> 11.706309
A34: Diluted | B34: =B29/B38 -> 5.6139935 | C34: =C29/C38 -> 6.1131324 | D34: =D29/D38 -> 6.1338772 | E34: =E29/E38 -> 6.0835929 | F34: =F29/F38 -> 7.4648451 | G34: =G29/G38 -> 8.9167972 | H34: =H29/H38 -> 9.3587068 | I34: =I29/I38 -> 10.11953 | ... K34: =K29/K38 -> 11.66262
A36: WEIGHTED AVERAGE SHARES (millions)
A37: Basic | B37: 16701 | C37: 16216 | D37: 15744 | E37: 15344 | F37: 14949 | G37: =F37*(1+G39) -> 14620.122 | H37: =G37*(1+H39) -> 14298.479 | I37: =H37*(1+I39) -> 13983.913 | J37: =I37*(1+J39) -> 13676.267 | K37: =J37*(1+K39) -> 13375.389
A38: Diluted | B38: 16865 | C38: 16326 | D38: 15813 | E38: 15408 | F38: 15005 | G38: =F38*(1+G39) -> 14674.89 | H38: =G38*(1+H39) -> 14352.042 | I38: =H38*(1+I39) -> 14036.297 | J38: =I38*(1+J39) -> 13727.499 | K38: =J38*(1+K39) -> 13425.494
A39: % change in shares (buybacks) | C39: =C38/B38-1 -> -0.03195968 | D39: =D38/C38-1 -> -0.031422271 | E39: =E38/D38-1 -> -0.025611838 | F39: =F38/E38-1 -> -0.026155244 | G39: -0.022 | H39: -0.022 | I39: -0.022 | J39: -0.022 | K39: -0.022

Sheet C.S
A1: ($ in millions) | B1: 2021 | C1: =B1+1 -> 2022 | D1: =C1+1 -> 2023 | E1: =D1+1 -> 2024 | F1: =E1+1 -> 2025 | G1: =F1+1 -> 2026 | H1: =G1+1 -> 2027 | I1: =H1+1 -> 2028 | J1: =I1+1 -> 2029 | K1: =J1+1 -> 2030
A2: OPERATING ACTIVITIES
A3: Net income | B3: =I.S!B29 -> 94680 | C3: =I.S!C29 -> 99803 | D3: =I.S!D29 -> 96995 | E3: =I.S!E29 -> 93736 | F3: =I.S!F29 -> 112010 | G3: =I.S!G29 -> 130853.02 | H3: =I.S!H29 -> 134316.56 | I3: =I.S!I29 -> 142040.74 | ... K3: =I.S!K29 -> 156576.43
A4: Depreciation and amortization | B4: 11284 | C4: 11104 | D4: 11519 | E4: 11445 | F4: 11698 | G4: ='Depreciation Schedule'!I19 -> 11450.553 | H4: ='Depreciation Schedule'!J19 -> 13135.672 | I4: ='Depreciation Schedule'!K19 -> 14913.472 | J4: ='Depreciation Schedule'!L19 -> 16780.163 | K4: ='Depreciation Schedule'!M19 -> 18730.855
A5: Share-based compensation | B5: 7906 | C5: 9038 | D5: 10833 | E5: 11688 | F5: 12863 | G5: =G6*I.S!G2 -> 13830.695 | H5: =H6*I.S!H2 -> 14660.536 | I5: =I6*I.S!I2 -> 15466.866 | J5: =J6*I.S!J2 -> 16240.209 | K5: =K6*I.S!K2 -> 16971.019
A6: % of revenue | B6: =B5/I.S!B2 -> 0.021611899 | C6: =C5/I.S!C2 -> 0.022920006 | D6: =D5/I.S!D2 -> 0.028263564 | E6: =E5/I.S!E2 -> 0.029889908 | F6: =F5/I.S!F2 -> 0.030908711 | G6: 0.029 | H6: 0.029 | I6: 0.029 | J6: 0.029 | K6: 0.029
A7: Deferred income taxes (projected; included in 'Other' historically) | B7: 0 | C7: 0 | D7: 0 | E7: 0 | F7: 0 | G7: ='Depreciation Schedule'!I40 -> 72.165279 | H7: ='Depreciation Schedule'!J40 -> 385.67886 | I7: ='Depreciation Schedule'!K40 -> 576.21553 | J7: ='Depreciation Schedule'!L40 -> 650.466 | K7: ='Depreciation Schedule'!M40 -> 636.52644
A8: Other operating items | B8: -4921 | C8: 1006 | D8: -2227 | E8: -2266 | F8: -89 | G8: 0 | H8: 0 | I8: 0 | J8: 0 | K8: 0
A9: Changes in operating assets and liabilities:
A10: Accounts receivable | B10: -10125 | C10: -1823 | D10: -1688 | E10: -3788 | F10: -6682 | G10: =-('Working Capital Schedule'!G4-'Working Capital Schedule'!F4) -> -1239.4063 | H10: =-('Working Capital Schedule'!H4-'Working Capital Schedule'!G4) -> -2460.9844 | I10: =-('Working Capital Schedule'!I4-'Working Capital Schedule'!H4) -> -2391.2565 | J10: =-('Working Capital Schedule'!J4-'Working Capital Schedule'!I4) -> -2293.4324 | K10: =-('Working Capital Schedule'!K4-'Working Capital Schedule'!J4) -> -2167.2936
A11: Inventories | B11: -2642 | C11: 1484 | D11: -1618 | E11: -1046 | F11: 1400 | G11: =-('Working Capital Schedule'!G8-'Working Capital Schedule'!F8) -> -1642.6799 | H11: =-('Working Capital Schedule'!H8-'Working Capital Schedule'!G8) -> -608.61653 | I11: =-('Working Capital Schedule'!I8-'Working Capital Schedule'!H8) -> -438.3113 | J11: =-('Working Capital Schedule'!J8-'Working Capital Schedule'!I8) -> -420.38039 | K11: =-('Working Capital Schedule'!K8-'Working Capital Schedule'!J8) -> -397.25947
A12: Accounts payable | B12: 12326 | C12: 9448 | D12: -1889 | E12: 6020 | F12: 902 | G12: ='Working Capital Schedule'!G14-'Working Capital Schedule'!F14 -> 6654.2347 | H12: ='Working Capital Schedule'!H14-'Working Capital Schedule'!G14 -> 6326.5661 | I12: ='Working Capital Schedule'!I14-'Working Capital Schedule'!H14 -> 4556.244 | J12: ='Working Capital Schedule'!J14-'Working Capital Schedule'!I14 -> 4369.8522 | K12: ='Working Capital Schedule'!K14-'Working Capital Schedule'!J14 -> 4129.5104
A13: Other operating assets and liabilities, net | B13: -4470 | C13: -7909 | D13: -1382 | E13: 2465 | F13: -20620 | G13: =-('Working Capital Schedule'!G6-'Working Capital Schedule'!F6)-('Working Capital Schedule'!G10-'Working Capital Schedule'!F10)+('Working Capital Schedule'!G16-'Working Capital Schedule'!F16)+('Working Capital Schedule'!G18-'Working Capital Schedule'!F18) -> -6699.7744 | H13: =-('Working Capital Schedule'!H6-'Working Capital Schedule'!G6)-('Working Capital Schedule'!H10-'Working Capital Schedule'!G10)+('Working Capital Schedule'!H16-'Working Capital Schedule'!G16)+('Working Capital Schedule'!H18-'Working Capital Schedule'!G18) -> 418.48714 | I13: =-('Working Capital Schedule'!I6-'Working Capital Schedule'!H6)-('Working Capital Schedule'!I10-'Working Capital Schedule'!H10)+('Working Capital Schedule'!I16-'Working Capital Schedule'!H16)+('Working Capital Schedule'!I18-'Working Capital Schedule'!H18) -> 1176.7642 | J13: =-('Working Capital Schedule'!J6-'Working Capital Schedule'!I6)-('Working Capital Schedule'!J10-'Working Capital Schedule'!I10)+('Working Capital Schedule'!J16-'Working Capital Schedule'!I16)+('Working Capital Schedule'!J18-'Working Capital Schedule'!I18) -> 1128.6238 | K13: =-('Working Capital Schedule'!K6-'Working Capital Schedule'!J6)-('Working Capital Schedule'!K10-'Working Capital Schedule'!J10)+('Working Capital Schedule'!K16-'Working Capital Schedule'!J16)+('Working Capital Schedule'!K18-'Working Capital Schedule'!J18) -> 1066.5495
A14: Net change in operating assets and liabilities | B14: =SUM(B10:B13) -> -4911 | C14: =SUM(C10:C13) -> 1200 | D14: =SUM(D10:D13) -> -6577 | E14: =SUM(E10:E13) -> 3651 | F14: =SUM(F10:F13) -> -25000 | G14: =SUM(G10:G13) -> -2927.6259 | H14: =SUM(H10:H13) -> 3675.4523 | I14: =SUM(I10:I13) -> 2903.4405 | ... K14: =SUM(K10:K13) -> 2631.5069
A15: Cash generated by operating activities | B15: =B3+B4+B5+B7+B8+B14 -> 104038 | C15: =C3+C4+C5+C7+C8+C14 -> 122151 | D15: =D3+D4+D5+D7+D8+D14 -> 110543 | E15: =E3+E4+E5+E7+E8+E14 -> 118254 | F15: =F3+F4+F5+F7+F8+F14 -> 111482 | G15: =G3+G4+G5+G7+G8+G14 -> 153278.81 | H15: =H3+H4+H5+H7+H8+H14 -> 166173.9 | I15: =I3+I4+I5+I7+I8+I14 -> 175900.73 | ... K15: =K3+K4+K5+K7+K8+K14 -> 195546.34
A17: INVESTING ACTIVITIES
A18: Capital expenditures | B18: -11085 | C18: -10708 | D18: -10959 | E18: -9447 | F18: -12715 | G18: =-G19*I.S!G2 -> -13353.774 | H18: =-H19*I.S!H2 -> -15166.072 | I18: =-I19*I.S!I2 -> -16000.206 | J18: =-J19*I.S!J2 -> -16800.216 | K18: =-K19*I.S!K2 -> -17556.226
A19: % of revenue | B19: =-B18/I.S!B2 -> 0.030302036 | C19: =-C18/I.S!C2 -> 0.027155059 | D19: =-D18/I.S!D2 -> 0.028592301 | E19: =-E18/I.S!E2 -> 0.024158963 | F19: =-F18/I.S!F2 -> 0.030553079 | G19: 0.028 | H19: 0.03 | I19: 0.03 | J19: 0.03 | K19: 0.03
A20: Net (purchases)/sales of marketable securities | B20: -3075 | C20: -9560 | D20: 16001 | E20: 13690 | F20: 29390 | G20: 0 | H20: 0 | I20: 0 | J20: 0 | K20: 0
A21: Other investing activities | B21: -385 | C21: -2086 | D21: -1337 | E21: -1308 | F21: -1480 | G21: 0 | H21: 0 | I21: 0 | J21: 0 | K21: 0
A22: Cash from/(used in) investing activities | B22: =B18+B20+B21 -> -14545 | C22: =C18+C20+C21 -> -22354 | D22: =D18+D20+D21 -> 3705 | E22: =E18+E20+E21 -> 2935 | F22: =F18+F20+F21 -> 15195 | G22: =G18+G20+G21 -> -13353.774 | H22: =H18+H20+H21 -> -15166.072 | I22: =I18+I20+I21 -> -16000.206 | ... K22: =K18+K20+K21 -> -17556.226
A24: FINANCING ACTIVITIES
A25: Net debt issued/(repaid) | B25: 12665 | C25: -123 | D25: -9901 | E25: -5998 | F25: -8483 | G25: ='Debt Schedule'!G27 -> -18329 | H25: ='Debt Schedule'!H27 -> -9000 | I25: ='Debt Schedule'!I27 -> -9000 | J25: ='Debt Schedule'!J27 -> -9000 | K25: ='Debt Schedule'!K27 -> -9000
A26: Repurchases of common stock (incl. net share settlement) | B26: -92527 | C26: -95625 | D26: -82981 | E26: -100390 | F26: -96671 | G26: =-(G30*G40+G27) -> -110423.5 | H26: =-(H30*H40+H27) -> -120132.5 | I26: =-(I30*I40+I27) -> -127865.87 | J26: =-(J30*J40+J27) -> -135910.81 | K26: =-(K30*K40+K27) -> -143592.43
A27: Dividends paid | B27: -14467 | C27: -14841 | D27: -15025 | E27: -15234 | F27: -15421 | G27: =-(G28*I.S!G37) -> -15509.025 | H27: =-(H28*I.S!H37) -> -15774.54 | I27: =-(I28*I.S!I37) -> -16044.6 | J27: =-(J28*I.S!J37) -> -16319.284 | K27: =-(K28*I.S!K37) -> -16598.67
A28: Dividend per share ($) | B28: 0.85 | C28: 0.9 | D28: 0.94 | E28: 0.98 | F28: 1.02 | G28: =F28*(1+G29) -> 1.0608 | H28: =G28*(1+H29) -> 1.103232 | I28: =H28*(1+I29) -> 1.1473613 | J28: =I28*(1+J29) -> 1.1932557 | K28: =J28*(1+K29) -> 1.240986
A29: % growth | C29: =C28/B28-1 -> 0.058823529 | D29: =D28/C28-1 -> 0.044444444 | E29: =E28/D28-1 -> 0.042553191 | F29: =F28/E28-1 -> 0.040816327 | G29: 0.04 | H29: 0.04 | I29: 0.04 | J29: 0.04 | K29: 0.04
A30: Cash returned to shareholders as % of FCF | B30: =-(B26+B27)/B40 -> 1.1510548 | C30: =-(C26+C27)/C40 -> 0.99123319 | D30: =-(D26+D27)/D40 -> 0.98415408 | E30: =-(E26+E27)/E40 -> 1.0626522 | F30: =-(F26+F27)/F40 -> 1.1349135 | G30: 0.9 | H30: 0.9 | I30: 0.9 | J30: 0.9 | K30: 0.9
A31: Other financing activities | B31: 976 | C31: -160 | D31: -581 | E31: -361 | F31: -111 | G31: 0 | H31: 0 | I31: 0 | J31: 0 | K31: 0
A32: Cash used in financing activities | B32: =B25+B26+B27+B31 -> -93353 | C32: =C25+C26+C27+C31 -> -110749 | D32: =D25+D26+D27+D31 -> -108488 | E32: =E25+E26+E27+E31 -> -121983 | F32: =F25+F26+F27+F31 -> -120686 | G32: =G25+G26+G27+G31 -> -144261.53 | H32: =H25+H26+H27+H31 -> -144907.04 | I32: =I25+I26+I27+I31 -> -152910.47 | ... K32: =K25+K26+K27+K31 -> -169191.1
A34: NET INCREASE/(DECREASE) IN CASH, CASH EQUIVALENTS & RESTRICTED CASH | B34: =B15+B22+B32 -> -3860 | C34: =C15+C22+C32 -> -10952 | D34: =D15+D22+D32 -> 5760 | E34: =E15+E22+E32 -> -794 | F34: =F15+F22+F32 -> 5991 | G34: =G15+G22+G32 -> -4336.4969 | H34: =H15+H22+H32 -> 6100.7824 | I34: =I15+I22+I32 -> 6990.0524 | ... K34: =K15+K22+K32 -> 8799.0115
A36: CASH, CASH EQUIVALENTS & RESTRICTED CASH AT BEGINNING OF PERIOD | B36: 39789 | C36: =B37 -> 35929 | D36: =C37 -> 24977 | E36: =D37 -> 30737 | F36: =E37 -> 29943 | G36: =F37 -> 35934 | H36: =G37 -> 31597.503 | I36: =H37 -> 37698.286 | J36: =I37 -> 44688.338 | K36: =J37 -> 52602.792
A37: CASH, CASH EQUIVALENTS & RESTRICTED CASH AT END OF PERIOD | B37: =B36+B34 -> 35929 | C37: =C36+C34 -> 24977 | D37: =D36+D34 -> 30737 | E37: =E36+E34 -> 29943 | F37: =F36+F34 -> 35934 | G37: =G36+G34 -> 31597.503 | H37: =H36+H34 -> 37698.286 | I37: =I36+I34 -> 44688.338 | ... K37: =K36+K34 -> 61401.804
A39: SUPPLEMENTARY DATA
A40: Free cash flow (operating cash flow + capex) | B40: =B15+B18 -> 92953 | C40: =C15+C18 -> 111443 | D40: =D15+D18 -> 99584 | E40: =E15+E18 -> 108807 | F40: =F15+F18 -> 98767 | G40: =G15+G18 -> 139925.03 | H40: =H15+H18 -> 151007.82 | I40: =I15+I18 -> 159900.52 | ... K40: =K15+K18 -> 177990.12
A41: Cash flow before debt issuance/(repayment) | B41: =B34-B25 -> -16525 | C41: =C34-C25 -> -10829 | D41: =D34-D25 -> 15661 | E41: =E34-E25 -> 5204 | F41: =F34-F25 -> 14474 | G41: =G34-G25 -> 13992.503 | H41: =H34-H25 -> 15100.782 | I41: =I34-I25 -> 15990.052 | ... K41: =K34-K25 -> 17799.012

Sheet B.S
A1: ($ in millions) | B1: 2022 | C1: =B1+1 -> 2023 | D1: =C1+1 -> 2024 | E1: =D1+1 -> 2025 | F1: =E1+1 -> 2026 | G1: =F1+1 -> 2027 | H1: =G1+1 -> 2028 | I1: =H1+1 -> 2029 | J1: =I1+1 -> 2030
A2: Assets
A3: Cash and cash equivalents | B3: 23646 | C3: 29965 | D3: 29943 | E3: 35934 | F3: =E3+'C.S'!G34 -> 31597.503 | G3: =F3+'C.S'!H34 -> 37698.286 | H3: =G3+'C.S'!I34 -> 44688.338 | I3: =H3+'C.S'!J34 -> 52602.792 | J3: =I3+'C.S'!K34 -> 61401.804
A4: Short-term marketable securities | B4: 24658 | C4: 31590 | D4: 35228 | E4: 18763 | F4: =E4 -> 18763 | G4: =F4 -> 18763 | H4: =G4 -> 18763 | I4: =H4 -> 18763 | J4: =I4 -> 18763
A5: Accounts receivable, net | B5: 28184 | C5: 29508 | D5: 33410 | E5: 39777 | F5: ='Working Capital Schedule'!G4 -> 41016.406 | G5: ='Working Capital Schedule'!H4 -> 43477.391 | H5: ='Working Capital Schedule'!I4 -> 45868.647 | I5: ='Working Capital Schedule'!J4 -> 48162.08 | J5: ='Working Capital Schedule'!K4 -> 50329.373
A6: Other receivables (vendor non-trade) | B6: 32748 | C6: 31477 | D6: 32833 | E6: 33180 | F6: ='Working Capital Schedule'!G6 -> 37035.613 | G6: ='Working Capital Schedule'!H6 -> 40097.896 | H6: ='Working Capital Schedule'!I6 -> 42303.28 | I6: ='Working Capital Schedule'!J6 -> 44418.444 | J6: ='Working Capital Schedule'!K6 -> 46417.274
A7: Inventories | B7: 4946 | C7: 6331 | D7: 7286 | E7: 5718 | F7: ='Working Capital Schedule'!G8 -> 7360.6799 | G7: ='Working Capital Schedule'!H8 -> 7969.2964 | H7: ='Working Capital Schedule'!I8 -> 8407.6077 | I7: ='Working Capital Schedule'!J8 -> 8827.9881 | J7: ='Working Capital Schedule'!K8 -> 9225.2476
A8: Other current assets | B8: 21223 | C8: 14695 | D8: 14287 | E8: 14585 | F8: ='Working Capital Schedule'!G10 -> 17474.768 | G8: ='Working Capital Schedule'!H10 -> 18523.254 | H8: ='Working Capital Schedule'!I10 -> 19542.033 | I8: ='Working Capital Schedule'!J10 -> 20519.135 | J8: ='Working Capital Schedule'!K10 -> 21442.496
A9: Total current assets | B9: =SUM(B3:B8) -> 135405 | C9: =SUM(C3:C8) -> 143566 | D9: =SUM(D3:D8) -> 152987 | E9: =SUM(E3:E8) -> 147957 | F9: =SUM(F3:F8) -> 153247.97 | G9: =SUM(G3:G8) -> 166529.12 | H9: =SUM(H3:H8) -> 179572.91 | I9: =SUM(I3:I8) -> 193293.44 | J9: =SUM(J3:J8) -> 207579.19
A11: Long-Term Assets
A12: Long-term marketable securities | B12: 120805 | C12: 100544 | D12: 91479 | E12: 77723 | F12: =E12-'C.S'!G20 -> 77723 | G12: =F12-'C.S'!H20 -> 77723 | H12: =G12-'C.S'!I20 -> 77723 | I12: =H12-'C.S'!J20 -> 77723 | J12: =I12-'C.S'!K20 -> 77723
A13: Property, plant and equipment, net | B13: 52534 | C13: 43715 | D13: 45680 | E13: 49834 | F13: =E13-'C.S'!G18-'C.S'!G4 -> 51737.221 | G13: =F13-'C.S'!H18-'C.S'!H4 -> 53767.622 | H13: =G13-'C.S'!I18-'C.S'!I4 -> 54854.355 | I13: =H13-'C.S'!J18-'C.S'!J4 -> 54874.409 | J13: =I13-'C.S'!K18-'C.S'!K4 -> 53699.78
A14: Other non-current assets (incl. deferred tax assets) | B14: 44011 | C14: 64758 | D14: 74834 | E14: 83727 | F14: =E14-'C.S'!G21-'C.S'!G8 -> 83727 | G14: =F14-'C.S'!H21-'C.S'!H8 -> 83727 | H14: =G14-'C.S'!I21-'C.S'!I8 -> 83727 | I14: =H14-'C.S'!J21-'C.S'!J8 -> 83727 | J14: =I14-'C.S'!K21-'C.S'!K8 -> 83727
A15: Total Long Term Assets | B15: =SUM(B12:B14) -> 217350 | C15: =SUM(C12:C14) -> 209017 | D15: =SUM(D12:D14) -> 211993 | E15: =SUM(E12:E14) -> 211284 | F15: =SUM(F12:F14) -> 213187.22 | G15: =SUM(G12:G14) -> 215217.62 | H15: =SUM(H12:H14) -> 216304.36 | I15: =SUM(I12:I14) -> 216324.41 | J15: =SUM(J12:J14) -> 215149.78
A16: Total Assets | B16: =B9+B15 -> 352755 | C16: =C9+C15 -> 352583 | D16: =D9+D15 -> 364980 | E16: =E9+E15 -> 359241 | F16: =F9+F15 -> 366435.19 | G16: =G9+G15 -> 381746.74 | H16: =H9+H15 -> 395877.26 | I16: =I9+I15 -> 409617.85 | J16: =J9+J15 -> 422728.97
A18: Operating Current Liabilities
A19: Accounts payable | B19: 64115 | C19: 62611 | D19: 68960 | E19: 69860 | F19: ='Working Capital Schedule'!G14 -> 76514.235 | G19: ='Working Capital Schedule'!H14 -> 82840.801 | H19: ='Working Capital Schedule'!I14 -> 87397.045 | I19: ='Working Capital Schedule'!J14 -> 91766.897 | J19: ='Working Capital Schedule'!K14 -> 95896.407
A20: Other current liabilities | B20: 60845 | C20: 58829 | D20: 78304 | E20: 66387 | F20: ='Working Capital Schedule'!G16 -> 65331.576 | G20: ='Working Capital Schedule'!H16 -> 69251.471 | H20: ='Working Capital Schedule'!I16 -> 73060.302 | I20: ='Working Capital Schedule'!J16 -> 76713.317 | J20: ='Working Capital Schedule'!K16 -> 80165.416
A21: Deferred revenue | B21: 7912 | C21: 8061 | D21: 8249 | E21: 9055 | F21: ='Working Capital Schedule'!G18 -> 10156.03 | G21: ='Working Capital Schedule'!H18 -> 10765.392 | H21: ='Working Capital Schedule'!I18 -> 11357.489 | I21: ='Working Capital Schedule'!J18 -> 11925.363 | J21: ='Working Capital Schedule'!K18 -> 12462.005
A22: Commercial paper | B22: 9982 | C22: 5985 | D22: 9967 | E22: 7979 | F22: ='Debt Schedule'!G15 -> 2000 | G22: ='Debt Schedule'!H15 -> 2000 | H22: ='Debt Schedule'!I15 -> 2000 | I22: ='Debt Schedule'!J15 -> 2000 | J22: ='Debt Schedule'!K15 -> 2000
A23: Total operating current liabilities | B23: =B22+B21+B20+B19 -> 142854 | C23: =C22+C21+C20+C19 -> 135486 | D23: =D22+D21+D20+D19 -> 165480 | E23: =E22+E21+E20+E19 -> 153281 | F23: =F22+F21+F20+F19 -> 154001.84 | G23: =G22+G21+G20+G19 -> 164857.66 | H23: =H22+H21+H20+H19 -> 173814.84 | I23: =I22+I21+I20+I19 -> 182405.58 | J23: =J22+J21+J20+J19 -> 190523.83
A25: Debt
A26: Term debt (current + non-current) | B26: 110087 | C26: 105103 | D26: 96662 | E26: 90678 | F26: ='Debt Schedule'!G23 -> 78328 | G26: ='Debt Schedule'!H23 -> 69328 | H26: ='Debt Schedule'!I23 -> 60328 | I26: ='Debt Schedule'!J23 -> 51328 | J26: ='Debt Schedule'!K23 -> 42328
A27: Other non-current liabilities (incl. leases, deferred tax) | B27: 49142 | C27: 49848 | D27: 45888 | E27: 41549 | F27: =E27+'C.S'!G7 -> 41621.165 | G27: =F27+'C.S'!H7 -> 42006.844 | H27: =G27+'C.S'!I7 -> 42583.06 | I27: =H27+'C.S'!J7 -> 43233.526 | J27: =I27+'C.S'!K7 -> 43870.052
A28: Total Long term Liabilities | B28: =B27+B26 -> 159229 | C28: =C27+C26 -> 154951 | D28: =D27+D26 -> 142550 | E28: =E27+E26 -> 132227 | F28: =F27+F26 -> 119949.17 | G28: =G27+G26 -> 111334.84 | H28: =H27+H26 -> 102911.06 | I28: =I27+I26 -> 94561.526 | J28: =J27+J26 -> 86198.052
A29: Total Liabilities | B29: =B28+B23 -> 302083 | C29: =C28+C23 -> 290437 | D29: =D28+D23 -> 308030 | E29: =E28+E23 -> 285508 | F29: =F28+F23 -> 273951.01 | G29: =G28+G23 -> 276192.51 | H29: =H28+H23 -> 276725.89 | I29: =I28+I23 -> 276967.1 | J29: =J28+J23 -> 276721.88
A31: Shareholders' Equity
A32: Common stock and additional paid-in capital | B32: 64849 | C32: 73812 | D32: 83276 | E32: 93568 | F32: =E32+'C.S'!G5+'C.S'!G31 -> 107398.69 | G32: =F32+'C.S'!H5+'C.S'!H31 -> 122059.23 | H32: =G32+'C.S'!I5+'C.S'!I31 -> 137526.1 | I32: =H32+'C.S'!J5+'C.S'!J31 -> 153766.31 | J32: =I32+'C.S'!K5+'C.S'!K31 -> 170737.32
A33: Retained earnings / (accumulated deficit) | B33: -3068 | C33: -214 | D33: -19154 | E33: -14264 | F33: =E33+I.S!G29+'C.S'!G26+'C.S'!G27 -> -9343.5094 | G33: =F33+I.S!H29+'C.S'!H26+'C.S'!H27 -> -10933.994 | H33: =G33+I.S!I29+'C.S'!I26+'C.S'!I27 -> -12803.73 | I33: =H33+I.S!J29+'C.S'!J26+'C.S'!J27 -> -15544.561 | J33: =I33+I.S!K29+'C.S'!K26+'C.S'!K27 -> -19159.23
A34: Accumulated other comprehensive loss | B34: -11109 | C34: -11452 | D34: -7172 | E34: -5571 | F34: =E34 -> -5571 | G34: =F34 -> -5571 | H34: =G34 -> -5571 | I34: =H34 -> -5571 | J34: =I34 -> -5571
A35: Total shareholders' equity | B35: =SUM(B32:B34) -> 50672 | C35: =SUM(C32:C34) -> 62146 | D35: =SUM(D32:D34) -> 56950 | E35: =SUM(E32:E34) -> 73733 | F35: =SUM(F32:F34) -> 92484.185 | G35: =SUM(G32:G34) -> 105554.24 | H35: =SUM(H32:H34) -> 119151.37 | I35: =SUM(I32:I34) -> 132650.74 | J35: =SUM(J32:J34) -> 146007.09
A36: Total Liabilities and Shareholders' Equity | B36: =B29+B35 -> 352755 | C36: =C29+C35 -> 352583 | D36: =D29+D35 -> 364980 | E36: =E29+E35 -> 359241 | F36: =F29+F35 -> 366435.19 | G36: =G29+G35 -> 381746.74 | H36: =H29+H35 -> 395877.26 | I36: =I29+I35 -> 409617.85 | J36: =J29+J35 -> 422728.97
A38: Balance check (Assets - Liabilities & Equity) | B38: =B16-B36 -> 0 | C38: =C16-C36 -> 0 | D38: =D16-D36 -> 0 | E38: =E16-E36 -> 0 | F38: =F16-F36 -> 0 | G38: =G16-G36 -> 0 | H38: =H16-H36 -> 0 | I38: =I16-I36 -> 0 | J38: =J16-J36 -> 0
A39: Match (Y/N) | B39: =IF(ABS(B38)<0.5,"Y","N") -> Y | C39: =IF(ABS(C38)<0.5,"Y","N") -> Y | D39: =IF(ABS(D38)<0.5,"Y","N") -> Y | E39: =IF(ABS(E38)<0.5,"Y","N") -> Y | F39: =IF(ABS(F38)<0.5,"Y","N") -> Y | G39: =IF(ABS(G38)<0.5,"Y","N") -> Y | H39: =IF(ABS(H38)<0.5,"Y","N") -> Y | I39: =IF(ABS(I38)<0.5,"Y","N") -> Y | J39: =IF(ABS(J38)<0.5,"Y","N") -> Y

Sheet >>Valuation
A1: APPLE INC. - DCF VALUATION
A2: ($ in millions, except per share) | B2: 2023 | C2: =B2+1 -> 2024 | D2: =C2+1 -> 2025 | E2: =D2+1 -> 2026 | F2: =E2+1 -> 2027 | G2: =F2+1 -> 2028 | H2: =G2+1 -> 2029 | I2: =H2+1 -> 2030
A4: Unlevered Free Cash Flow
A5: EBIT | E5: =I.S!G15 -> 156429.93 | F5: =I.S!H15 -> 160254.83 | G5: =I.S!I15 -> 169068.84 | H5: =I.S!J15 -> 177522.29 | I5: =I.S!K15 -> 185510.79
A6: Depreciation & Amortization | E6: ='C.S'!G4 -> 11450.553 | F6: ='C.S'!H4 -> 13135.672 | G6: ='C.S'!I4 -> 14913.472 | H6: ='C.S'!J4 -> 16780.163 | I6: ='C.S'!K4 -> 18730.855
A7: Changes in Working Capital | E7: ='C.S'!G14 -> -2927.6259 | F7: ='C.S'!H14 -> 3675.4523 | G7: ='C.S'!I14 -> 2903.4405 | H7: ='C.S'!J14 -> 2784.6633 | I7: ='C.S'!K14 -> 2631.5069
A8: Capital Expenditure | E8: ='C.S'!G18 -> -13353.774 | F8: ='C.S'!H18 -> -15166.072 | G8: ='C.S'!I18 -> -16000.206 | H8: ='C.S'!J18 -> -16800.216 | I8: ='C.S'!K18 -> -17556.226
A9: Taxes (tax rate x EBIT) | E9: =-(I.S!G28*E5) -> -26593.087 | F9: =-(I.S!H28*F5) -> -27243.321 | G9: =-(I.S!I28*G5) -> -28741.703 | H9: =-(I.S!J28*H5) -> -30178.789 | I9: =-(I.S!K28*I5) -> -31536.834
A10: Deferred income taxes | E10: ='C.S'!G7 -> 72.165279 | F10: ='C.S'!H7 -> 385.67886 | G10: ='C.S'!I7 -> 576.21553 | H10: ='C.S'!J7 -> 650.466 | I10: ='C.S'!K7 -> 636.52644
A11: Total Unlevered Free Cash Flow | E11: =SUM(E5:E10) -> 125078.16 | F11: =SUM(F5:F10) -> 135042.24 | G11: =SUM(G5:G10) -> 142720.06 | H11: =SUM(H5:H10) -> 150758.57 | I11: =SUM(I5:I10) -> 158416.62
A13: Net Present Value Calculation
A14: Period (end-of-year convention) | E14: 1 | F14: 2 | G14: 3 | H14: 4 | I14: 5
A15: Discounted Cash Flow | D15: =J26 -> 0.10080096 | E15: =E11/(1+$D$15)^E14 -> 113624.68 | F15: =F11/(1+$D$15)^F14 -> 111442.8 | G15: =G11/(1+$D$15)^G14 -> 106993.81 | H15: =H11/(1+$D$15)^H14 -> 102670.77 | I15: =I11/(1+$D$15)^I14 -> 98006.921
A16: Total Net Present Value | D16: =SUM(E15:I15) -> 532738.98
A18: Terminal Value
A19: EBITDA Method | H19: Cost of Capital | K19: Market data & capital structure
A20: Exit Year EBITDA (FY2030E) | C20: =I.S!K20 -> 204241.64 | H20: Risk Free Rate | J20: 0.0528 | K20: Total debt (CP + term debt, FY2025) | M20: =B.S!E22+B.S!E26 -> 98657
A21: Multiple (current EV / TTM EBITDA) | C21: =M27 -> 29.378161 | H21: Market Risk Premium | J21: 0.045 | K21: Stock price ($, 8-Oct-2026 close) | M21: 340.42
A22: Terminal Value | C22: =C21*C20 -> 6000243.8 | H22: Beta | J22: 1.09 | K22: Shares outstanding - current (mm) | M22: 14594
A23: Net Present Value | C23: =C22/(1+D15)^I14 -> 3712144.8 | H23: Cost of Equity | J23: =J20+(J22*J21) -> 0.10185 | K23: Equity Value (market cap) | M23: =M22*M21 -> 4968089.5
A24: Perpetuity Method | H24: Cost of Debt (pre-tax) | J24: =J20+0.005 -> 0.0578 | K24: Net Debt / (net cash) incl. all securities | M24: =M20-(B.S!E3+B.S!E4+B.S!E12) -> -33763
A25: Unlevered Free Cash Flow (FY2030E) | C25: =I11 -> 158416.62 | H25: Tax rate | J25: =I.S!G28 -> 0.17 | K25: Enterprise Value | M25: =M23+M24 -> 4934326.5
A26: Growth Rate | C26: 0.03 | H26: WACC | J26: =((M23/(M23+M20))*J23)+((M20/(M23+M20))*(J24*(1-J25))) -> 0.10080096 | K26: TTM EBITDA (Jun-26) | M26: 167959
A27: Terminal Value | C27: =C25*(1+C26)/(D15-C26) -> 2304617.4 | K27: Current EV / TTM EBITDA | M27: =M25/M26 -> 29.378161
A28: Net Present Value | C28: =C27/(1+D15)^I14 -> 1425787.7 | K28: Basic shares outstanding at 27-Sep-2025 (mm) | M28: 14773
A29: Cross-check: exit multiple implied by perpetuity TV | C29: =C27/C20 -> 11.283778 | K29: Dilution from RSUs (FY25 diluted - basic, mm) | M29: =I.S!F38-I.S!F37 -> 56
A30: Cross-check: perpetual growth implied by exit multiple | C30: =(C22*D15-C25)/(C22+C25) -> 0.072485518 | K30: Diluted shares at valuation date (mm) | M30: =M28+M29 -> 14829
K31: Valuation date | M31: =DATE(2025,9,27) -> 45927
A32: Discounted Cash Flow Total Valuation | B32: EBITDA Method | C32: Perpetuity Method | K32: Pricing date | M32: =DATE(2026,10,8) -> 46303
A33: Total of Present Value of Cash Flows | B33: =D16 -> 532738.98 | C33: =D16 -> 532738.98
A34: Present Value of Terminal Value | B34: =C23 -> 3712144.8 | C34: =C28 -> 1425787.7
A35: Total Enterprise Value | B35: =SUM(B33:B34) -> 4244883.8 | C35: =SUM(C33:C34) -> 1958526.7
A36: Less: Net Debt / (plus net cash) | B36: =M24 -> -33763 | C36: =B36 -> -33763
A37: Equity Value | B37: =B35-B36 -> 4278646.8 | C37: =C35-C36 -> 1992289.7
A38: Diluted Share Count (millions) | B38: =M30 -> 14829 | C38: =B38 -> 14829
A39: Estimated Equity Value per Share at 27-Sep-2025 | B39: =B37/B38 -> 288.53239 | C39: =C37/C38 -> 134.35091
A40: Years from valuation date to pricing date | B40: =(M32-M31)/365 -> 1.030137 | C40: =B40 -> 1.030137
A41: Less: dividends per share paid in the period (FY26E DPS) | B41: ='C.S'!G28 -> 1.0608 | C41: =B41 -> 1.0608
A42: Equity Value per Share rolled forward to pricing date | B42: =B39*(1+$J$23)^B40-B41 -> 317.78925 | C42: =C39*(1+$J$23)^C40-C41 -> 147.40709
A43: Current share price | B43: =M21 -> 340.42 | C43: =M21 -> 340.42
...

Sheet Working Capital Schedule
A1: Operating Working Capital
A2: Days in year | B2: 365
A3: Valuation date 27-Sep-2025 ($ in millions) | B3: 2021 | C3: =B3+1 -> 2022 | D3: =C3+1 -> 2023 | E3: =D3+1 -> 2024 | F3: =E3+1 -> 2025 | G3: =F3+1 -> 2026 | H3: =G3+1 -> 2027 | I3: =H3+1 -> 2028 | J3: =I3+1 -> 2029 | K3: =J3+1 -> 2030
A4: Accounts receivable | C4: =B.S!B5 -> 28184 | D4: =B.S!C5 -> 29508 | E4: =B.S!D5 -> 33410 | F4: =B.S!E5 -> 39777 | G4: =G5*I.S!G2/$B$2 -> 41016.406 | H4: =H5*I.S!H2/$B$2 -> 43477.391 | I4: =I5*I.S!I2/$B$2 -> 45868.647 | J4: =J5*I.S!J2/$B$2 -> 48162.08 | K4: =K5*I.S!K2/$B$2 -> 50329.373
A5: Receivable days (on revenue) | C5: =C4/I.S!C2*$B$2 -> 26.087825 | D5: =D4/I.S!D2*$B$2 -> 28.100291 | E5: =E4/I.S!E2*$B$2 -> 31.185572 | F5: =F4/I.S!F2*$B$2 -> 34.886991 | G5: =AVERAGE(D5:F5) -> 31.390951 | H5: =G5 -> 31.390951 | I5: =H5 -> 31.390951 | J5: =I5 -> 31.390951 | K5: =J5 -> 31.390951
A6: Other receivables (vendor non-trade) | C6: =B.S!B6 -> 32748 | D6: =B.S!C6 -> 31477 | E6: =B.S!D6 -> 32833 | F6: =B.S!E6 -> 33180 | G6: =G7*-I.S!G4/$B$2 -> 37035.613 | H6: =H7*-I.S!H4/$B$2 -> 40097.896 | I6: =I7*-I.S!I4/$B$2 -> 42303.28 | J6: =J7*-I.S!J4/$B$2 -> 44418.444 | K6: =K7*-I.S!K4/$B$2 -> 46417.274
A7: Days (on cost of sales) | C7: =C6/-I.S!C4*$B$2 -> 53.470069 | D7: =D6/-I.S!D4*$B$2 -> 53.653059 | E7: =E6/-I.S!E4*$B$2 -> 56.971386 | F7: =F6/-I.S!F4*$B$2 -> 54.809468 | G7: =AVERAGE(D7:F7) -> 55.144637 | H7: =G7 -> 55.144637 | I7: =H7 -> 55.144637 | J7: =I7 -> 55.144637 | K7: =J7 -> 55.144637
A8: Inventories | C8: =B.S!B7 -> 4946 | D8: =B.S!C7 -> 6331 | E8: =B.S!D7 -> 7286 | F8: =B.S!E7 -> 5718 | G8: =G9*-I.S!G4/$B$2 -> 7360.6799 | H8: =H9*-I.S!H4/$B$2 -> 7969.2964 | I8: =I9*-I.S!I4/$B$2 -> 8407.6077 | J8: =J9*-I.S!J4/$B$2 -> 8827.9881 | K8: =K9*-I.S!K4/$B$2 -> 9225.2476
A9: Inventory days (on cost of sales) | C9: =C8/-I.S!C4*$B$2 -> 8.0756981 | D9: =D8/-I.S!D4*$B$2 -> 10.791292 | E9: =E8/-I.S!E4*$B$2 -> 12.642571 | F9: =F8/-I.S!F4*$B$2 -> 9.4454652 | G9: =AVERAGE(D9:F9) -> 10.959776 | H9: =G9 -> 10.959776 | I9: =H9 -> 10.959776 | J9: =I9 -> 10.959776 | K9: =J9 -> 10.959776
A10: Other current assets | C10: =B.S!B8 -> 21223 | D10: =B.S!C8 -> 14695 | E10: =B.S!D8 -> 14287 | F10: =B.S!E8 -> 14585 | G10: =G11*I.S!G2/$B$2 -> 17474.768 | H10: =H11*I.S!H2/$B$2 -> 18523.254 | I10: =I11*I.S!I2/$B$2 -> 19542.033 | J10: =J11*I.S!J2/$B$2 -> 20519.135 | K10: =K11*I.S!K2/$B$2 -> 21442.496
A11: Days (on revenue) | C11: =C10/I.S!C2*$B$2 -> 19.644547 | D11: =D10/I.S!D2*$B$2 -> 13.99396 | E11: =E10/I.S!E2*$B$2 -> 13.335776 | F11: =F10/I.S!F2*$B$2 -> 12.791984 | G11: =AVERAGE(D11:F11) -> 13.373907 | H11: =G11 -> 13.373907 | I11: =H11 -> 13.373907 | J11: =I11 -> 13.373907 | K11: =J11 -> 13.373907
A12: Current operating assets | C12: =C4+C6+C8+C10 -> 87101 | D12: =D4+D6+D8+D10 -> 82011 | E12: =E4+E6+E8+E10 -> 87816 | F12: =F4+F6+F8+F10 -> 93260 | G12: =G4+G6+G8+G10 -> 102887.47 | H12: =H4+H6+H8+H10 -> 110067.84 | I12: =I4+I6+I8+I10 -> 116121.57 | J12: =J4+J6+J8+J10 -> 121927.65 | K12: =K4+K6+K8+K10 -> 127414.39
A14: Accounts payable | C14: =B.S!B19 -> 64115 | D14: =B.S!C19 -> 62611 | E14: =B.S!D19 -> 68960 | F14: =B.S!E19 -> 69860 | G14: =G15*-I.S!G4/$B$2 -> 76514.235 | H14: =H15*-I.S!H4/$B$2 -> 82840.801 | I14: =I15*-I.S!I4/$B$2 -> 87397.045 | J14: =J15*-I.S!J4/$B$2 -> 91766.897 | K14: =K15*-I.S!K4/$B$2 -> 95896.407
A15: Payable days (on cost of sales) | C15: =C14/-I.S!C4*$B$2 -> 104.68528 | D15: =D14/-I.S!D4*$B$2 -> 106.72147 | E15: =E14/-I.S!E4*$B$2 -> 119.65848 | F15: =F14/-I.S!F4*$B$2 -> 115.40052 | G15: =AVERAGE(D15:F15) -> 113.92682 | H15: =G15 -> 113.92682 | I15: =H15 -> 113.92682 | J15: =I15 -> 113.92682 | K15: =J15 -> 113.92682
A16: Other current liabilities | C16: =B.S!B20 -> 60845 | D16: =B.S!C20 -> 58829 | E16: =B.S!D20 -> 78304 | F16: =B.S!E20 -> 66387 | G16: =G17*I.S!G2/$B$2 -> 65331.576 | H16: =H17*I.S!H2/$B$2 -> 69251.471 | I16: =I17*I.S!I2/$B$2 -> 73060.302 | J16: =J17*I.S!J2/$B$2 -> 76713.317 | K16: =K17*I.S!K2/$B$2 -> 80165.416
A17: Days (on revenue) | C17: =C16/I.S!C2*$B$2 -> 56.319675 | D17: =D16/I.S!D2*$B$2 -> 56.022503 | E17: =E16/I.S!E2*$B$2 -> 73.090542 | F17: =F16/I.S!F2*$B$2 -> 58.225675 | G17: 50 | H17: =G17 -> 50 | I17: =H17 -> 50 | J17: =I17 -> 50 | K17: =J17 -> 50
A18: Deferred revenue | C18: =B.S!B21 -> 7912 | D18: =B.S!C21 -> 8061 | E18: =B.S!D21 -> 8249 | F18: =B.S!E21 -> 9055 | G18: =G19*I.S!G2/$B$2 -> 10156.03 | H18: =H19*I.S!H2/$B$2 -> 10765.392 | I18: =I19*I.S!I2/$B$2 -> 11357.489 | J18: =J19*I.S!J2/$B$2 -> 11925.363 | K18: =K19*I.S!K2/$B$2 -> 12462.005
A19: Days (on revenue) | C19: =C18/I.S!C2*$B$2 -> 7.3235479 | D19: =D18/I.S!D2*$B$2 -> 7.6764418 | E19: =E18/I.S!E2*$B$2 -> 7.6997839 | F19: =F18/I.S!F2*$B$2 -> 7.9418182 | G19: =AVERAGE(D19:F19) -> 7.7726813 | H19: =G19 -> 7.7726813 | I19: =H19 -> 7.7726813 | J19: =I19 -> 7.7726813 | K19: =J19 -> 7.7726813
A20: Current operating liabilities | C20: =C14+C16+C18 -> 132872 | D20: =D14+D16+D18 -> 129501 | E20: =E14+E16+E18 -> 155513 | F20: =F14+F16+F18 -> 145302 | G20: =G14+G16+G18 -> 152001.84 | H20: =H14+H16+H18 -> 162857.66 | I20: =I14+I16+I18 -> 171814.84 | J20: =J14+J16+J18 -> 180405.58 | K20: =K14+K16+K18 -> 188523.83
A22: Total working capital | C22: =C12-C20 -> -45771 | D22: =D12-D20 -> -47490 | E22: =E12-E20 -> -67697 | F22: =F12-F20 -> -52042 | G22: =G12-G20 -> -49114.374 | H22: =H12-H20 -> -52789.826 | I22: =I12-I20 -> -55693.267 | J22: =J12-J20 -> -58477.93 | K22: =K12-K20 -> -61109.437
A23: Change in working capital (cash flow impact) | D23: =-(D22-C22) -> 1719 | E23: =-(E22-D22) -> 20207 | F23: =-(F22-E22) -> -15655 | G23: =-(G22-F22) -> -2927.6259 | H23: =-(H22-G22) -> 3675.4523 | I23: =-(I22-H22) -> 2903.4405 | J23: =-(J22-I22) -> 2784.6633 | K23: =-(K22-J22) -> 2631.5069
A25: Match (Y/N) vs. cash flow statement | G25: =IF(ABS(G23-'C.S'!G14)<0.5,"Y","N") -> Y | H25: =IF(ABS(H23-'C.S'!H14)<0.5,"Y","N") -> Y | I25: =IF(ABS(I23-'C.S'!I14)<0.5,"Y","N") -> Y | J25: =IF(ABS(J23-'C.S'!J14)<0.5,"Y","N") -> Y | K25: =IF(ABS(K23-'C.S'!K14)<0.5,"Y","N") -> Y

Sheet Depreciation Schedule
A1: Depreciation Schedule
D2: Historical | I2: Projections
A3: Period Ending September ($ in millions) | D3: 2021 | E3: =D3+1 -> 2022 | F3: =E3+1 -> 2023 | G3: =F3+1 -> 2024 | H3: =G3+1 -> 2025 | I3: =H3+1 -> 2026 | J3: =I3+1 -> 2027 | K3: =J3+1 -> 2028 | L3: =K3+1 -> 2029 | M3: =L3+1 -> 2030
A4: PP&E at start of projection (FY2025 year-end) | I4: =B.S!E13 -> 49834
A5: Capital Expenditure | I5: =-'C.S'!G18 -> 13353.774 | J5: =-'C.S'!H18 -> 15166.072 | K5: =-'C.S'!I18 -> 16000.206 | L5: =-'C.S'!J18 -> 16800.216 | M5: =-'C.S'!K18 -> 17556.226
A6: % Growth | J6: =J5/I5-1 -> 0.13571429 | K6: =K5/J5-1 -> 0.055 | L6: =L5/K5-1 -> 0.05 | M6: =M5/L5-1 -> 0.045
A8: Straight line Depreciation Years
A9: Years:
A10: Existing property, plant and equipment | I10: 5
A11: CAPEX (new layers) | I11: 9 | J11: 9 | K11: 9 | L11: 9 | M11: 9
A12: Depreciation
A13: Existing PP&E | I13: =$I$4/$I$10 -> 9966.8 | J13: =$I$4/$I$10 -> 9966.8 | K13: =$I$4/$I$10 -> 9966.8 | L13: =$I$4/$I$10 -> 9966.8 | M13: =$I$4/$I$10 -> 9966.8
A14: 2026E CAPEX | I14: =$I$5/$I$11 -> 1483.7527 | J14: =$I$5/$I$11 -> 1483.7527 | K14: =$I$5/$I$11 -> 1483.7527 | L14: =$I$5/$I$11 -> 1483.7527 | M14: =$I$5/$I$11 -> 1483.7527
A15: 2027E CAPEX | J15: =$J$5/$J$11 -> 1685.1191 | K15: =$J$5/$J$11 -> 1685.1191 | L15: =$J$5/$J$11 -> 1685.1191 | M15: =$J$5/$J$11 -> 1685.1191
A16: 2028E CAPEX | K16: =$K$5/$K$11 -> 1777.8007 | L16: =$K$5/$K$11 -> 1777.8007 | M16: =$K$5/$K$11 -> 1777.8007
A17: 2029E CAPEX | L17: =$L$5/$L$11 -> 1866.6907 | M17: =$L$5/$L$11 -> 1866.6907
A18: 2030E CAPEX | M18: =$M$5/$M$11 -> 1950.6918
A19: Total book depreciation & amortization | D19: ='C.S'!B4 -> 11284 | E19: ='C.S'!C4 -> 11104 | F19: ='C.S'!D4 -> 11519 | G19: ='C.S'!E4 -> 11445 | H19: ='C.S'!F4 -> 11698 | I19: =SUM(I13:I18) -> 11450.553 | J19: =SUM(J13:J18) -> 13135.672 | K19: =SUM(K13:K18) -> 14913.472 | L19: =SUM(L13:L18) -> 16780.163 | M19: =SUM(M13:M18) -> 18730.855
A20: % Growth | E20: =E19/D19-1 -> -0.01595179 | F20: =F19/E19-1 -> 0.037373919 | G20: =G19/F19-1 -> -0.0064241688 | H20: =H19/G19-1 -> 0.022105723 | I20: =I19/H19-1 -> -0.021152959 | J20: =J19/I19-1 -> 0.14716487 | K20: =K19/J19-1 -> 0.13534144 | L20: =L19/K19-1 -> 0.12516808 | M20: =M19/L19-1 -> 0.11624987
A22: Tax depreciation: accelerated (MACRS) schedule (%)
A23: Existing PP&E | I23: 0.2 | J23: 0.2 | K23: 0.2 | L23: 0.2 | M23: 0.2
A24: 2026E CAPEX | I24: 0.1429 | J24: 0.2449 | K24: 0.1749 | L24: 0.1249 | M24: 0.0893
A25: 2027E CAPEX | J25: 0.1429 | K25: 0.2449 | L25: 0.1749 | M25: 0.1249
A26: 2028E CAPEX | K26: 0.1429 | L26: 0.2449 | M26: 0.1749
A27: 2029E CAPEX | L27: 0.1429 | M27: 0.2449
A28: 2030E CAPEX | M28: 0.1429
A30: Tax depreciation ($)
A31: Existing PP&E | I31: =$I$4*I23 -> 9966.8 | J31: =$I$4*J23 -> 9966.8 | K31: =$I$4*K23 -> 9966.8 | L31: =$I$4*L23 -> 9966.8 | M31: =$I$4*M23 -> 9966.8
A32: 2026E CAPEX | I32: =$I$5*I24 -> 1908.2543 | J32: =$I$5*J24 -> 3270.3393 | K32: =$I$5*K24 -> 2335.5751 | L32: =$I$5*L24 -> 1667.8864 | M32: =$I$5*M24 -> 1192.492
A33: 2027E CAPEX | J33: =$J$5*J25 -> 2167.2317 | K33: =$J$5*K25 -> 3714.1711 | L33: =$J$5*L25 -> 2652.546 | M33: =$J$5*M25 -> 1894.2424
A34: 2028E CAPEX | K34: =$K$5*K26 -> 2286.4294 | L34: =$K$5*L26 -> 3918.4505 | M34: =$K$5*M26 -> 2798.436
A35: 2029E CAPEX | L35: =$L$5*L27 -> 2400.7509 | M35: =$L$5*M27 -> 4114.373
A36: 2030E CAPEX | M36: =$M$5*M28 -> 2508.7847
A37: Total Tax Depreciation | I37: =SUM(I31:I36) -> 11875.054 | J37: =SUM(J31:J36) -> 15404.371 | K37: =SUM(K31:K36) -> 18302.976 | L37: =SUM(L31:L36) -> 20606.434 | M37: =SUM(M31:M36) -> 22475.128
A38: Difference in depreciation (tax - book) | I38: =I37-I19 -> 424.50164 | J38: =J37-J19 -> 2268.6992 | K38: =K37-K19 -> 3389.5031 | L38: =L37-L19 -> 3826.2706 | M38: =M37-M19 -> 3744.2732
A39: Tax rate % | I39: =I.S!G28 -> 0.17 | J39: =I.S!H28 -> 0.17 | K39: =I.S!I28 -> 0.17 | L39: =I.S!J28 -> 0.17 | M39: =I.S!K28 -> 0.17
A40: Deferred taxes | I40: =I38*I39 -> 72.165279 | J40: =J38*J39 -> 385.67886 | K40: =K38*K39 -> 576.21553 | L40: =L38*L39 -> 650.466 | M40: =M38*M39 -> 636.52644

Sheet Debt Schedule
A1: Debt Schedule
B2: Actuals | G2: Projections
A3: Valuation date 27-Sep-2025 ($ in millions) | B3: 2021 | C3: =B3+1 -> 2022 | D3: =C3+1 -> 2023 | E3: =D3+1 -> 2024 | F3: =E3+1 -> 2025 | G3: =F3+1 -> 2026 | H3: =G3+1 -> 2027 | I3: =H3+1 -> 2028 | J3: =I3+1 -> 2029 | K3: =J3+1 -> 2030
A5: Cash available to pay down debt
A6: Cash at beginning of year | G6: =F29 -> 35934 | H6: =G29 -> 31597.503 | I6: =H29 -> 37698.286 | J6: =I29 -> 44688.338 | K6: =J29 -> 52602.792
A7: Cash flow before debt issuance/(repayment) | G7: ='C.S'!G41 -> 13992.503 | H7: ='C.S'!H41 -> 15100.782 | I7: ='C.S'!I41 -> 15990.052 | J7: ='C.S'!J41 -> 16914.454 | K7: ='C.S'!K41 -> 17799.012
A8: Minimum cash cushion | G8: -20000 | H8: -20000 | I8: -20000 | J8: -20000 | K8: -20000
A9: Total cash available to pay down debt | G9: =SUM(G6:G8) -> 29926.503 | H9: =SUM(H6:H8) -> 26698.286 | I9: =SUM(I6:I8) -> 33688.338 | J9: =SUM(J6:J8) -> 41602.792 | K9: =SUM(K6:K8) -> 50401.804
A11: Commercial paper
A12: Commercial paper (beginning of year) | G12: =F15 -> 7979 | H12: =G15 -> 2000 | I12: =H15 -> 2000 | J12: =I15 -> 2000 | K12: =J15 -> 2000
A13: Mandatory issuances / (retirements) | G13: -5979 | H13: 0 | I13: 0 | J13: 0 | K13: 0
A14: Non-mandatory issuances / (retirements) | G14: 0 | H14: 0 | I14: 0 | J14: 0 | K14: 0
A15: Commercial paper (end of year) | F15: =B.S!E22 -> 7979 | G15: =SUM(G12:G14) -> 2000 | H15: =SUM(H12:H14) -> 2000 | I15: =SUM(I12:I14) -> 2000 | J15: =SUM(J12:J14) -> 2000 | K15: =SUM(K12:K14) -> 2000
A16: Commercial paper interest expense | G16: =AVERAGE(F15:G15)*G17 -> 224.5275 | H16: =AVERAGE(G15:H15)*H17 -> 90 | I16: =AVERAGE(H15:I15)*I17 -> 90 | J16: =AVERAGE(I15:J15)*J17 -> 90 | K16: =AVERAGE(J15:K15)*K17 -> 90
A17: Commercial paper interest rate | G17: 0.045 | H17: 0.045 | I17: 0.045 | J17: 0.045 | K17: 0.045
A19: Term debt (current + non-current)
A20: Term debt (beginning of year) | G20: =F23 -> 90678 | H20: =G23 -> 78328 | I20: =H23 -> 69328 | J20: =I23 -> 60328 | K20: =J23 -> 51328
A21: Mandatory issuances / (retirements) | G21: -12350 | H21: -9000 | I21: -9000 | J21: -9000 | K21: -9000
A22: Non-mandatory issuances / (retirements) | G22: 0 | H22: 0 | I22: 0 | J22: 0 | K22: 0
A23: Term debt (end of year) | F23: =B.S!E26 -> 90678 | G23: =SUM(G20:G22) -> 78328 | H23: =SUM(H20:H22) -> 69328 | I23: =SUM(I20:I22) -> 60328 | J23: =SUM(J20:J22) -> 51328 | K23: =SUM(K20:K22) -> 42328
A24: Term debt interest expense | G24: =AVERAGE(F23:G23)*G25 -> 2788.599 | H24: =AVERAGE(G23:H23)*H25 -> 2436.324 | I24: =AVERAGE(H23:I23)*I25 -> 2139.324 | J24: =AVERAGE(I23:J23)*J25 -> 1842.324 | K24: =AVERAGE(J23:K23)*K25 -> 1545.324
A25: Term debt interest rate | G25: 0.033 | H25: 0.033 | I25: 0.033 | J25: 0.033 | K25: 0.033
A27: Total issuances / (retirements) | G27: =G13+G14+G21+G22 -> -18329 | H27: =H13+H14+H21+H22 -> -9000 | I27: =I13+I14+I21+I22 -> -9000 | J27: =J13+J14+J21+J22 -> -9000 | K27: =K13+K14+K21+K22 -> -9000
A28: Total interest expense | G28: =G16+G24 -> 3013.1265 | H28: =H16+H24 -> 2526.324 | I28: =I16+I24 -> 2229.324 | J28: =J16+J24 -> 1932.324 | K28: =K16+K24 -> 1635.324
A29: Cash at the end of the year | F29: =B.S!E3 -> 35934 | G29: =G6+G7+G27 -> 31597.503 | H29: =H6+H7+H27 -> 37698.286 | I29: =I6+I7+I27 -> 44688.338 | J29: =J6+J7+J27 -> 52602.792 | K29: =K6+K7+K27 -> 61401.804
A30: Interest income (on beginning-of-year cash & marketable securities) | G30: =(B.S!E3+B.S!E4+B.S!E12)*G31 -> 4237.44 | H30: =(B.S!F3+B.S!F4+B.S!F12)*H31 -> 4098.6721 | I30: =(B.S!G3+B.S!G4+B.S!G12)*I31 -> 4293.8971 | J30: =(B.S!H3+B.S!H4+B.S!H12)*J31 -> 4517.5788 | K30: =(B.S!I3+B.S!I4+B.S!I12)*K31 -> 4770.8414
A31: Interest rate on cash & marketable securities | G31: 0.032 | H31: 0.032 | I31: 0.032 | J31: 0.032 | K31: 0.032
A33: Match (Y/N) vs. balance sheet cash | G33: =IF(ABS(G29-B.S!F3)<0.5,"Y","N") -> Y | H33: =IF(ABS(H29-B.S!G3)<0.5,"Y","N") -> Y | I33: =IF(ABS(I29-B.S!H3)<0.5,"Y","N") -> Y | J33: =IF(ABS(J29-B.S!I3)<0.5,"Y","N") -> Y | K33: =IF(ABS(K29-B.S!J3)<0.5,"Y","N") -> Y
