Workbook

Sheet Apple Consolidated Statements
A1: Apple Inc. Historical Financial Statements (FY1992–FY2025)
A2: Units: $ millions unless otherwise noted; EPS/dividends in $/share; share counts in thousands.
A4: Fiscal Year | B4: 1992 | C4: 1993 | D4: 1994 | E4: 1995 | F4: 1996 | G4: 1997 | H4: 1998 | I4: 1999 | J4: 2000 | K4: 2001 | L4: 2002 | M4: 2003 | N4: 2004 | O4: 2005 | P4: 2006 | Q4: 2007 | R4: 2008 | S4: 2009 | T4: 2010 | U4: 2011 | V4: 2012 | W4: 2013 | X4: 2014 | Y4: 2015 | Z4: 2016 | AA4: 2017 | AB4: 2018 | AC4: 2019 | AD4: 2020 | AE4: 2021 | AF4: 2022 | AG4: 2023 | AH4: 2024 | AI4: 2025
A6: INCOME STATEMENT | AL6: 5yr | AM6: Check | AO6: 3yr | AP6: Check
A7: Products Net Sales | B7: 0 | C7: 0 | D7: 0 | E7: 0 | F7: 0 | G7: 0 | H7: 0 | I7: 0 | J7: 0 | K7: 0 | L7: 0 | M7: 0 | N7: 0 | O7: 0 | P7: 0 | Q7: 0 | R7: 0 | S7: 0 | T7: 0 | U7: 0 | V7: 0 | W7: 0 | X7: 0 | Y7: 0 | Z7: 0 | AA7: 0 | AB7: 0 | AC7: 213883 | AD7: 220747 | AE7: 297392 | AF7: 316199 | AG7: 298085 | AH7: 294866 | AI7: 307003 | AL7: =IFERROR((AI7/AD7)^(1/5)-1,"") -> 0.068192592 | AM7: =IFERROR(PRODUCT(1+AE8,1+AF8,1+AG8,1+AH8,1+AI8)^(1/5)-1,"") -> 0.068192592 | AO7: =IFERROR((AI7/AF7)^(1/3)-1,"") -> -0.0097898453 | AP7: =IFERROR(PRODUCT(1+AG8,1+AH8,1+AI8)^(1/3)-1,"") -> -0.0097898453
A8: % Growth | AD8: =IFERROR(AD7/AC7-1,"") -> 0.032092312 | AE8: =IFERROR(AE7/AD7-1,"") -> 0.34720744 | AF8: =IFERROR(AF7/AE7-1,"") -> 0.063239764 | AG8: =IFERROR(AG7/AF7-1,"") -> -0.057286709 | AH8: =IFERROR(AH7/AG7-1,"") -> -0.010798933 | AI8: =IFERROR(AI7/AH7-1,"") -> 0.04116107 | AL8: =IFERROR((AI9/AD9)^(1/5)-1,"") -> 0.15214287 | AM8: =IFERROR(PRODUCT(1+AE10,1+AF10,1+AG10,1+AH10,1+AI10)^(1/5)-1,"") -> 0.15214287 | AO8: =IFERROR((AI9/AF9)^(1/3)-1,"") -> 0.11792955 | AP8: =IFERROR(PRODUCT(1+AG10,1+AH10,1+AI10)^(1/3)-1,"") -> 0.11792955
A9: Services Net Sales | B9: 0 | C9: 0 | D9: 0 | E9: 0 | F9: 0 | G9: 0 | H9: 0 | I9: 0 | J9: 0 | K9: 0 | L9: 0 | M9: 0 | N9: 0 | O9: 0 | P9: 0 | Q9: 0 | R9: 0 | S9: 0 | T9: 0 | U9: 0 | V9: 0 | W9: 0 | X9: 0 | Y9: 0 | Z9: 0 | AA9: 0 | AB9: 0 | AC9: 46291 | AD9: 53768 | AE9: 68425 | AF9: 78129 | AG9: 85200 | AH9: 96169 | AI9: 109158
A10: % Growth | AD10: =IFERROR(AD9/AC9-1,"") -> 0.16152168 | AE10: =IFERROR(AE9/AD9-1,"") -> 0.27259708 | AF10: =IFERROR(AF9/AE9-1,"") -> 0.14181951 | AG10: =IFERROR(AG9/AF9-1,"") -> 0.090504166 | AH10: =IFERROR(AH9/AG9-1,"") -> 0.12874413 | AI10: =IFERROR(AI9/AH9-1,"") -> 0.13506431 | AL10: 33yr | AM10: Check | AO10: 20yr | AP10: Check | AR10: 10yr | AS10: Check | AU10: 5yr | AV10: Check
A11: Net Sales / Revenue | B11: 7086.542 | C11: 7976.954 | D11: 9188.748 | E11: 11062 | F11: 9833 | G11: 7081 | H11: 5941 | I11: 6134 | J11: 7983 | K11: 5363 | L11: 5742 | M11: 6207 | N11: 8279 | O11: 13931 | P11: 19315 | Q11: 24578 | R11: 37491 | S11: 42905 | T11: 65225 | U11: 108249 | V11: 156508 | W11: 170910 | X11: 182795 | Y11: 233715 | Z11: 215639 | AA11: 229234 | AB11: 265595 | AC11: =AC9+AC7 -> 260174 | AD11: =AD9+AD7 -> 274515 | AE11: =AE9+AE7 -> 365817 | AF11: =AF9+AF7 -> 394328 | AG11: =AG9+AG7 -> 383285 | AH11: =AH9+AH7 -> 391035 | AI11: =AI9+AI7 -> 416161 | AL11: =IFERROR((AI11/B11)^(1/33)-1,"") -> 0.13136 | AM11: =IFERROR(PRODUCT(1+C12,1+D12,1+E12,1+F12,1+G12,1+H12,1+I12,1+J12,1+K12,1+L12,1+M12,1+N12,1+O12,1+P12,1+Q12,1+R12,1+S12,1+T12,1+U12,1+V12,1+W12,1+X12,1+Y12,1+Z12,1+AA12,1+AB12,1+AC12,1+AD12,1+AE12,1+AF12,1+AG12,1+AH12,1+AI12)^(1/33)-1,"") -> 0.13136 | AO11: =IFERROR((AI11/O11)^(1/20)-1, "") -> 0.18512444 | AP11: =IFERROR(PRODUCT(1+P12,1+Q12,1+R12,1+S12,1+T12,1+U12,1+V12,1+W12,1+X12,1+Y12,1+Z12,1+AA12,1+AB12,1+AC12,1+AD12,1+AE12,1+AF12,1+AG12,1+AH12,1+AI12)^(1/20)-1,"") -> 0.18512444 | AR11: =IFERROR((AI11/Y11)^(1/10)-1,"") -> 0.059393927 | AS11: =IFERROR(PRODUCT(1+Z12,1+AA12,1+AB12,1+AC12,1+AD12,1+AE12,1+AF12,1+AG12,1+AH12,1+AI12)^(1/10)-1,"") -> 0.059393927 | AU11: =IFERROR((AI11/AD11)^(1/5)-1,"") -> 0.086773549 | AV11: =IFERROR(PRODUCT(1+AE12,1+AF12,1+AG12,1+AH12,1+AI12)^(1/5)-1,"") -> 0.086773549
A12: % Growth | C12: =IFERROR(C11/B11-1,"") -> 0.12564831 | D12: =IFERROR(D11/C11-1,"") -> 0.15191187 | E12: =IFERROR(E11/D11-1,"") -> 0.20386368 | F12: =IFERROR(F11/E11-1,"") -> -0.11110107 | G12: =IFERROR(G11/F11-1,"") -> -0.27987389 | H12: =IFERROR(H11/G11-1,"") -> -0.16099421 | I12: =IFERROR(I11/H11-1,"") -> 0.032486113 | J12: =IFERROR(J11/I11-1,"") -> 0.30143463 | ... AI12: =IFERROR(AI11/AH11-1,"") -> 0.064255118
A14: Products Cost of Sales | B14: 0 | C14: 0 | D14: 0 | E14: 0 | F14: 0 | G14: 0 | H14: 0 | I14: 0 | J14: 0 | K14: 0 | L14: 0 | M14: 0 | N14: 0 | O14: 0 | P14: 0 | Q14: 0 | R14: 0 | S14: 0 | T14: 0 | U14: 0 | V14: 0 | W14: 0 | X14: 0 | Y14: 0 | Z14: 0 | AA14: 0 | AB14: 0 | AC14: 144996 | AD14: 151286 | AE14: 192266 | AF14: 201471 | AG14: 189282 | AH14: 185233 | AI14: 194116
A15: % Growth | AD15: =IFERROR(AD14/AC14-1,"") -> 0.043380507 | AE15: =IFERROR(AE14/AD14-1,"") -> 0.27087768 | AF15: =IFERROR(AF14/AE14-1,"") -> 0.04787638 | AG15: =IFERROR(AG14/AF14-1,"") -> -0.060500022 | AH15: =IFERROR(AH14/AG14-1,"") -> -0.021391363 | AI15: =IFERROR(AI14/AH14-1,"") -> 0.047955818
A16: Services Cost of Sales | B16: 0 | C16: 0 | D16: 0 | E16: 0 | F16: 0 | G16: 0 | H16: 0 | I16: 0 | J16: 0 | K16: 0 | L16: 0 | M16: 0 | N16: 0 | O16: 0 | P16: 0 | Q16: 0 | R16: 0 | S16: 0 | T16: 0 | U16: 0 | V16: 0 | W16: 0 | X16: 0 | Y16: 0 | Z16: 0 | AA16: 0 | AB16: 0 | AC16: 16786 | AD16: 18273 | AE16: 20715 | AF16: 22075 | AG16: 24855 | AH16: 25119 | AI16: 26844
A17: % Growth | AD17: =IFERROR(AD16/AC16-1,"") -> 0.088585726 | AE17: =IFERROR(AE16/AD16-1,"") -> 0.1336398 | AF17: =IFERROR(AF16/AE16-1,"") -> 0.065652909 | AG17: =IFERROR(AG16/AF16-1,"") -> 0.12593431 | AH17: =IFERROR(AH16/AG16-1,"") -> 0.010621605 | AI17: =IFERROR(AI16/AH16-1,"") -> 0.068673116
A18: Total COGS | B18: 3991.337 | C18: 5248.834 | D18: 6844.915 | E18: 8204 | F18: 8865 | G18: 5713 | H18: 4462 | I18: 4438 | J18: 5817 | K18: 4128 | L18: 4139 | M18: 4499 | N18: 6022 | O18: 9889 | P18: 13717 | Q18: 16426 | R18: 24294 | S18: 25683 | T18: 39541 | U18: 64431 | V18: 87846 | W18: 106606 | X18: 112258 | Y18: 140089 | Z18: 131376 | AA18: 141048 | AB18: 163756 | AC18: =AC16+AC14 -> 161782 | AD18: =AD16+AD14 -> 169559 | AE18: =AE16+AE14 -> 212981 | AF18: =AF16+AF14 -> 223546 | AG18: =AG16+AG14 -> 214137 | AH18: =AH16+AH14 -> 210352 | AI18: =AI16+AI14 -> 220960
A19: % Growth | C19: =IFERROR(C18/B18-1,"") -> 0.31505658 | D19: =IFERROR(D18/C18-1,"") -> 0.30408296 | E19: =IFERROR(E18/D18-1,"") -> 0.19855396 | F19: =IFERROR(F18/E18-1,"") -> 0.080570453 | G19: =IFERROR(G18/F18-1,"") -> -0.35555556 | H19: =IFERROR(H18/G18-1,"") -> -0.21897427 | I19: =IFERROR(I18/H18-1,"") -> -0.0053787539 | J19: =IFERROR(J18/I18-1,"") -> 0.31072555 | ... AI19: =IFERROR(AI18/AH18-1,"") -> 0.050429756 | AL19: 33yr | AM19: Check | AO19: 20yr | AP19: Check | AR19: 10yr | AS19: Check | AU19: 5yr | AV19: Check
A20: Products Gross Profit | B20: =B7-B14 -> 0 | C20: =C7-C14 -> 0 | D20: =D7-D14 -> 0 | E20: =E7-E14 -> 0 | F20: =F7-F14 -> 0 | G20: =G7-G14 -> 0 | H20: =H7-H14 -> 0 | I20: =I7-I14 -> 0 | ... AI20: =AI7-AI14 -> 112887
A21: % Growth | AD21: =IFERROR(AD20/AC20-1,"") -> 0.0083324865 | AE21: =IFERROR(AE20/AD20-1,"") -> 0.51345359 | AF21: =IFERROR(AF20/AE20-1,"") -> 0.091338013 | AG21: =IFERROR(AG20/AF20-1,"") -> -0.051643888 | AH21: =IFERROR(AH20/AG20-1,"") -> 0.0076284661 | AI21: =IFERROR(AI20/AH20-1,"") -> 0.029680844
A22: Services Gross Profit | B22: =B9-B16 -> 0 | C22: =C9-C16 -> 0 | D22: =D9-D16 -> 0 | E22: =E9-E16 -> 0 | F22: =F9-F16 -> 0 | G22: =G9-G16 -> 0 | H22: =H9-H16 -> 0 | I22: =I9-I16 -> 0 | ... AI22: =AI9-AI16 -> 82314
A23: % Growth | AD23: =IFERROR(AD22/AC22-1,"") -> 0.20301644 | AE23: =IFERROR(AE22/AD22-1,"") -> 0.34413298 | AF23: =IFERROR(AF22/AE22-1,"") -> 0.17488996 | AG23: =IFERROR(AG22/AF22-1,"") -> 0.076551183 | AH23: =IFERROR(AH22/AG22-1,"") -> 0.17739664 | AI23: =IFERROR(AI22/AH22-1,"") -> 0.15853624 | AL23: 33yr | AM23: Check | AO23: 20yr | AP23: Check | AR23: 10yr | AS23: Check | AU23: 5yr | AV23: Check
A24: Gross Profit | B24: =B11-B18 -> 3095.205 | C24: =C11-C18 -> 2728.12 | D24: =D11-D18 -> 2343.833 | E24: =E11-E18 -> 2858 | F24: =F11-F18 -> 968 | G24: =G11-G18 -> 1368 | H24: =H11-H18 -> 1479 | I24: =I11-I18 -> 1696 | ... AI24: =AI11-AI18 -> 195201 | AL24: =IFERROR((AI24/B24)^(1/33)-1,"") -> 0.13380709 | AM24: =IFERROR(PRODUCT(1+C25,1+D25,1+E25,1+F25,1+G25,1+H25,1+I25,1+J25,1+K25,1+L25,1+M25,1+N25,1+O25,1+P25,1+Q25,1+R25,1+S25,1+T25,1+U25,1+V25,1+W25,1+X25,1+Y25,1+Z25,1+AA25,1+AB25,1+AC25,1+AD25,1+AE25,1+AF25,1+AG25,1+AH25,1+AI25)^(1/33)-1,"") -> 0.13380709 | AO24: =IFERROR((AI24/O24)^(1/20)-1, "") -> 0.21393179 | AP24: =IFERROR(PRODUCT(1+P25,1+Q25,1+R25,1+S25,1+T25,1+U25,1+V25,1+W25,1+X25,1+Y25,1+Z25,1+AA25,1+AB25,1+AC25,1+AD25,1+AE25,1+AF25,1+AG25,1+AH25,1+AI25)^(1/20)-1,"") -> 0.21393179 | AR24: =IFERROR((AI24/Y24)^(1/10)-1,"") -> 0.076238582 | AS24: =IFERROR(PRODUCT(1+Z25,1+AA25,1+AB25,1+AC25,1+AD25,1+AE25,1+AF25,1+AG25,1+AH25,1+AI25)^(1/10)-1,"") -> 0.076238582 | AU24: =IFERROR((AI24/AD24)^(1/5)-1,"") -> 0.13212649 | AV24: =IFERROR(PRODUCT(1+AE25,1+AF25,1+AG25,1+AH25,1+AI25)^(1/5)-1,"") -> 0.13212649
A25: % Growth | C25: =IFERROR(C24/B24-1,"") -> -0.11859796 | D25: =IFERROR(D24/C24-1,"") -> -0.14086147 | E25: =IFERROR(E24/D24-1,"") -> 0.21937015 | F25: =IFERROR(F24/E24-1,"") -> -0.66130161 | G25: =IFERROR(G24/F24-1,"") -> 0.41322314 | H25: =IFERROR(H24/G24-1,"") -> 0.081140351 | I25: =IFERROR(I24/H24-1,"") -> 0.14672076 | J25: =IFERROR(J24/I24-1,"") -> 0.27712264 | ... AI25: =IFERROR(AI24/AH24-1,"") -> 0.080350669
AL26: 33yr | AM26: Check | AO26: 20yr | AP26: Check | AR26: 10yr | AS26: Check | AU26: 5yr | AV26: Check
A27: Research & Development | B27: 602.135 | C27: 664.564 | D27: 564.303 | E27: 614 | F27: 604 | G27: 485 | H27: 303 | I27: 314 | J27: 380 | K27: 430 | L27: 446 | M27: 471 | N27: 491 | O27: 535 | P27: 712 | Q27: 782 | R27: 1109 | S27: 1333 | T27: 1782 | U27: 2429 | V27: 3381 | W27: 4475 | X27: 6041 | Y27: 8067 | Z27: 10045 | AA27: 11581 | AB27: 14236 | AC27: 16217 | AD27: 18752 | AE27: 21914 | AF27: 26251 | AG27: 29915 | AH27: 31370 | AI27: 34550 | AL27: =IFERROR((AI27/B27)^(1/33)-1,"") -> 0.13056512 | AM27: =IFERROR(PRODUCT(1+C28,1+D28,1+E28,1+F28,1+G28,1+H28,1+I28,1+J28,1+K28,1+L28,1+M28,1+N28,1+O28,1+P28,1+Q28,1+R28,1+S28,1+T28,1+U28,1+V28,1+W28,1+X28,1+Y28,1+Z28,1+AA28,1+AB28,1+AC28,1+AD28,1+AE28,1+AF28,1+AG28,1+AH28,1+AI28)^(1/33)-1,"") -> 0.13056512 | AO27: =IFERROR((AI27/O27)^(1/20)-1, "") -> 0.23169935 | AP27: =IFERROR(PRODUCT(1+P28,1+Q28,1+R28,1+S28,1+T28,1+U28,1+V28,1+W28,1+X28,1+Y28,1+Z28,1+AA28,1+AB28,1+AC28,1+AD28,1+AE28,1+AF28,1+AG28,1+AH28,1+AI28)^(1/20)-1,"") -> 0.23169935 | AR27: =IFERROR((AI27/Y27)^(1/10)-1,"") -> 0.15657446 | AS27: =IFERROR(PRODUCT(1+Z28,1+AA28,1+AB28,1+AC28,1+AD28,1+AE28,1+AF28,1+AG28,1+AH28,1+AI28)^(1/10)-1,"") -> 0.15657446 | AU27: =IFERROR((AI27/AD27)^(1/5)-1,"") -> 0.13000429 | AV27: =IFERROR(PRODUCT(1+AE28,1+AF28,1+AG28,1+AH28,1+AI28)^(1/5)-1,"") -> 0.13000429
A28: % Growth | C28: =IFERROR(C27/B27-1,"") -> 0.10367941 | D28: =IFERROR(D27/C27-1,"") -> -0.15086734 | E28: =IFERROR(E27/D27-1,"") -> 0.088067935 | F28: =IFERROR(F27/E27-1,"") -> -0.016286645 | G28: =IFERROR(G27/F27-1,"") -> -0.19701987 | H28: =IFERROR(H27/G27-1,"") -> -0.37525773 | I28: =IFERROR(I27/H27-1,"") -> 0.03630363 | J28: =IFERROR(J27/I27-1,"") -> 0.21019108 | ... AI28: =IFERROR(AI27/AH27-1,"") -> 0.10137074
A29: Selling, General & Administrative | B29: 1687.262 | C29: 1632.362 | D29: 1384.111 | E29: 1583 | F29: 1568 | G29: 1286 | H29: 908 | I29: 996 | J29: 1166 | K29: 1138 | L29: 1111 | M29: 1212 | N29: 1430 | O29: 1864 | P29: 2433 | Q29: 2963 | R29: 3761 | S29: 4149 | T29: 5517 | U29: 7599 | V29: 10040 | W29: 10830 | X29: 11993 | Y29: 14329 | Z29: 14194 | AA29: 15261 | AB29: 16705 | AC29: 18245 | AD29: 19916 | AE29: 21973 | AF29: 25094 | AG29: 24932 | AH29: 26097 | AI29: 27601 | AL29: =IFERROR((AI29/B29)^(1/33)-1,"") -> 0.088378789 | AM29: =IFERROR(PRODUCT(1+C30,1+D30,1+E30,1+F30,1+G30,1+H30,1+I30,1+J30,1+K30,1+L30,1+M30,1+N30,1+O30,1+P30,1+Q30,1+R30,1+S30,1+T30,1+U30,1+V30,1+W30,1+X30,1+Y30,1+Z30,1+AA30,1+AB30,1+AC30,1+AD30,1+AE30,1+AF30,1+AG30,1+AH30,1+AI30)^(1/33)-1,"") -> 0.088378789 | AO29: =IFERROR((AI29/O29)^(1/20)-1, "") -> 0.14425797 | AP29: =IFERROR(PRODUCT(1+P30,1+Q30,1+R30,1+S30,1+T30,1+U30,1+V30,1+W30,1+X30,1+Y30,1+Z30,1+AA30,1+AB30,1+AC30,1+AD30,1+AE30,1+AF30,1+AG30,1+AH30,1+AI30)^(1/20)-1,"") -> 0.14425797 | AR29: =IFERROR((AI29/Y29)^(1/10)-1,"") -> 0.067753229 | AS29: =IFERROR(PRODUCT(1+Z30,1+AA30,1+AB30,1+AC30,1+AD30,1+AE30,1+AF30,1+AG30,1+AH30,1+AI30)^(1/10)-1,"") -> 0.067753229 | AU29: =IFERROR((AI29/AD29)^(1/5)-1,"") -> 0.067442622 | AV29: =IFERROR(PRODUCT(1+AE30,1+AF30,1+AG30,1+AH30,1+AI30)^(1/5)-1,"") -> 0.067442622
A30: % Growth | C30: =IFERROR(C29/B29-1,"") -> -0.032537922 | D30: =IFERROR(D29/C29-1,"") -> -0.15208085 | E30: =IFERROR(E29/D29-1,"") -> 0.1436944 | F30: =IFERROR(F29/E29-1,"") -> -0.0094756791 | G30: =IFERROR(G29/F29-1,"") -> -0.17984694 | H30: =IFERROR(H29/G29-1,"") -> -0.29393468 | I30: =IFERROR(I29/H29-1,"") -> 0.0969163 | J30: =IFERROR(J29/I29-1,"") -> 0.17068273 | ... AI30: =IFERROR(AI29/AH29-1,"") -> 0.057631145
A31: Restructuring Costs | B31: 0 | C31: 320.856 | D31: -126.855 | E31: -23 | F31: 179 | G31: 217 | H31: 0 | I31: 27 | J31: 8 | K31: 0 | L31: 30 | M31: 26 | N31: 23 | O31: 0 | P31: 0 | Q31: 0 | R31: 0 | S31: 0 | T31: 0 | U31: 0 | V31: 0 | W31: 0 | X31: 0 | Y31: 0 | Z31: 0 | AA31: 0 | AB31: 0 | AC31: 0 | AD31: 0 | AE31: 0 | AF31: 0 | AG31: 0 | AH31: 0 | AI31: 0
A32: % Growth | C32: =IFERROR(C31/B31-1,"") | D32: =IFERROR(D31/C31-1,"") -> -1.3953643 | E32: =IFERROR(E31/D31-1,"") -> -0.81869063 | F32: =IFERROR(F31/E31-1,"") -> -8.7826087 | G32: =IFERROR(G31/F31-1,"") -> 0.2122905 | H32: =IFERROR(H31/G31-1,"") -> -1 | I32: =IFERROR(I31/H31-1,"") | J32: =IFERROR(J31/I31-1,"") -> -0.7037037 | ... AI32: =IFERROR(AI31/AH31-1,"")
A33: In-Process R&D | B33: 0 | C33: 0 | D33: 0 | E33: 0 | F33: 0 | G33: 375 | H33: 7 | I33: 0 | J33: 0 | K33: 11 | L33: 1 | M33: 0 | N33: 0 | O33: 0 | P33: 0 | Q33: 0 | R33: 0 | S33: 0 | T33: 0 | U33: 0 | V33: 0 | W33: 0 | X33: 0 | Y33: 0 | Z33: 0 | AA33: 0 | AB33: 0 | AC33: 0 | AD33: 0 | AE33: 0 | AF33: 0 | AG33: 0 | AH33: 0 | AI33: 0
A34: % Growth | C34: =IFERROR(C33/B33-1,"") | D34: =IFERROR(D33/C33-1,"") | E34: =IFERROR(E33/D33-1,"") | F34: =IFERROR(F33/E33-1,"") | G34: =IFERROR(G33/F33-1,"") | H34: =IFERROR(H33/G33-1,"") -> -0.98133333 | I34: =IFERROR(I33/H33-1,"") -> -1 | J34: =IFERROR(J33/I33-1,"") | ... AI34: =IFERROR(AI33/AH33-1,"")
A35: Termination of License Agreement | B35: 0 | C35: 0 | D35: 0 | E35: 0 | F35: 0 | G35: 75 | H35: 0 | I35: 0 | J35: 0 | K35: 0 | L35: 0 | M35: 0 | N35: 0 | O35: 0 | P35: 0 | Q35: 0 | R35: 0 | S35: 0 | T35: 0 | U35: 0 | V35: 0 | W35: 0 | X35: 0 | Y35: 0 | Z35: 0 | AA35: 0 | AB35: 0 | AC35: 0 | AD35: 0 | AE35: 0 | AF35: 0 | AG35: 0 | AH35: 0 | AI35: 0
A36: % Growth | C36: =IFERROR(C35/B35-1,"") | D36: =IFERROR(D35/C35-1,"") | E36: =IFERROR(E35/D35-1,"") | F36: =IFERROR(F35/E35-1,"") | G36: =IFERROR(G35/F35-1,"") | H36: =IFERROR(H35/G35-1,"") -> -1 | I36: =IFERROR(I35/H35-1,"") | J36: =IFERROR(J35/I35-1,"") | ... AI36: =IFERROR(AI35/AH35-1,"")
A37: Executive Bonus / Special Compensation | B37: 0 | C37: 0 | D37: 0 | E37: 0 | F37: 0 | G37: 0 | H37: 0 | I37: 0 | J37: 90 | K37: 0 | L37: -2 | M37: 0 | N37: 0 | O37: 0 | P37: 0 | Q37: 0 | R37: 0 | S37: 0 | T37: 0 | U37: 0 | V37: 0 | W37: 0 | X37: 0 | Y37: 0 | Z37: 0 | AA37: 0 | AB37: 0 | AC37: 0 | AD37: 0 | AE37: 0 | AF37: 0 | AG37: 0 | AH37: 0 | AI37: 0
A38: % Growth | B38: =IFERROR(B37/A37-1,"") | C38: =IFERROR(C37/B37-1,"") | D38: =IFERROR(D37/C37-1,"") | E38: =IFERROR(E37/D37-1,"") | F38: =IFERROR(F37/E37-1,"") | G38: =IFERROR(G37/F37-1,"") | H38: =IFERROR(H37/G37-1,"") | I38: =IFERROR(I37/H37-1,"") | ... AI38: =IFERROR(AI37/AH37-1,"")
A39: Total Operating Expenses | B39: =B27+B29+B31+B33+B35+B37 -> 2289.397 | C39: =C27+C29+C31+C33+C35+C37 -> 2617.782 | D39: =D27+D29+D31+D33+D35+D37 -> 1821.559 | E39: =E27+E29+E31+E33+E35+E37 -> 2174 | F39: =F27+F29+F31+F33+F35+F37 -> 2351 | G39: =G27+G29+G31+G33+G35+G37 -> 2438 | H39: =H27+H29+H31+H33+H35+H37 -> 1218 | I39: =I27+I29+I31+I33+I35+I37 -> 1337 | ... AI39: =AI27+AI29+AI31+AI33+AI35+AI37 -> 62151
A40: % Growth | C40: =IFERROR(C39/B39-1,"") -> 0.14343733 | D40: =IFERROR(D39/C39-1,"") -> -0.3041594 | E40: =IFERROR(E39/D39-1,"") -> 0.19348316 | F40: =IFERROR(F39/E39-1,"") -> 0.081416743 | G40: =IFERROR(G39/F39-1,"") -> 0.03700553 | H40: =IFERROR(H39/G39-1,"") -> -0.50041017 | I40: =IFERROR(I39/H39-1,"") -> 0.097701149 | J40: =IFERROR(J39/I39-1,"") -> 0.22961855 | ... AI40: =IFERROR(AI39/AH39-1,"") -> 0.081507648 | AL40: 33yr | AM40: Check | AO40: 20yr | AP40: Check | AR40: 10yr | AS40: Check | AU40: 5yr | AV40: Check
A41: Operating Income (EBIT) | B41: =B24-B39 -> 805.808 | C41: =C24-C39 -> 110.338 | D41: =D24-D39 -> 522.274 | E41: =E24-E39 -> 684 | F41: =F24-F39 -> -1383 | G41: =G24-G39 -> -1070 | H41: =H24-H39 -> 261 | I41: =I24-I39 -> 359 | ... AI41: =AI24-AI39 -> 133050 | AL41: =IFERROR((AI41/B41)^(1/33)-1,"") -> 0.16736201 | AM41: =IFERROR(PRODUCT(1+C42,1+D42,1+E42,1+F42,1+G42,1+H42,1+I42,1+J42,1+K42,1+L42,1+M42,1+N42,1+O42,1+P42,1+Q42,1+R42,1+S42,1+T42,1+U42,1+V42,1+W42,1+X42,1+Y42,1+Z42,1+AA42,1+AB42,1+AC42,1+AD42,1+AE42,1+AF42,1+AG42,1+AH42,1+AI42)^(1/33)-1,"") -> 0.16736201 | AO41: =IFERROR((AI41/O41)^(1/20)-1, "") -> 0.24571549 | AP41: =IFERROR(PRODUCT(1+P42,1+Q42,1+R42,1+S42,1+T42,1+U42,1+V42,1+W42,1+X42,1+Y42,1+Z42,1+AA42,1+AB42,1+AC42,1+AD42,1+AE42,1+AF42,1+AG42,1+AH42,1+AI42)^(1/20)-1,"") -> 0.24571549 | AR41: =IFERROR((AI41/Y41)^(1/10)-1,"") -> 0.064474332 | AS41: =IFERROR(PRODUCT(1+Z42,1+AA42,1+AB42,1+AC42,1+AD42,1+AE42,1+AF42,1+AG42,1+AH42,1+AI42)^(1/10)-1,"") -> 0.064474332 | AU41: =IFERROR((AI41/AD41)^(1/5)-1,"") -> 0.14951857 | AV41: =IFERROR(PRODUCT(1+AE42,1+AF42,1+AG42,1+AH42,1+AI42)^(1/5)-1,"") -> 0.14951857
A42: % Growth | C42: =IFERROR(C41/B41-1,"") -> -0.8630716 | D42: =IFERROR(D41/C41-1,"") -> 3.733401 | E42: =IFERROR(E41/D41-1,"") -> 0.30965738 | F42: =IFERROR(F41/E41-1,"") -> -3.0219298 | G42: =IFERROR(G41/F41-1,"") -> -0.2263196 | H42: =IFERROR(H41/G41-1,"") -> -1.2439252 | I42: =IFERROR(I41/H41-1,"") -> 0.37547893 | J42: =IFERROR(J41/I41-1,"") -> 0.454039 | ... AI42: =IFERROR(AI41/AH41-1,"") -> 0.079811063
A44: Gains on Sales of Investments | B44: 0 | C44: 0 | D44: 0 | E44: 0 | F44: 0 | G44: 0 | H44: 40 | I44: 230 | J44: 0 | K44: 0 | L44: 0 | M44: 0 | N44: 0 | O44: 0 | P44: 0 | Q44: 0 | R44: 0 | S44: 0 | T44: 0 | U44: 0 | V44: 0 | W44: 0 | X44: 0 | Y44: 0 | Z44: 0 | AA44: 0 | AB44: 0 | AC44: 0 | AD44: 0 | AE44: 0 | AF44: 0 | AG44: 0 | AH44: 0 | AI44: 0
...

Sheet Apple Unit Volumes
A1: Units Sold ('000)
A3: Product | B3: 1994 | C3: 1995 | D3: 1996 | E3: 1997 | F3: 1998 | G3: 1999 | H3: 2000 | I3: 2001 | J3: 2002 | K3: 2003 | L3: 2004 | M3: 2005 | N3: 2006 | O3: 2007 | P3: 2008 | Q3: 2009 | R3: 2010 | S3: 2011 | T3: 2012 | U3: 2013 | V3: 2014 | W3: 2015 | X3: 2016 | Y3: 2017 | Z3: 2018 | AA3: 2019 | AB3: 2020 | AC3: 2021 | AD3: 2022 | AE3: 2023 | AF3: 2024 | AG3: 2025 | AJ3: Source (2007 - 2018) | AK3: Source (2019 - 2025
A4: iPhone | B4: 0 | C4: 0 | D4: 0 | E4: 0 | F4: 0 | G4: 0 | H4: 0 | I4: 0 | J4: 0 | K4: 0 | L4: 0 | M4: 0 | N4: 0 | O4: 1389 | P4: 11627 | Q4: 20731 | R4: 39989 | S4: 72293 | T4: 125046 | U4: 150257 | V4: 169219 | W4: 231218 | X4: 211884 | Y4: 216756 | Z4: 217722 | AA4: 187200 | AB4: 196900 | AC4: 242000 | AD4: 232200 | AE4: 231300 | AF4: 232100 | AG4: 247000 | AJ4: Financial Statements | AK4: https://backlinko.com/iphone-users?
A5: % Growth | P5: =IFERROR(P4/O4-1,"") -> 7.3707703 | Q5: =IFERROR(Q4/P4-1,"") -> 0.78300507 | R5: =IFERROR(R4/Q4-1,"") -> 0.92894699 | S5: =IFERROR(S4/R4-1,"") -> 0.80782215 | T5: =IFERROR(T4/S4-1,"") -> 0.72971104 | U5: =IFERROR(U4/T4-1,"") -> 0.20161381 | V5: =IFERROR(V4/U4-1,"") -> 0.12619712 | W5: =IFERROR(W4/V4-1,"") -> 0.36638321 | ... AG5: =IFERROR(AG4/AF4-1,"") -> 0.064196467
A6: Mac | E6: 2874 | F6: 2763 | G6: 3448 | H6: 4558 | I6: 3087 | J6: 3101 | K6: 3012 | L6: 3290 | M6: 4534 | N6: 5303 | O6: 7051 | P6: 9715 | Q6: 10396 | R6: 13662 | S6: 16735 | T6: 18158 | U6: 16341 | V6: 18906 | W6: 20587 | X6: 18484 | Y6: 19251 | Z6: 18209 | AA6: 17500 | AB6: 20200 | AC6: 25700 | AD6: 26100 | AE6: 22100 | AF6: 23000 | AG6: 25600 | AJ6: Financial Statements | AK6: https://www.businessofapps.com/data/apple-statistics/?utm_source=chatgpt.com
A7: % Growth | F7: =IFERROR(F6/E6-1,"") -> -0.038622129 | G7: =IFERROR(G6/F6-1,"") -> 0.24791893 | H7: =IFERROR(H6/G6-1,"") -> 0.32192575 | I7: =IFERROR(I6/H6-1,"") -> -0.32272927 | J7: =IFERROR(J6/I6-1,"") -> 0.0045351474 | K7: =IFERROR(K6/J6-1,"") -> -0.028700419 | L7: =IFERROR(L6/K6-1,"") -> 0.092297477 | M7: =IFERROR(M6/L6-1,"") -> 0.3781155 | ... AG7: =IFERROR(AG6/AF6-1,"") -> 0.11304348
A8: iPad | B8: 0 | C8: 0 | D8: 0 | E8: 0 | F8: 0 | G8: 0 | H8: 0 | I8: 0 | J8: 0 | K8: 0 | L8: 0 | M8: 0 | N8: 0 | O8: 0 | P8: 0 | Q8: 0 | R8: 7458 | S8: 32394 | T8: 58310 | U8: 71033 | V8: 67977 | W8: 54856 | X8: 45590 | Y8: 43753 | Z8: 43535 | AA8: 45200 | AB8: 71100 | AC8: 57800 | AD8: 61800 | AE8: 49500 | AF8: 52100 | AG8: 58300 | AJ8: Financial Statements | AK8: https://www.businessofapps.com/data/apple-statistics/?utm_source=chatgpt.com
A9: % Growth | S9: =IFERROR(S8/R8-1,"") -> 3.3435237 | T9: =IFERROR(T8/S8-1,"") -> 0.8000247 | U9: =IFERROR(U8/T8-1,"") -> 0.21819585 | V9: =IFERROR(V8/U8-1,"") -> -0.043022257 | W9: =IFERROR(W8/V8-1,"") -> -0.19302117 | X9: =IFERROR(X8/W8-1,"") -> -0.16891498 | Y9: =IFERROR(Y8/X8-1,"") -> -0.040293924 | Z9: =IFERROR(Z8/Y8-1,"") -> -0.0049825155 | ... AG9: =IFERROR(AG8/AF8-1,"") -> 0.11900192
A11: Active iPhone, Mac, iPad | AJ11: Source
A12: iPhone | P12: 10000 | Q12: 25000 | R12: 60000 | S12: 115000 | T12: 206000 | U12: 329000 | V12: 442000 | W12: 569000 | X12: 710000 | Y12: 814000 | Z12: 888000 | AA12: 948000 | AB12: 1042000 | AC12: 1231000 | AD12: 1334000 | AE12: 1382000 | AF12: 1404000 | AG12: 1595000 | AJ12: https://backlinko.com/iphone-users?
A13: % Growth | Q13: =IFERROR(Q12/P12-1,"") -> 1.5 | R13: =IFERROR(R12/Q12-1,"") -> 1.4 | S13: =IFERROR(S12/R12-1,"") -> 0.91666667 | T13: =IFERROR(T12/S12-1,"") -> 0.79130435 | U13: =IFERROR(U12/T12-1,"") -> 0.59708738 | V13: =IFERROR(V12/U12-1,"") -> 0.34346505 | W13: =IFERROR(W12/V12-1,"") -> 0.28733032 | X13: =IFERROR(X12/W12-1,"") -> 0.24780316 | ... AG13: =IFERROR(AG12/AF12-1,"") -> 0.13603989
A14: Mac | U14: 70400 | V14: 77600 | W14: 86000 | X14: 91900 | Y14: 97900 | Z14: 103600 | AA14: 109400 | AB14: 120000 | AC14: 134300 | AD14: 144600 | AE14: 154100 | AF14: =AE14*(1+AF15) -> 172463.58 | AG14: 233000 | AJ14: https://reportify-1252068037.cos.ap-beijing.myqcloud.com/media/production/s_0132ddf6_0132ddf6f76452b09a6eaf33303689a1.pdf | AL14: https://asymco.com/2026/04/24/the-composition-of-active-devices/?utm_source=chatgpt.com
A15: % Growth | V15: =IFERROR(V14/U14-1,"") -> 0.10227273 | W15: =IFERROR(W14/V14-1,"") -> 0.10824742 | X15: =IFERROR(X14/W14-1,"") -> 0.068604651 | Y15: =IFERROR(Y14/X14-1,"") -> 0.065288357 | Z15: =IFERROR(Z14/Y14-1,"") -> 0.058222676 | AA15: =IFERROR(AA14/Z14-1,"") -> 0.055984556 | AB15: =IFERROR(AB14/AA14-1,"") -> 0.096892139 | AC15: =IFERROR(AC14/AB14-1,"") -> 0.11916667 | ... AE15: =IFERROR(AE14/AD14-1,"") -> 0.065698479 | AF15: =AC15 -> 0.11916667 | AG15: =IFERROR(AG14/AF14-1,"") -> 0.35100985
A16: iPad | U16: 121000 | V16: 195200 | W16: 258600 | X16: 293400 | Y16: 310800 | Z16: 296400 | AA16: 298200 | AB16: 311500 | AC16: 339200 | AD16: 377800 | AE16: 405700 | AF16: =AE16*(1+AF17) -> 435660.38 | AG16: 442000 | AJ16: https://reportify-1252068037.cos.ap-beijing.myqcloud.com/media/production/s_0132ddf6_0132ddf6f76452b09a6eaf33303689a1.pdf | AL16: https://asymco.com/2026/04/24/the-composition-of-active-devices/?utm_source=chatgpt.com
A17: % Growth | V17: =IFERROR(V16/U16-1,"") -> 0.61322314 | W17: =IFERROR(W16/V16-1,"") -> 0.32479508 | X17: =IFERROR(X16/W16-1,"") -> 0.13457077 | Y17: =IFERROR(Y16/X16-1,"") -> 0.059304703 | Z17: =IFERROR(Z16/Y16-1,"") -> -0.046332046 | AA17: =IFERROR(AA16/Z16-1,"") -> 0.0060728745 | AB17: =IFERROR(AB16/AA16-1,"") -> 0.044600939 | AC17: =IFERROR(AC16/AB16-1,"") -> 0.088924559 | ... AE17: =IFERROR(AE16/AD16-1,"") -> 0.073848597 | AF17: =AE17 -> 0.073848597 | AG17: =IFERROR(AG16/AF16-1,"") -> 0.014551757
A22: iPhone Units Sold By Region | AJ22: Source
A23: Americas | W23: 70300 | X23: 62900 | Y23: 69300 | Z23: 74800 | AA23: 65700 | AB23: 73300 | AC23: 84300 | AD23: 99800 | AE23: 98100 | AF23: 100400 | AG23: 105900 | AJ23: https://backlinko.com/iphone-users?
A24: % Growth | X24: =IFERROR(X23/W23-1,"") -> -0.10526316 | Y24: =IFERROR(Y23/X23-1,"") -> 0.10174881 | Z24: =IFERROR(Z23/Y23-1,"") -> 0.079365079 | AA24: =IFERROR(AA23/Z23-1,"") -> -0.12165775 | AB24: =IFERROR(AB23/AA23-1,"") -> 0.11567732 | AC24: =IFERROR(AC23/AB23-1,"") -> 0.15006821 | AD24: =IFERROR(AD23/AC23-1,"") -> 0.18386714 | AE24: =IFERROR(AE23/AD23-1,"") -> -0.017034068 | ... AG24: =IFERROR(AG23/AF23-1,"") -> 0.054780876
A25: Europe | W25: 33900 | X25: 34600 | Y25: 36800 | Z25: 38200 | AA25: 36300 | AB25: 37300 | AC25: 56100 | AD25: 56000 | AE25: 56800 | AF25: 58800 | AG25: 65900
A26: % Growth | X26: =IFERROR(X25/W25-1,"") -> 0.020648968 | Y26: =IFERROR(Y25/X25-1,"") -> 0.063583815 | Z26: =IFERROR(Z25/Y25-1,"") -> 0.038043478 | AA26: =IFERROR(AA25/Z25-1,"") -> -0.04973822 | AB26: =IFERROR(AB25/AA25-1,"") -> 0.027548209 | AC26: =IFERROR(AC25/AB25-1,"") -> 0.50402145 | AD26: =IFERROR(AD25/AC25-1,"") -> -0.0017825312 | AE26: =IFERROR(AE25/AD25-1,"") -> 0.014285714 | ... AG26: =IFERROR(AG25/AF25-1,"") -> 0.1207483
A27: China | W27: 71200 | X27: 58300 | Y27: 51600 | Z27: 44800 | AA27: 31400 | AB27: 34900 | AC27: 42900 | AD27: 43600 | AE27: 43700 | AF27: 38500 | AG27: 38200
A28: % Growth | X28: =IFERROR(X27/W27-1,"") -> -0.18117978 | Y28: =IFERROR(Y27/X27-1,"") -> -0.11492281 | Z28: =IFERROR(Z27/Y27-1,"") -> -0.13178295 | AA28: =IFERROR(AA27/Z27-1,"") -> -0.29910714 | AB28: =IFERROR(AB27/AA27-1,"") -> 0.11146497 | AC28: =IFERROR(AC27/AB27-1,"") -> 0.22922636 | AD28: =IFERROR(AD27/AC27-1,"") -> 0.016317016 | AE28: =IFERROR(AE27/AD27-1,"") -> 0.002293578 | ... AG28: =IFERROR(AG27/AF27-1,"") -> -0.0077922078
A29: Japan | W29: 15000 | X29: 14600 | Y29: 15300 | Z29: 14900 | AA29: 14800 | AB29: 14700 | AC29: 17800 | AD29: 15200 | AE29: 14600 | AF29: 14500 | AG29: 17000
A30: % Growth | X30: =IFERROR(X29/W29-1,"") -> -0.026666667 | Y30: =IFERROR(Y29/X29-1,"") -> 0.047945205 | Z30: =IFERROR(Z29/Y29-1,"") -> -0.026143791 | AA30: =IFERROR(AA29/Z29-1,"") -> -0.0067114094 | AB30: =IFERROR(AB29/AA29-1,"") -> -0.0067567568 | AC30: =IFERROR(AC29/AB29-1,"") -> 0.21088435 | AD30: =IFERROR(AD29/AC29-1,"") -> -0.14606742 | AE30: =IFERROR(AE29/AD29-1,"") -> -0.039473684 | ... AG30: =IFERROR(AG29/AF29-1,"") -> 0.17241379
A31: Rest of Asia Pacific | W31: 12200 | X31: 14800 | Y31: 13300 | Z31: 14200 | AA31: 12800 | AB31: 14000 | AC31: 17300 | AD31: 17200 | AE31: 17800 | AF31: 19900 | AG31: 20000
A32: % Growth | X32: =IFERROR(X31/W31-1,"") -> 0.21311475 | Y32: =IFERROR(Y31/X31-1,"") -> -0.10135135 | Z32: =IFERROR(Z31/Y31-1,"") -> 0.067669173 | AA32: =IFERROR(AA31/Z31-1,"") -> -0.098591549 | AB32: =IFERROR(AB31/AA31-1,"") -> 0.09375 | AC32: =IFERROR(AC31/AB31-1,"") -> 0.23571429 | AD32: =IFERROR(AD31/AC31-1,"") -> -0.0057803468 | AE32: =IFERROR(AE31/AD31-1,"") -> 0.034883721 | ... AG32: =IFERROR(AG31/AF31-1,"") -> 0.0050251256
A33: Total Sales | W33: =W31+W29+W27+W25+W23 -> 202600 | X33: =X31+X29+X27+X25+X23 -> 185200 | Y33: =Y31+Y29+Y27+Y25+Y23 -> 186300 | Z33: =Z31+Z29+Z27+Z25+Z23 -> 186900 | AA33: =AA31+AA29+AA27+AA25+AA23 -> 161000 | AB33: =AB31+AB29+AB27+AB25+AB23 -> 174200 | AC33: =AC31+AC29+AC27+AC25+AC23 -> 218400 | AD33: =AD31+AD29+AD27+AD25+AD23 -> 231800 | ... AG33: =AG31+AG29+AG27+AG25+AG23 -> 247000
A34: % Growth | X34: =IFERROR(X33/W33-1,"") -> -0.085883514 | Y34: =IFERROR(Y33/X33-1,"") -> 0.0059395248 | Z34: =IFERROR(Z33/Y33-1,"") -> 0.0032206119 | AA34: =IFERROR(AA33/Z33-1,"") -> -0.13857678 | AB34: =IFERROR(AB33/AA33-1,"") -> 0.081987578 | AC34: =IFERROR(AC33/AB33-1,"") -> 0.25373134 | AD34: =IFERROR(AD33/AC33-1,"") -> 0.061355311 | AE34: =IFERROR(AE33/AD33-1,"") -> -0.0034512511 | ... AG34: =IFERROR(AG33/AF33-1,"") -> 0.064196467
A38: Active Service Users/Subsribers
A39: Number of iOS Subscriptions | W39: 30000 | X39: 95000 | Y39: 200000 | Z39: 325000 | AA39: 480000 | AB39: 620000 | AC39: 745000 | AD39: 900000 | AE39: 1050000 | AF39: 1160000 | AG39: 1250000 | AJ39: Source
A40: % Growth | X40: =IFERROR(X39/W39-1,"") -> 2.1666667 | Y40: =IFERROR(Y39/X39-1,"") -> 1.1052632 | Z40: =IFERROR(Z39/Y39-1,"") -> 0.625 | AA40: =IFERROR(AA39/Z39-1,"") -> 0.47692308 | AB40: =IFERROR(AB39/AA39-1,"") -> 0.29166667 | AC40: =IFERROR(AC39/AB39-1,"") -> 0.2016129 | AD40: =IFERROR(AD39/AC39-1,"") -> 0.20805369 | AE40: =IFERROR(AE39/AD39-1,"") -> 0.16666667 | ... AG40: =IFERROR(AG39/AF39-1,"") -> 0.077586207 | AJ40: https://backlinko.com/iphone-users?
A41: Apple Pay Active Users | Y41: 337000 | Z41: 389000 | AA41: 441000 | AB41: 507000 | AC41: 631000 | AD41: 701000 | AE41: 744000 | AF41: 785000 | AG41: 803000
A42: % Growth | Z42: =IFERROR(Z41/Y41-1,"") -> 0.15430267 | AA42: =IFERROR(AA41/Z41-1,"") -> 0.13367609 | AB42: =IFERROR(AB41/AA41-1,"") -> 0.14965986 | AC42: =IFERROR(AC41/AB41-1,"") -> 0.24457594 | AD42: =IFERROR(AD41/AC41-1,"") -> 0.11093502 | AE42: =IFERROR(AE41/AD41-1,"") -> 0.061340942 | AF42: =IFERROR(AF41/AE41-1,"") -> 0.055107527 | AG42: =IFERROR(AG41/AF41-1,"") -> 0.022929936
A43: Apple Pay Transaction Volume | X43: 65000 | Y43: 90000 | Z43: 325000 | AA43: 650000 | AB43: 1900000 | AC43: 3700000 | AD43: 6000000 | AE43: 7300000 | AF43: 8500000 | AG43: 9450000
A44: % Growth | Y44: =IFERROR(Y43/X43-1,"") -> 0.38461538 | Z44: =IFERROR(Z43/Y43-1,"") -> 2.6111111 | AA44: =IFERROR(AA43/Z43-1,"") -> 1 | AB44: =IFERROR(AB43/AA43-1,"") -> 1.9230769 | AC44: =IFERROR(AC43/AB43-1,"") -> 0.94736842 | AD44: =IFERROR(AD43/AC43-1,"") -> 0.62162162 | AE44: =IFERROR(AE43/AD43-1,"") -> 0.21666667 | AF44: =IFERROR(AF43/AE43-1,"") -> 0.16438356 | AG44: =IFERROR(AG43/AF43-1,"") -> 0.11176471
A45: Apple Music Subscribers | W45: 11000 | X45: 20000 | Y45: 27000 | Z45: 40000 | AA45: 50000 | AB45: 72000 | AC45: 80000 | AD45: 88000 | AE45: 93000 | AF45: 95000 | AG45: 104000
A46: % Growth | X46: =IFERROR(X45/W45-1,"") -> 0.81818182 | Y46: =IFERROR(Y45/X45-1,"") -> 0.35 | Z46: =IFERROR(Z45/Y45-1,"") -> 0.48148148 | AA46: =IFERROR(AA45/Z45-1,"") -> 0.25 | AB46: =IFERROR(AB45/AA45-1,"") -> 0.44 | AC46: =IFERROR(AC45/AB45-1,"") -> 0.11111111 | AD46: =IFERROR(AD45/AC45-1,"") -> 0.1 | AE46: =IFERROR(AE45/AD45-1,"") -> 0.056818182 | ... AG46: =IFERROR(AG45/AF45-1,"") -> 0.094736842
A47: Apple TV+ Subscribers | AA47: 5700 | AB47: 33600 | AC47: 48000 | AD47: 55000 | AE47: 40000 | AF47: 30000 | AG47: 45000
A48: % Growth | AB48: =IFERROR(AB47/AA47-1,"") -> 4.8947368 | AC48: =IFERROR(AC47/AB47-1,"") -> 0.42857143 | AD48: =IFERROR(AD47/AC47-1,"") -> 0.14583333 | AE48: =IFERROR(AE47/AD47-1,"") -> -0.27272727 | AF48: =IFERROR(AF47/AE47-1,"") -> -0.25 | AG48: =IFERROR(AG47/AF47-1,"") -> 0.5
A49: Apple News Users | Y49: 70000 | Z49: 85000 | AA49: 90000 | AB49: 100000 | AC49: 135000 | AD49: 160000 | AE49: 185000 | AF49: 195000 | AG49: 220000
...

Sheet Apple Product Revenue
A1: Main Products Net Sales ($mm)
A3: Product | B3: 1994 | C3: 1995 | D3: 1996 | E3: 1997 | F3: 1998 | G3: 1999 | H3: 2000 | I3: 2001 | J3: 2002 | K3: 2003 | L3: 2004 | M3: 2005 | N3: 2006 | O3: 2007 | P3: 2008 | Q3: 2009 | R3: 2010 | S3: 2011 | T3: 2012 | U3: 2013 | V3: 2014 | W3: 2015 | X3: 2016 | Y3: 2017 | Z3: 2018 | AA3: 2019 | AB3: 2020 | AC3: 2021 | AD3: 2022 | AE3: 2023 | AF3: 2024 | AG3: 2025 | AM3: 13yrs | AO3: 3yrs
A4: iPhone | B4: 0 | C4: 0 | D4: 0 | E4: 0 | F4: 0 | G4: 0 | H4: 0 | I4: 0 | J4: 0 | K4: 0 | L4: 0 | M4: 0 | N4: 0 | O4: 630 | P4: 1800 | Q4: 13033 | R4: 25179 | S4: 45998 | T4: 78692 | U4: 91279 | V4: 101991 | W4: 155041 | X4: 136700 | Y4: 139337 | Z4: 164888 | AA4: 142381 | AB4: 137781 | AC4: 191973 | AD4: 205489 | AE4: 200583 | AF4: 201183 | AG4: 209586 | AM4: =(AG4/T4)^(1/13)-1 -> 0.078265015 | AO4: =(AG4/AD4)^(1/3)-1 -> 0.00660225
A5: % Growth | P5: =P4/O4-1 -> 1.8571429 | Q5: =Q4/P4-1 -> 6.2405556 | R5: =R4/Q4-1 -> 0.93194199 | S5: =S4/R4-1 -> 0.82683983 | T5: =T4/S4-1 -> 0.71077003 | U5: =U4/T4-1 -> 0.15995273 | V5: =V4/U4-1 -> 0.11735448 | W5: =W4/V4-1 -> 0.52014393 | ... AG5: =AG4/AF4-1 -> 0.041767943
A6: Mac | E6: 5671 | F6: 4862 | G6: 5082 | H6: 6885 | I6: 4403 | J6: 4534 | K6: 4491 | L6: 4923 | M6: 6275 | N6: 7375 | O6: 10336 | P6: 14354 | Q6: 13859 | R6: 17479 | S6: 21783 | T6: 23221 | U6: 21483 | V6: 24079 | W6: 25471 | X6: 22831 | Y6: 25569 | Z6: 25198 | AA6: 25740 | AB6: 28622 | AC6: 35190 | AD6: 40177 | AE6: 29357 | AF6: 29984 | AG6: 33708 | AM6: =(AG6/T6)^(1/13)-1 -> 0.02908242 | AO6: =(AG6/AD6)^(1/3)-1 -> -0.056840464
A7: % Growth | F7: =F6/E6-1 -> -0.14265562 | G7: =G6/F6-1 -> 0.045248869 | H7: =H6/G6-1 -> 0.35478158 | I7: =I6/H6-1 -> -0.36049383 | J7: =J6/I6-1 -> 0.029752442 | K7: =K6/J6-1 -> -0.0094838994 | L7: =L6/K6-1 -> 0.096192385 | M7: =M6/L6-1 -> 0.27462929 | ... AG7: =AG6/AF6-1 -> 0.12419957
A8: iPad | B8: 0 | C8: 0 | D8: 0 | E8: 0 | F8: 0 | G8: 0 | H8: 0 | I8: 0 | J8: 0 | K8: 0 | L8: 0 | M8: 0 | N8: 0 | O8: 0 | P8: 0 | Q8: 0 | R8: 4958 | S8: 19168 | T8: 30945 | U8: 31980 | V8: 30283 | W8: 23227 | X8: 20628 | Y8: 18802 | Z8: 18380 | AA8: 21280 | AB8: 23724 | AC8: 31862 | AD8: 29292 | AE8: 28300 | AF8: 26694 | AG8: 28023 | AM8: =(AG8/T8)^(1/13)-1 -> -0.0076006474 | AO8: =(AG8/AD8)^(1/3)-1 -> -0.014654509
A9: % Growth | S9: =S8/R8-1 -> 2.866075 | T9: =T8/S8-1 -> 0.61440943 | U9: =U8/T8-1 -> 0.033446437 | V9: =V8/U8-1 -> -0.053064415 | W9: =W8/V8-1 -> -0.23300201 | X9: =X8/W8-1 -> -0.11189564 | Y9: =Y8/X8-1 -> -0.088520458 | Z9: =Z8/Y8-1 -> -0.022444421 | ... AG9: =AG8/AF8-1 -> 0.049786469
A10: Wearables, Home & Accessories | B10: 0 | C10: 0 | D10: 0 | E10: 0 | F10: 0 | G10: 0 | H10: 0 | I10: 0 | J10: 0 | K10: 0 | L10: 0 | M10: 0 | N10: 0 | O10: 0 | P10: 0 | Q10: 0 | R10: 0 | S10: 0 | T10: 0 | U10: 0 | V10: 0 | W10: 9800 | X10: 10900 | Y10: 12826 | Z10: 17381 | AA10: 24482 | AB10: 30620 | AC10: 38367 | AD10: 41241 | AE10: 39845 | AF10: 37005 | AG10: 35686 | AM10: =(AG10/W10)^(1/10)-1 -> 0.13796048 | AO10: =(AG10/AD10)^(1/3)-1 -> -0.04708047
A11: % Growth | X11: =X10/W10-1 -> 0.1122449 | Y11: =Y10/X10-1 -> 0.17669725 | Z11: =Z10/Y10-1 -> 0.355138 | AA11: =AA10/Z10-1 -> 0.40854957 | AB11: =AB10/AA10-1 -> 0.25071481 | AC11: =AC10/AB10-1 -> 0.25300457 | AD11: =AD10/AC10-1 -> 0.074908124 | AE11: =AE10/AD10-1 -> -0.03384981 | ... AG11: =AG10/AF10-1 -> -0.035643832
A12: Services Net Sales | B12: 0 | C12: 0 | D12: 0 | E12: 0 | F12: 0 | G12: 0 | H12: 0 | I12: 0 | J12: 0 | K12: 0 | L12: 0 | M12: 0 | N12: 0 | O12: 0 | P12: 0 | Q12: 0 | R12: 0 | S12: 9373 | T12: 12890 | U12: 16051 | V12: 18063 | W12: 19909 | X12: 24348 | Y12: 32700 | Z12: 39748 | AA12: 46291 | AB12: 53768 | AC12: 68425 | AD12: 78129 | AE12: 85200 | AF12: 96169 | AG12: 109158 | AM12: =(AG12/T12)^(1/13)-1 -> 0.17860814 | AO12: =(AG12/AD12)^(1/3)-1 -> 0.11792955
A13: % Growth | T13: =T12/S12-1 -> 0.37522672 | U13: =U12/T12-1 -> 0.24522886 | V13: =V12/U12-1 -> 0.12535045 | W13: =W12/V12-1 -> 0.10219786 | X13: =X12/W12-1 -> 0.22296449 | Y13: =Y12/X12-1 -> 0.34302612 | Z13: =Z12/Y12-1 -> 0.21553517 | AA13: =AA12/Z12-1 -> 0.16461206 | ... AG13: =AG12/AF12-1 -> 0.13506431
A14: Total Net Sales | B14: =B4+B6+B8+B10 -> 0 | C14: =C4+C6+C8+C10 -> 0 | D14: =D4+D6+D8+D10 -> 0 | E14: =E4+E6+E8+E10 -> 5671 | F14: =F4+F6+F8+F10 -> 4862 | G14: =G4+G6+G8+G10 -> 5082 | H14: =H4+H6+H8+H10 -> 6885 | I14: =I4+I6+I8+I10 -> 4403 | ... R14: =R4+R6+R8+R10 -> 47616 | S14: =S4+S6+S8+S10+S12 -> 96322 | T14: =T4+T6+T8+T10+T12 -> 145748 | U14: =U4+U6+U8+U10+U12 -> 160793 | V14: =V4+V6+V8+V10+V12 -> 174416 | W14: =W4+W6+W8+W10+W12 -> 233448 | X14: =X4+X6+X8+X10+X12 -> 215407 | Y14: =Y4+Y6+Y8+Y10+Y12 -> 229234 | Z14: =Z4+Z6+Z8+Z10+Z12 -> 265595 | ... AG14: =AG4+AG6+AG8+AG10+AG12 -> 416161
A15: % Growth | F15: =F14/E14-1 -> -0.14265562 | G15: =G14/F14-1 -> 0.045248869 | H15: =H14/G14-1 -> 0.35478158 | I15: =I14/H14-1 -> -0.36049383 | J15: =J14/I14-1 -> 0.029752442 | K15: =K14/J14-1 -> -0.0094838994 | L15: =L14/K14-1 -> 0.096192385 | M15: =M14/L14-1 -> 0.27462929 | ... AG15: =AG14/AF14-1 -> 0.064255118

Sheet Apple Country Revenue
A1: Country / International Net Sales ($mm) | X1: Source
X2: Financial Statements
A3: Country / Group | B3: 2006 | C3: 2007 | D3: 2008 | E3: 2009 | F3: 2010 | G3: 2011 | H3: 2012 | I3: 2013 | J3: 2014 | K3: 2015 | L3: 2016 | M3: 2017 | N3: 2018 | O3: 2019 | P3: 2020 | Q3: 2021 | R3: 2022 | S3: 2023 | T3: 2024 | U3: 2025
A4: U.S. | B4: 11486 | C4: 14128 | D4: 18469 | E4: 22325 | F4: 28633 | G4: 41812 | H4: 60949 | I4: 66197 | J4: 68909 | K4: 81732 | L4: 75667 | M4: 84339 | N4: 98061 | O4: 102266 | P4: 109197 | Q4: 133803 | R4: 147859 | S4: 138573 | T4: 142196 | U4: 151790
A5: % Growth | C5: =IFERROR(C4/B4-1,"") -> 0.23001915 | D5: =IFERROR(D4/C4-1,"") -> 0.30726217 | E5: =IFERROR(E4/D4-1,"") -> 0.20878228 | F5: =IFERROR(F4/E4-1,"") -> 0.28255319 | G5: =IFERROR(G4/F4-1,"") -> 0.46027311 | H5: =IFERROR(H4/G4-1,"") -> 0.45769157 | I5: =IFERROR(I4/H4-1,"") -> 0.086104776 | J5: =IFERROR(J4/I4-1,"") -> 0.040968624 | ... U5: =IFERROR(U4/T4-1,"") -> 0.067470252
A6: China | E6: 769 | F6: 2764 | G6: 12472 | H6: 22797 | I6: 25946 | J6: 30638 | K6: 56547 | L6: 46349 | M6: 44764 | N6: 51942 | O6: 43678 | P6: 40308 | Q6: 68366 | R6: 74200 | S6: 72559 | T6: 66952 | U6: 64377
A7: % Growth | F7: =IFERROR(F6/E6-1,"") -> 2.5942783 | G7: =IFERROR(G6/F6-1,"") -> 3.512301 | H7: =IFERROR(H6/G6-1,"") -> 0.82785439 | I7: =IFERROR(I6/H6-1,"") -> 0.13813221 | J7: =IFERROR(J6/I6-1,"") -> 0.18083712 | K7: =IFERROR(K6/J6-1,"") -> 0.84564919 | L7: =IFERROR(L6/K6-1,"") -> -0.18034555 | M7: =IFERROR(M6/L6-1,"") -> -0.03419707 | ... U7: =IFERROR(U6/T6-1,"") -> -0.03846039
A8: International | B8: 7829 | C8: 9878 | D8: 14010 | E8: 19811 | F8: 33828 | G8: 53965 | H8: 72762 | I8: 78767 | J8: 83248 | K8: 95436 | L8: 93623 | M8: 100131 | N8: 115592 | O8: 114230 | P8: 125010 | Q8: 163648 | R8: 172269 | S8: 172153 | T8: 181887 | U8: 199994
A9: % Growth | C9: =IFERROR(C8/B8-1,"") -> 0.26171925 | D9: =IFERROR(D8/C8-1,"") -> 0.4183033 | E9: =IFERROR(E8/D8-1,"") -> 0.41406138 | F9: =IFERROR(F8/E8-1,"") -> 0.70753622 | G9: =IFERROR(G8/F8-1,"") -> 0.5952761 | H9: =IFERROR(H8/G8-1,"") -> 0.34831835 | I9: =IFERROR(I8/H8-1,"") -> 0.082529342 | J9: =IFERROR(J8/I8-1,"") -> 0.056889306 | ... U9: =IFERROR(U8/T8-1,"") -> 0.09955082
A10: Total net sales | B10: =B4+B6+B8 -> 19315 | C10: =C4+C6+C8 -> 24006 | D10: =D4+D6+D8 -> 32479 | E10: =E4+E6+E8 -> 42905 | F10: =F4+F6+F8 -> 65225 | G10: =G4+G6+G8 -> 108249 | H10: =H4+H6+H8 -> 156508 | I10: =I4+I6+I8 -> 170910 | ... U10: =U4+U6+U8 -> 416161
A11: % Growth | C11: =IFERROR(C10/B10-1,"") -> 0.24286824 | D11: =IFERROR(D10/C10-1,"") -> 0.35295343 | E11: =IFERROR(E10/D10-1,"") -> 0.32100742 | F11: =IFERROR(F10/E10-1,"") -> 0.52021909 | G11: =IFERROR(G10/F10-1,"") -> 0.65962438 | H11: =IFERROR(H10/G10-1,"") -> 0.44581474 | I11: =IFERROR(I10/H10-1,"") -> 0.092020855 | J11: =IFERROR(J10/I10-1,"") -> 0.069539524 | ... U11: =IFERROR(U10/T10-1,"") -> 0.064255118
A16: Americas | K16: 93800 | L16: 86600 | M16: 96600 | N16: 112000 | O16: 116900 | P16: 124500 | Q16: 153300 | R16: 169600 | S16: 162500 | T16: 167000 | U16: 178300 | X16: Source
A17: % Growth | L17: =IFERROR(L16/K16-1,"") -> -0.076759062 | M17: =IFERROR(M16/L16-1,"") -> 0.11547344 | N17: =IFERROR(N16/M16-1,"") -> 0.15942029 | O17: =IFERROR(O16/N16-1,"") -> 0.04375 | P17: =IFERROR(P16/O16-1,"") -> 0.065012831 | Q17: =IFERROR(Q16/P16-1,"") -> 0.2313253 | R17: =IFERROR(R16/Q16-1,"") -> 0.10632746 | S17: =IFERROR(S16/R16-1,"") -> -0.041863208 | ... U17: =IFERROR(U16/T16-1,"") -> 0.067664671 | X17: https://www.businessofapps.com/data/apple-statistics/?utm_source=chatgpt.com
A18: Europe | K18: 50300 | L18: 49800 | M18: 54900 | N18: 62400 | O18: 60200 | P18: 68600 | Q18: 89300 | R18: 95100 | S18: 94200 | T18: 101300 | U18: 111000
A19: % Growth | L19: =IFERROR(L18/K18-1,"") -> -0.0099403579 | M19: =IFERROR(M18/L18-1,"") -> 0.10240964 | N19: =IFERROR(N18/M18-1,"") -> 0.13661202 | O19: =IFERROR(O18/N18-1,"") -> -0.03525641 | P19: =IFERROR(P18/O18-1,"") -> 0.13953488 | Q19: =IFERROR(Q18/P18-1,"") -> 0.30174927 | R19: =IFERROR(R18/Q18-1,"") -> 0.064949608 | S19: =IFERROR(S18/R18-1,"") -> -0.0094637224 | ... U19: =IFERROR(U18/T18-1,"") -> 0.095755183
A20: China | K20: 58700 | L20: 48500 | M20: 51600 | N20: 51900 | O20: 43600 | P20: 40300 | Q20: 68300 | R20: 74200 | S20: 72500 | T20: 66900 | U20: 64300
A21: % Growth | L21: =IFERROR(L20/K20-1,"") -> -0.17376491 | M21: =IFERROR(M20/L20-1,"") -> 0.063917526 | N21: =IFERROR(N20/M20-1,"") -> 0.0058139535 | O21: =IFERROR(O20/N20-1,"") -> -0.15992293 | P21: =IFERROR(P20/O20-1,"") -> -0.075688073 | Q21: =IFERROR(Q20/P20-1,"") -> 0.69478908 | R21: =IFERROR(R20/Q20-1,"") -> 0.086383602 | S21: =IFERROR(S20/R20-1,"") -> -0.022911051 | ... U21: =IFERROR(U20/T20-1,"") -> -0.038863976
A22: Japan | K22: 15700 | L22: 16900 | M22: 15300 | N22: 21700 | O22: 21500 | P22: 21400 | Q22: 28400 | R22: 25900 | S22: 24200 | T22: 25000 | U22: 28700
A23: % Growth | L23: =IFERROR(L22/K22-1,"") -> 0.076433121 | M23: =IFERROR(M22/L22-1,"") -> -0.094674556 | N23: =IFERROR(N22/M22-1,"") -> 0.41830065 | O23: =IFERROR(O22/N22-1,"") -> -0.0092165899 | P23: =IFERROR(P22/O22-1,"") -> -0.0046511628 | Q23: =IFERROR(Q22/P22-1,"") -> 0.3271028 | R23: =IFERROR(R22/Q22-1,"") -> -0.088028169 | S23: =IFERROR(S22/R22-1,"") -> -0.065637066 | ... U23: =IFERROR(U22/T22-1,"") -> 0.148
A24: Rest of Asia Pacific | K24: 15000 | L24: 13600 | M24: 14100 | N24: 17400 | O24: 17800 | P24: 19600 | Q24: 26300 | R24: 29300 | S24: 29600 | T24: 30600 | U24: 33600
A25: % Growth | L25: =IFERROR(L24/K24-1,"") -> -0.093333333 | M25: =IFERROR(M24/L24-1,"") -> 0.036764706 | N25: =IFERROR(N24/M24-1,"") -> 0.23404255 | O25: =IFERROR(O24/N24-1,"") -> 0.022988506 | P25: =IFERROR(P24/O24-1,"") -> 0.1011236 | Q25: =IFERROR(Q24/P24-1,"") -> 0.34183673 | R25: =IFERROR(R24/Q24-1,"") -> 0.11406844 | S25: =IFERROR(S24/R24-1,"") -> 0.010238908 | ... U25: =IFERROR(U24/T24-1,"") -> 0.098039216
A26: Total Sales | K26: =K24+K22+K20+K18+K16 -> 233500 | L26: =L24+L22+L20+L18+L16 -> 215400 | M26: =M24+M22+M20+M18+M16 -> 232500 | N26: =N24+N22+N20+N18+N16 -> 265400 | O26: =O24+O22+O20+O18+O16 -> 260000 | P26: =P24+P22+P20+P18+P16 -> 274400 | Q26: =Q24+Q22+Q20+Q18+Q16 -> 365600 | R26: =R24+R22+R20+R18+R16 -> 394100 | ... U26: =U24+U22+U20+U18+U16 -> 415900
A27: % Growth | L27: =IFERROR(L26/K26-1,"") -> -0.07751606 | M27: =IFERROR(M26/L26-1,"") -> 0.079387187 | N27: =IFERROR(N26/M26-1,"") -> 0.14150538 | O27: =IFERROR(O26/N26-1,"") -> -0.020346647 | P27: =IFERROR(P26/O26-1,"") -> 0.055384615 | Q27: =IFERROR(Q26/P26-1,"") -> 0.33236152 | R27: =IFERROR(R26/Q26-1,"") -> 0.077954048 | S27: =IFERROR(S26/R26-1,"") -> -0.02816544 | ... U27: =IFERROR(U26/T26-1,"") -> 0.064227226

Sheet Apple Debt
A1: Units: $ millions
B2: 1992 | C2: 1993 | D2: 1994 | E2: 1995 | F2: 1996 | G2: 1997 | H2: 1998 | I2: 1999 | J2: 2000 | K2: 2001 | L2: 2002 | M2: 2003 | N2: 2004 | O2: 2005 | P2: 2006 | Q2: 2007 | R2: 2008 | S2: 2009 | T2: 2010 | U2: 2011 | V2: 2012 | W2: 2013 | X2: 2014 | Y2: 2015 | Z2: 2016 | AA2: 2017 | AB2: 2018 | AC2: 2019 | AD2: 2020 | AE2: 2021 | AF2: 2022 | AG2: 2023 | AH2: 2024 | AI2: 2025
A3: Commercial Paper | B3: 0 | C3: 0 | D3: 0 | E3: 0 | F3: 0 | G3: 0 | H3: 0 | I3: 0 | J3: 0 | K3: 0 | L3: 0 | M3: 0 | N3: 0 | O3: 0 | P3: 0 | Q3: 0 | R3: 0 | S3: 0 | T3: 0 | U3: 0 | V3: 0 | W3: 0 | X3: 6308 | Y3: 8499 | Z3: 8105 | AA3: 11977 | AB3: 11964 | AC3: 5980 | AD3: 4996 | AE3: 6000 | AF3: 9982 | AG3: 5985 | AH3: 9967 | AI3: 7979
A4: Current Portion Term Debt | B4: 0 | C4: 0 | D4: 0 | E4: 0 | F4: 0 | G4: 0 | H4: 0 | I4: 0 | J4: 0 | K4: 0 | L4: 0 | M4: 304 | N4: 0 | O4: 0 | P4: 0 | Q4: 0 | R4: 0 | S4: 0 | T4: 0 | U4: 0 | V4: 0 | W4: 0 | X4: 0 | Y4: 2500 | Z4: 3500 | AA4: 6496 | AB4: 8784 | AC4: 10260 | AD4: 8773 | AE4: 9613 | AF4: 11128 | AG4: 9822 | AH4: 10912 | AI4: 12350
A5: Short-term / Current Debt | B5: 184.461 | C5: 823.182 | D5: 292.2 | E5: 461 | F5: 186 | G5: 25 | H5: 0 | I5: 0 | J5: 0 | K5: 0 | L5: 0 | M5: =M3+M4 -> 304 | N5: =N3+N4 -> 0 | O5: =O3+O4 -> 0 | P5: =P3+P4 -> 0 | Q5: =Q3+Q4 -> 0 | R5: =R3+R4 -> 0 | S5: =S3+S4 -> 0 | T5: =T3+T4 -> 0 | ... AI5: =AI3+AI4 -> 20329
A7: Non-current Term Debt | B7: =B6+B3 -> 0 | C7: 7 | D7: 304 | E7: 303 | F7: 949 | G7: 951 | H7: 954 | I7: 300 | J7: 300 | K7: 317 | L7: 316 | M7: 0 | N7: 0 | O7: 0 | P7: 0 | Q7: 0 | R7: 0 | S7: 0 | T7: 0 | U7: 0 | V7: 0 | W7: 16960 | X7: 28987 | Y7: 53463 | Z7: 75427 | AA7: 97207 | AB7: 93735 | AC7: 91807 | AD7: 98667 | AE7: 109106 | AF7: 98959 | AG7: 95281 | AH7: 85750 | AI7: 78328
A8: Term Debt Carrying Value | B8: =B7+B4 -> 0 | C8: =C7+C4 -> 7 | D8: =D7+D4 -> 304 | E8: =E7+E4 -> 303 | F8: =F7+F4 -> 949 | G8: =G7+G4 -> 951 | H8: =H7+H4 -> 954 | I8: =I7+I4 -> 300 | ... AI8: =AI7+AI4 -> 90678
A9: Gross Disclosed Term Principal | B9: =B13+B6 -> 0 | D9: 300 | E9: 300 | F9: 961 | G9: 961 | H9: 961 | I9: 300 | J9: 300 | K9: 300 | L9: 300 | M9: 300 | N9: 0 | O9: 0 | P9: 0 | Q9: 0 | R9: 0 | S9: 0 | T9: 0 | U9: 0 | V9: 0 | W9: 17000 | X9: 29000 | Y9: 55700 | Z9: 78400 | AA9: 104021 | AB9: 104193 | AC9: 101679 | AD9: 106078 | AE9: 118063 | AF9: 111824 | AG9: 106572 | AH9: 97341 | AI9: 91281
A10: Principal less Carrying | B10: =B9-B8 -> 0 | D10: =D9-D8 -> -4 | E10: =E9-E8 -> -3 | F10: =F9-F8 -> 12 | G10: =G9-G8 -> 10 | H10: =H9-H8 -> 7 | I10: =I9-I8 -> 0 | J10: =J9-J8 -> 0 | K10: =K9-K8 -> -17 | ... AI10: =AI9-AI8 -> 603
A13: Total Interest-bearing Debt | B13: 0 | C13: =C7+C5 -> 830.182 | D13: =D7+D5 -> 596.2 | E13: =E7+E5 -> 764 | F13: =F7+F5 -> 1135 | G13: =G7+G5 -> 976 | H13: =H7+H5 -> 954 | I13: =I7+I5 -> 300 | J13: =J7+J5 -> 300 | ... AI13: =AI7+AI5 -> 98657
A14: % of Revenue | C14: =C13/'Apple Consolidated Statements'!C$11 -> 0.10407256 | D14: =D13/'Apple Consolidated Statements'!D11 -> 0.064883703 | E14: =E13/'Apple Consolidated Statements'!E11 -> 0.069065268 | F14: =F13/'Apple Consolidated Statements'!F11 -> 0.11542764 | G14: =G13/'Apple Consolidated Statements'!G11 -> 0.13783364 | H14: =H13/'Apple Consolidated Statements'!H11 -> 0.16057903 | I14: =I13/'Apple Consolidated Statements'!I11 -> 0.048907727 | J14: =J13/'Apple Consolidated Statements'!J11 -> 0.037579857 | K14: =K13/'Apple Consolidated Statements'!K11 -> 0.059108708 | ... AI14: =AI13/'Apple Consolidated Statements'!AI11 -> 0.2370645
A15: =A5 -> Short-term / Current Debt | B15: =B5 -> 184.461 | C15: =C5 -> 823.182 | D15: =D5 -> 292.2 | E15: =E5 -> 461 | F15: =F5 -> 186 | G15: =G5 -> 25 | H15: =H5 -> 0 | ... AI15: =AI5 -> 20329
A16: % of Revenue | B16: =B15/'Apple Consolidated Statements'!B$11 -> 0.026029762 | C16: =C15/'Apple Consolidated Statements'!C$11 -> 0.10319503 | D16: =D15/'Apple Consolidated Statements'!D$11 -> 0.031799762 | E16: =E15/'Apple Consolidated Statements'!E$11 -> 0.0416742 | F16: =F15/'Apple Consolidated Statements'!F$11 -> 0.018915895 | G16: =G15/'Apple Consolidated Statements'!G$11 -> 0.0035305748 | H16: =H15/'Apple Consolidated Statements'!H$11 -> 0 | I16: =I15/'Apple Consolidated Statements'!I$11 -> 0 | ... AI16: =AI15/'Apple Consolidated Statements'!AI$11 -> 0.048848883
A17: =A7 -> Non-current Term Debt | B17: 0 | C17: =C7 -> 7 | D17: =D7 -> 304 | E17: =E7 -> 303 | F17: =F7 -> 949 | G17: =G7 -> 951 | H17: =H7 -> 954 | I17: =I7 -> 300 | J17: =J7 -> 300 | ... AI17: =AI7 -> 78328
A18: % of Revenue | B18: =B17/'Apple Consolidated Statements'!B$11 -> 0 | C18: =C17/'Apple Consolidated Statements'!C$11 -> 0.00087752794 | D18: =D17/'Apple Consolidated Statements'!D$11 -> 0.033083941 | E18: =E17/'Apple Consolidated Statements'!E$11 -> 0.027391069 | F18: =F17/'Apple Consolidated Statements'!F$11 -> 0.096511746 | G18: =G17/'Apple Consolidated Statements'!G$11 -> 0.13430306 | H18: =H17/'Apple Consolidated Statements'!H$11 -> 0.16057903 | I18: =I17/'Apple Consolidated Statements'!I$11 -> 0.048907727 | ... AI18: =AI17/'Apple Consolidated Statements'!AI$11 -> 0.18821562

Sheet Apple Capex
A1: Units: $ millions
B2: 1992 | C2: 1993 | D2: 1994 | E2: 1995 | F2: 1996 | G2: 1997 | H2: 1998 | I2: 1999 | J2: 2000 | K2: 2001 | L2: 2002 | M2: 2003 | N2: 2004 | O2: 2005 | P2: 2006 | Q2: 2007 | R2: 2008 | S2: 2009 | T2: 2010 | U2: 2011 | V2: 2012 | W2: 2013 | X2: 2014 | Y2: 2015 | Z2: 2016 | AA2: 2017 | AB2: 2018 | AC2: 2019 | AD2: 2020 | AE2: 2021 | AF2: 2022 | AG2: 2023 | AH2: 2024 | AI2: 2025
A3: ='Apple Consolidated Statements'!A172 -> Purchases of PP&E | B3: ='Apple Consolidated Statements'!B172 -> -194.853 | C3: ='Apple Consolidated Statements'!C172 -> -213.118 | D3: ='Apple Consolidated Statements'!D172 -> -159.587 | E3: ='Apple Consolidated Statements'!E172 -> -159 | F3: ='Apple Consolidated Statements'!F172 -> -67 | G3: ='Apple Consolidated Statements'!G172 -> -53 | H3: ='Apple Consolidated Statements'!H172 -> -46 | ... AI3: ='Apple Consolidated Statements'!AI172 -> -12715 | AK3: Average 33yr | AL3: Average 20yr | AM3: Average 10yr | AN3: Average 5yr
A4: % of Revenue | B4: =-B3/'Apple Consolidated Statements'!B11 -> 0.027496203 | C4: =-C3/'Apple Consolidated Statements'!C11 -> 0.026716714 | D4: =-D3/'Apple Consolidated Statements'!D11 -> 0.017367654 | E4: =-E3/'Apple Consolidated Statements'!E11 -> 0.014373531 | F4: =-F3/'Apple Consolidated Statements'!F11 -> 0.0068137903 | G4: =-G3/'Apple Consolidated Statements'!G11 -> 0.0074848185 | H4: =-H3/'Apple Consolidated Statements'!H11 -> 0.0077428042 | I4: =-I3/'Apple Consolidated Statements'!I11 -> 0.0076622106 | ... AI4: =-AI3/'Apple Consolidated Statements'!AI11 -> 0.030553079 | AK4: =AVERAGE(B4:AI4) -> 0.030458917 | AL4: =AVERAGE(O4:AI4) -> 0.037186422 | AM4: =AVERAGE(Y4:AI4) -> 0.038121904 | AN4: =AVERAGE(AD4:AI4) -> 0.027897763

Sheet Apple Company Profile
C1: Source URL
A2: Company Overview
A3: Founded | B3: April 1, 1976 | C3: https://www.apple.com/newsroom/2026/03/apple-to-celebrate-50-years-of-thinking-different/
A4: IPO | B4: December 12, 1980 | C4: https://investor.apple.com/faq/
A5: S&P 500 addition | B5: November 30, 1982 | C5: https://github.com/datasets/s-and-p-500-companies/blob/main/data/constituents.csv
A6: Ticker / Exchange | B6: AAPL / Nasdaq | C6: https://investor.apple.com/faq/
A7: Headquarters | B7: One Apple Park Way, Cupertino, CA 95014 | C7: https://investor.apple.com/faq/
A8: FY2025 employees | B8: 166000 | C8: https://www.sec.gov/Archives/edgar/data/320193/000032019325000079/aapl-20250927.htm
A9: FY2025 net sales ($mm) | B9: 416161 | C9: https://www.apple.com/newsroom/pdfs/fy2025-q4/FY25_Q4_Consolidated_Financial_Statements.pdf
A10: Customer markets | B10: Consumer; small & mid-sized business; education; enterprise; government | C10: https://www.sec.gov/Archives/edgar/data/320193/000032019325000079/aapl-20250927.htm
A11: Distribution | B11: Direct retail/online/direct sales force + third-party carriers and other resellers | C11: https://www.sec.gov/Archives/edgar/data/320193/000032019325000079/aapl-20250927.htm
A12: FY2025 direct / indirect sales mix | B12: 40% / 60% | C12: https://www.sec.gov/Archives/edgar/data/320193/000032019325000079/aapl-20250927.htm
A13: Reportable geographies | B13: Americas; Europe; Greater China; Japan; Rest of Asia Pacific | C13: https://www.sec.gov/Archives/edgar/data/320193/000032019325000079/aapl-20250927.htm
A15: New CEO | B15: John Ternus (September 1 2026) | C15: https://www.apple.com/newsroom/2026/04/tim-cook-to-become-apple-executive-chairman-john-ternus-to-become-apple-ceo/
A16: iPhone Duo Launch | B16: Price $2,000 - September 9 2026 | C16: https://www.reuters.com/business/retail-consumer/apple-expected-unveil-first-folding-phone-with-new-ceo-ternus-command-2026-09-09/
A18: Smartphone Business (iPhone)
A19: Category | B19: Smartphones | C19: https://www.sec.gov/Archives/edgar/data/320193/000032019325000079/aapl-20250927.htm
A20: Products / offering | B20: iPhone line; iOS operating system | C20: https://www.sec.gov/Archives/edgar/data/320193/000032019325000079/aapl-20250927.htm
A21: Customers | B21: Consumer; SMB; education; enterprise; government | C21: https://www.sec.gov/Archives/edgar/data/320193/000032019325000079/aapl-20250927.htm
A22: Sales channels | B22: Apple retail/online/direct sales + cellular carriers and resellers | C22: https://www.sec.gov/Archives/edgar/data/320193/000032019325000079/aapl-20250927.htm
A23: Geographic reach | B23: Americas; Europe; Greater China; Japan; Rest of Asia Pacific | C23: https://www.sec.gov/Archives/edgar/data/320193/000032019325000079/aapl-20250927.htm
A24: FY2025 revenue ($mm) | B24: 209586 | C24: https://www.apple.com/newsroom/pdfs/fy2025-q4/FY25_Q4_Consolidated_Financial_Statements.pdf
A25: Revenue contribution | B25: 0.50361759 | C25: https://www.apple.com/newsroom/pdfs/fy2025-q4/FY25_Q4_Consolidated_Financial_Statements.pdf
A26: Market share | B26: 0.2 | C26: https://counterpointresearch.com/en/insights/global-smartphone-shipments-grew-2-percent-YoY-in-2025
A27: Market position | B27: Global smartphone shipment leader in 2025 | C27: https://counterpointresearch.com/en/insights/global-smartphone-shipments-grew-2-percent-YoY-in-2025
A29: Mac / MacBook Business
A30: Category | B30: Personal computers | C30: https://www.sec.gov/Archives/edgar/data/320193/000032019325000079/aapl-20250927.htm
A31: Products / offering | B31: MacBook Air; MacBook Pro; iMac; Mac mini; Mac Studio; Mac Pro | C31: https://www.sec.gov/Archives/edgar/data/320193/000032019325000079/aapl-20250927.htm
A32: Customers | B32: Consumer; SMB; education; enterprise; government | C32: https://www.sec.gov/Archives/edgar/data/320193/000032019325000079/aapl-20250927.htm
A33: Sales channels | B33: Apple retail/online/direct sales + resellers | C33: https://www.sec.gov/Archives/edgar/data/320193/000032019325000079/aapl-20250927.htm
A34: Geographic reach | B34: Americas; Europe; Greater China; Japan; Rest of Asia Pacific | C34: https://www.sec.gov/Archives/edgar/data/320193/000032019325000079/aapl-20250927.htm
A35: FY2025 revenue ($mm) | B35: 33708 | C35: https://www.apple.com/newsroom/pdfs/fy2025-q4/FY25_Q4_Consolidated_Financial_Statements.pdf
A36: Revenue contribution | B36: 0.080997499 | C36: https://www.apple.com/newsroom/pdfs/fy2025-q4/FY25_Q4_Consolidated_Financial_Statements.pdf
A37: Market share | B37: Just under 10% | C37: https://www.idc.com/resource-center/blog/macbook-neo-apples-strategic-play-to-disrupt-the-pc-market/
A38: Market position | B38: Top-tier global PC vendor; below 10% global unit share in 2025 | C38: https://www.idc.com/resource-center/blog/macbook-neo-apples-strategic-play-to-disrupt-the-pc-market/
A40: iPad Business
A41: Category | B41: Tablets | C41: https://www.sec.gov/Archives/edgar/data/320193/000032019325000079/aapl-20250927.htm
A42: Products / offering | B42: iPad Pro; iPad Air; iPad; iPad mini | C42: https://www.sec.gov/Archives/edgar/data/320193/000032019325000079/aapl-20250927.htm
A43: Customers | B43: Consumer; SMB; education; enterprise; government | C43: https://www.sec.gov/Archives/edgar/data/320193/000032019325000079/aapl-20250927.htm
A44: Sales channels | B44: Apple retail/online/direct sales + resellers | C44: https://www.sec.gov/Archives/edgar/data/320193/000032019325000079/aapl-20250927.htm
...
