Workbook

Sheet Vertical Analysis
A2: Fiscal Year | B2: 2010
A4: INCOME STATEMENT
A5: Net Sales / Revenue | B5: 65225
A6: Total COGS | B6: 39541
A7: Gross Profit | B7: =B5-B6 -> 25684
A9: Research & Development | B9: 1782
A10: Selling, General & Administrative | B10: 5517
A11: Total Operating Expenses | B11: =B9+B10 -> 7299
A12: Operating Income (EBIT) | B12: =B7-B11 -> 18385
A13: % Growth | B13: =IFERROR(B12/#REF!-1,"")
A15: Other Income/(Expense), Net | B15: 155
A16: Total Other Income/(Expense) | B16: =B15 -> 155
A19: Income Before Income Taxes | B19: =B12+B16 -> 18540
A20: Provision for Income Taxes | B20: 4527
A21: Net Income | B21: =B19-B20 -> 14013
A24: BALANCE SHEET
A25: Cash & Cash Equivalents (FY1992 source reports Cash + ST Investments combined) | B25: 11261
A26: Short-Term Investments / Marketable Securities | B26: 14359
A27: Accounts Receivable, Net | B27: 5510
A28: Inventories | B28: 1051
A29: Deferred Tax Assets | B29: 1636
A30: Vendor Non-Trade Receivables | B30: 4414
A31: Other Current Assets | B31: 3447
A32: Total Current Assets | B32: =B25+B26+B27+B28+B29+B30+B31 -> 41678
A34: Property, Plant & Equipment, Net | B34: 4768
A35: Long-Term Marketable Securities | B35: 25391
A36: Goodwill | B36: 741
A37: Acquired Intangible Assets, Net | B37: 342
A38: Other Assets (legacy) | B38: 2263
A39: Other Non-Current Assets | B39: 0
A40: Total Non-Current Assets | B40: =B34+B35+B36+B37+B38+B39 -> 33505
A41: Total Assets | B41: =B32+B40 -> 75183
A43: Short-Term Borrowings / Notes Payable | B43: 0
A44: Accounts Payable | B44: 12015
A45: Accrued Expenses | B45: 5723
A46: Deferred Revenue - Current | B46: 2984
A47: Other Current Liabilities | B47: 0
A48: Commercial Paper | B48: 0
A49: Current Debt / Term Debt | B49: 0
A50: Total Current Liabilities | B50: =SUM(B43:B49) -> 20722
...

Sheet Horizontal Analysis
A2: Fiscal Year | B2: 2010 | C2: 2011 | D2: 2012 | E2: 2013 | F2: 2014 | G2: 2015 | H2: 2016 | I2: 2017 | J2: 2018 | K2: 2019 | L2: 2020 | M2: 2021 | N2: 2022 | O2: 2023 | P2: 2024 | Q2: 2025
A4: INCOME STATEMENT
A5: Net Sales / Revenue | B5: 65225 | C5: 108249 | D5: 156508 | E5: 170910 | F5: 182795 | G5: 233715 | H5: 215639 | I5: 229234 | J5: 265595 | K5: 260174 | L5: 274515 | M5: 365817 | N5: 394328 | O5: 383285 | P5: 391035 | Q5: 416161
A6: Total COGS | B6: 39541 | C6: 64431 | D6: 87846 | E6: 106606 | F6: 112258 | G6: 140089 | H6: 131376 | I6: 141048 | J6: 163756 | K6: 161782 | L6: 169559 | M6: 212981 | N6: 223546 | O6: 214137 | P6: 210352 | Q6: 220960
A7: Gross Profit | B7: =B5-B6 -> 25684 | C7: =C5-C6 -> 43818 | D7: =D5-D6 -> 68662 | E7: =E5-E6 -> 64304 | F7: =F5-F6 -> 70537 | G7: =G5-G6 -> 93626 | H7: =H5-H6 -> 84263 | I7: =I5-I6 -> 88186 | ... Q7: =Q5-Q6 -> 195201
A9: Research & Development | B9: 1782 | C9: 2429 | D9: 3381 | E9: 4475 | F9: 6041 | G9: 8067 | H9: 10045 | I9: 11581 | J9: 14236 | K9: 16217 | L9: 18752 | M9: 21914 | N9: 26251 | O9: 29915 | P9: 31370 | Q9: 34550
A10: Selling, General & Administrative | B10: 5517 | C10: 7599 | D10: 10040 | E10: 10830 | F10: 11993 | G10: 14329 | H10: 14194 | I10: 15261 | J10: 16705 | K10: 18245 | L10: 19916 | M10: 21973 | N10: 25094 | O10: 24932 | P10: 26097 | Q10: 27601
A11: Total Operating Expenses | B11: =B9+B10 -> 7299 | C11: =C9+C10 -> 10028 | D11: =D9+D10 -> 13421 | E11: =E9+E10 -> 15305 | F11: =F9+F10 -> 18034 | G11: =G9+G10 -> 22396 | H11: =H9+H10 -> 24239 | I11: =I9+I10 -> 26842 | ... Q11: =Q9+Q10 -> 62151
A12: Operating Income (EBIT) | B12: =B7-B11 -> 18385 | C12: =C7-C11 -> 33790 | D12: =D7-D11 -> 55241 | E12: =E7-E11 -> 48999 | F12: =F7-F11 -> 52503 | G12: =G7-G11 -> 71230 | H12: =H7-H11 -> 60024 | I12: =I7-I11 -> 61344 | ... Q12: =Q7-Q11 -> 133050
A13: % Growth | B13: =IFERROR(B12/#REF!-1,"") | C13: =IFERROR(C12/B12-1,"") -> 0.83791134 | D13: =IFERROR(D12/C12-1,"") -> 0.63483279 | E13: =IFERROR(E12/D12-1,"") -> -0.11299578 | F13: =IFERROR(F12/E12-1,"") -> 0.071511664 | G13: =IFERROR(G12/F12-1,"") -> 0.35668438 | H13: =IFERROR(H12/G12-1,"") -> -0.15732135 | I13: =IFERROR(I12/H12-1,"") -> 0.021991204 | J13: =IFERROR(J12/I12-1,"") -> 0.15574465 | ... Q13: =IFERROR(Q12/P12-1,"") -> 0.079811063
A15: Other Income/(Expense), Net | B15: 155 | C15: 415 | D15: 522 | E15: 1156 | F15: 980 | G15: 1285 | H15: 1348 | I15: 2745 | J15: 2005 | K15: 1807 | L15: 803 | M15: 258 | N15: -334 | O15: -565 | P15: 269 | Q15: -321
A16: Total Other Income/(Expense) | B16: =B15 -> 155 | C16: =C15 -> 415 | D16: =D15 -> 522 | E16: =E15 -> 1156 | F16: =F15 -> 980 | G16: =G15 -> 1285 | H16: =H15 -> 1348 | I16: =I15 -> 2745 | ... Q16: =Q15 -> -321
A19: Income Before Income Taxes | B19: =B12+B16 -> 18540 | C19: =C12+C16 -> 34205 | D19: =D12+D16 -> 55763 | E19: =E12+E16 -> 50155 | F19: =F12+F16 -> 53483 | G19: =G12+G16 -> 72515 | H19: =H12+H16 -> 61372 | I19: =I12+I16 -> 64089 | ... Q19: =Q12+Q16 -> 132729
A20: Provision for Income Taxes | B20: 4527 | C20: 8283 | D20: 14030 | E20: 13118 | F20: 13973 | G20: 19121 | H20: 15685 | I20: 15738 | J20: 13372 | K20: 10481 | L20: 9680 | M20: 14527 | N20: 19300 | O20: 16741 | P20: 29749 | Q20: 20719
A21: Net Income | B21: =B19-B20 -> 14013 | C21: =C19-C20 -> 25922 | D21: =D19-D20 -> 41733 | E21: =E19-E20 -> 37037 | F21: =F19-F20 -> 39510 | G21: =G19-G20 -> 53394 | H21: =H19-H20 -> 45687 | I21: =I19-I20 -> 48351 | ... Q21: =Q19-Q20 -> 112010
A24: BALANCE SHEET
A25: Cash & Cash Equivalents (FY1992 source reports Cash + ST Investments combined) | B25: 11261 | C25: 9815 | D25: 10746 | E25: 14259 | F25: 13844 | G25: 21120 | H25: 20484 | I25: 20289 | J25: 25913 | K25: 48844 | L25: 38016 | M25: 34940 | N25: 23646 | O25: 29965 | P25: 29943 | Q25: 35934
A26: Short-Term Investments / Marketable Securities | B26: 14359 | C26: 16137 | D26: 18383 | E26: 26287 | F26: 11233 | G26: 20481 | H26: 46671 | I26: 53892 | J26: 40388 | K26: 51713 | L26: 52927 | M26: 27699 | N26: 24658 | O26: 31590 | P26: 35228 | Q26: 18763
A27: Accounts Receivable, Net | B27: 5510 | C27: 5369 | D27: 10930 | E27: 13102 | F27: 17460 | G27: 16849 | H27: 15754 | I27: 17874 | J27: 23186 | K27: 22926 | L27: 16120 | M27: 26278 | N27: 28184 | O27: 29508 | P27: 33410 | Q27: 39777
A28: Inventories | B28: 1051 | C28: 776 | D28: 791 | E28: 1764 | F28: 2111 | G28: 2349 | H28: 2132 | I28: 4855 | J28: 3956 | K28: 4106 | L28: 4061 | M28: 6580 | N28: 4946 | O28: 6331 | P28: 7286 | Q28: 5718
A29: Deferred Tax Assets | B29: 1636 | C29: 2014 | D29: 2583 | E29: 3453 | F29: 4318 | G29: 5546 | H29: 0 | I29: 0 | J29: 0 | K29: 0 | L29: 0 | M29: 0 | N29: 0 | O29: 0 | P29: 0 | Q29: 0
A30: Vendor Non-Trade Receivables | B30: 4414 | C30: 6348 | D30: 7762 | E30: 7539 | F30: 9759 | G30: 13494 | H30: 13545 | I30: 17799 | J30: 25809 | K30: 22878 | L30: 21325 | M30: 25228 | N30: 32748 | O30: 31477 | P30: 32833 | Q30: 33180
A31: Other Current Assets | B31: 3447 | C31: 4529 | D31: 6458 | E31: 6882 | F31: 9806 | G31: 9539 | H31: 8283 | I31: 13936 | J31: 12087 | K31: 12352 | L31: 11264 | M31: 14111 | N31: 21223 | O31: 14695 | P31: 14287 | Q31: 14585
A32: Total Current Assets | B32: =B25+B26+B27+B28+B29+B30+B31 -> 41678 | C32: =C25+C26+C27+C28+C29+C30+C31 -> 44988 | D32: =D25+D26+D27+D28+D29+D30+D31 -> 57653 | E32: =E25+E26+E27+E28+E29+E30+E31 -> 73286 | F32: =F25+F26+F27+F28+F29+F30+F31 -> 68531 | G32: =G25+G26+G27+G28+G29+G30+G31 -> 89378 | H32: =H25+H26+H27+H28+H29+H30+H31 -> 106869 | I32: =I25+I26+I27+I28+I29+I30+I31 -> 128645 | ... Q32: =Q25+Q26+Q27+Q28+Q29+Q30+Q31 -> 147957
A34: Property, Plant & Equipment, Net | B34: 4768 | C34: 7777 | D34: 15452 | E34: 16597 | F34: 20624 | G34: 22471 | H34: 27010 | I34: 33783 | J34: 41304 | K34: 37378 | L34: 36766 | M34: 39440 | N34: 42117 | O34: 43715 | P34: 45680 | Q34: 49834
A35: Long-Term Marketable Securities | B35: 25391 | C35: 55618 | D35: 92122 | E35: 106215 | F35: 130162 | G35: 164065 | H35: 170430 | I35: 194714 | J35: 170799 | K35: 105341 | L35: 100887 | M35: 127877 | N35: 120805 | O35: 100544 | P35: 91479 | Q35: 77723
A36: Goodwill | B36: 741 | C36: 896 | D36: 1135 | E36: 1577 | F36: 4616 | G36: 5116 | H36: 5414 | I36: 5717 | J36: 0 | K36: 0 | L36: 0 | M36: 0 | N36: 0 | O36: 0 | P36: 0 | Q36: 0
A37: Acquired Intangible Assets, Net | B37: 342 | C37: 3536 | D37: 4224 | E37: 4179 | F37: 4142 | G37: 3893 | H37: 3206 | I37: 2298 | J37: 0 | K37: 0 | L37: 0 | M37: 0 | N37: 0 | O37: 0 | P37: 0 | Q37: 0
A38: Other Assets (legacy) | B38: 2263 | C38: 3556 | D38: 5478 | E38: 5146 | F38: 3764 | G38: 5556 | H38: 8757 | I38: 10162 | J38: 0 | K38: 0 | L38: 0 | M38: 0 | N38: 0 | O38: 0 | P38: 0 | Q38: 0
A39: Other Non-Current Assets | B39: 0 | C39: 0 | D39: 0 | E39: 0 | F39: 0 | G39: 0 | H39: 0 | I39: 0 | J39: 22283 | K39: 32978 | L39: 42522 | M39: 48849 | N39: 54428 | O39: 64758 | P39: 74834 | Q39: 83727
A40: Total Non-Current Assets | B40: =B34+B35+B36+B37+B38+B39 -> 33505 | C40: =C34+C35+C36+C37+C38+C39 -> 71383 | D40: =D34+D35+D36+D37+D38+D39 -> 118411 | E40: =E34+E35+E36+E37+E38+E39 -> 133714 | F40: =F34+F35+F36+F37+F38+F39 -> 163308 | G40: =G34+G35+G36+G37+G38+G39 -> 201101 | H40: =H34+H35+H36+H37+H38+H39 -> 214817 | I40: =I34+I35+I36+I37+I38+I39 -> 246674 | ... Q40: =Q34+Q35+Q36+Q37+Q38+Q39 -> 211284
A41: Total Assets | B41: =B32+B40 -> 75183 | C41: =C32+C40 -> 116371 | D41: =D32+D40 -> 176064 | E41: =E32+E40 -> 207000 | F41: =F32+F40 -> 231839 | G41: =G32+G40 -> 290479 | H41: =H32+H40 -> 321686 | I41: =I32+I40 -> 375319 | ... Q41: =Q32+Q40 -> 359241
A43: Short-Term Borrowings / Notes Payable | B43: 0 | C43: 0 | D43: 0 | E43: 0 | F43: 0 | G43: 0 | H43: 0 | I43: 0 | J43: 0 | K43: 0 | L43: 0 | M43: 0 | N43: 0 | O43: 0 | P43: 0 | Q43: 0
A44: Accounts Payable | B44: 12015 | C44: 14632 | D44: 21175 | E44: 22367 | F44: 30196 | G44: 35490 | H44: 37294 | I44: 49049 | J44: 55888 | K44: 46236 | L44: 42296 | M44: 54763 | N44: 64115 | O44: 62611 | P44: 68960 | Q44: 69860
A45: Accrued Expenses | B45: 5723 | C45: 9247 | D45: 11414 | E45: 13856 | F45: 18453 | G45: 25181 | H45: 22027 | I45: 25744 | J45: 0 | K45: 0 | L45: 0 | M45: 0 | N45: 0 | O45: 0 | P45: 0 | Q45: 0
A46: Deferred Revenue - Current | B46: 2984 | C46: 4091 | D46: 5953 | E46: 7435 | F46: 8491 | G46: 8940 | H46: 8080 | I46: 7548 | J46: 7543 | K46: 5522 | L46: 6643 | M46: 7612 | N46: 7912 | O46: 8061 | P46: 8249 | Q46: 9055
A47: Other Current Liabilities | B47: 0 | C47: 0 | D47: 0 | E47: 0 | F47: 0 | G47: 0 | H47: 0 | I47: 0 | J47: 32687 | K47: 37720 | L47: 42684 | M47: 47493 | N47: 60845 | O47: 58829 | P47: 78304 | Q47: 66387
A48: Commercial Paper | B48: 0 | C48: 0 | D48: 0 | E48: 0 | F48: 6308 | G48: 8499 | H48: 8105 | I48: 11977 | J48: 11964 | K48: 5980 | L48: 4996 | M48: 6000 | N48: 9982 | O48: 5985 | P48: 9967 | Q48: 7979
A49: Current Debt / Term Debt | B49: 0 | C49: 0 | D49: 0 | E49: 0 | F49: 0 | G49: 2500 | H49: 3500 | I49: 6496 | J49: 8784 | K49: 10260 | L49: 8773 | M49: 9613 | N49: 11128 | O49: 9822 | P49: 10912 | Q49: 12350
A50: Total Current Liabilities | B50: =SUM(B43:B49) -> 20722 | C50: =SUM(C43:C49) -> 27970 | D50: =SUM(D43:D49) -> 38542 | E50: =SUM(E43:E49) -> 43658 | F50: =SUM(F43:F49) -> 63448 | G50: =SUM(G43:G49) -> 80610 | H50: =SUM(H43:H49) -> 79006 | I50: =SUM(I43:I49) -> 100814 | ... Q50: =SUM(Q43:Q49) -> 165631
...

Sheet Common Size
A2: Fiscal Year | B2: 2010 | C2: 2011 | D2: 2012 | E2: 2013 | F2: 2014 | G2: 2015 | H2: 2016 | I2: 2017 | J2: 2018 | K2: 2019 | L2: 2020 | M2: 2021 | N2: 2022 | O2: 2023 | P2: 2024 | Q2: 2025
A4: INCOME STATEMENT
A5: Net Sales / Revenue | B5: 65225 | C5: 108249 | D5: 156508 | E5: 170910 | F5: 182795 | G5: 233715 | H5: 215639 | I5: 229234 | J5: 265595 | K5: 260174 | L5: 274515 | M5: 365817 | N5: 394328 | O5: 383285 | P5: 391035 | Q5: 416161
A6: Total COGS | B6: 39541 | C6: 64431 | D6: 87846 | E6: 106606 | F6: 112258 | G6: 140089 | H6: 131376 | I6: 141048 | J6: 163756 | K6: 161782 | L6: 169559 | M6: 212981 | N6: 223546 | O6: 214137 | P6: 210352 | Q6: 220960
A7: Gross Profit | B7: =B5-B6 -> 25684 | C7: =C5-C6 -> 43818 | D7: =D5-D6 -> 68662 | E7: =E5-E6 -> 64304 | F7: =F5-F6 -> 70537 | G7: =G5-G6 -> 93626 | H7: =H5-H6 -> 84263 | I7: =I5-I6 -> 88186 | ... Q7: =Q5-Q6 -> 195201
A9: Research & Development | B9: 1782 | C9: 2429 | D9: 3381 | E9: 4475 | F9: 6041 | G9: 8067 | H9: 10045 | I9: 11581 | J9: 14236 | K9: 16217 | L9: 18752 | M9: 21914 | N9: 26251 | O9: 29915 | P9: 31370 | Q9: 34550
A10: Selling, General & Administrative | B10: 5517 | C10: 7599 | D10: 10040 | E10: 10830 | F10: 11993 | G10: 14329 | H10: 14194 | I10: 15261 | J10: 16705 | K10: 18245 | L10: 19916 | M10: 21973 | N10: 25094 | O10: 24932 | P10: 26097 | Q10: 27601
A11: Total Operating Expenses | B11: =B9+B10 -> 7299 | C11: =C9+C10 -> 10028 | D11: =D9+D10 -> 13421 | E11: =E9+E10 -> 15305 | F11: =F9+F10 -> 18034 | G11: =G9+G10 -> 22396 | H11: =H9+H10 -> 24239 | I11: =I9+I10 -> 26842 | ... Q11: =Q9+Q10 -> 62151
A12: Operating Income (EBIT) | B12: =B7-B11 -> 18385 | C12: =C7-C11 -> 33790 | D12: =D7-D11 -> 55241 | E12: =E7-E11 -> 48999 | F12: =F7-F11 -> 52503 | G12: =G7-G11 -> 71230 | H12: =H7-H11 -> 60024 | I12: =I7-I11 -> 61344 | ... Q12: =Q7-Q11 -> 133050
A13: % Growth | B13: =IFERROR(B12/#REF!-1,"") | C13: =IFERROR(C12/B12-1,"") -> 0.83791134 | D13: =IFERROR(D12/C12-1,"") -> 0.63483279 | E13: =IFERROR(E12/D12-1,"") -> -0.11299578 | F13: =IFERROR(F12/E12-1,"") -> 0.071511664 | G13: =IFERROR(G12/F12-1,"") -> 0.35668438 | H13: =IFERROR(H12/G12-1,"") -> -0.15732135 | I13: =IFERROR(I12/H12-1,"") -> 0.021991204 | J13: =IFERROR(J12/I12-1,"") -> 0.15574465 | ... Q13: =IFERROR(Q12/P12-1,"") -> 0.079811063
A15: Other Income/(Expense), Net | B15: 155 | C15: 415 | D15: 522 | E15: 1156 | F15: 980 | G15: 1285 | H15: 1348 | I15: 2745 | J15: 2005 | K15: 1807 | L15: 803 | M15: 258 | N15: -334 | O15: -565 | P15: 269 | Q15: -321
A16: Total Other Income/(Expense) | B16: =B15 -> 155 | C16: =C15 -> 415 | D16: =D15 -> 522 | E16: =E15 -> 1156 | F16: =F15 -> 980 | G16: =G15 -> 1285 | H16: =H15 -> 1348 | I16: =I15 -> 2745 | ... Q16: =Q15 -> -321
A19: Income Before Income Taxes | B19: =B12+B16 -> 18540 | C19: =C12+C16 -> 34205 | D19: =D12+D16 -> 55763 | E19: =E12+E16 -> 50155 | F19: =F12+F16 -> 53483 | G19: =G12+G16 -> 72515 | H19: =H12+H16 -> 61372 | I19: =I12+I16 -> 64089 | ... Q19: =Q12+Q16 -> 132729
A20: Provision for Income Taxes | B20: 4527 | C20: 8283 | D20: 14030 | E20: 13118 | F20: 13973 | G20: 19121 | H20: 15685 | I20: 15738 | J20: 13372 | K20: 10481 | L20: 9680 | M20: 14527 | N20: 19300 | O20: 16741 | P20: 29749 | Q20: 20719
A21: Net Income | B21: =B19-B20 -> 14013 | C21: =C19-C20 -> 25922 | D21: =D19-D20 -> 41733 | E21: =E19-E20 -> 37037 | F21: =F19-F20 -> 39510 | G21: =G19-G20 -> 53394 | H21: =H19-H20 -> 45687 | I21: =I19-I20 -> 48351 | ... Q21: =Q19-Q20 -> 112010
A24: BALANCE SHEET
A25: Cash & Cash Equivalents (FY1992 source reports Cash + ST Investments combined) | B25: 11261 | C25: 9815 | D25: 10746 | E25: 14259 | F25: 13844 | G25: 21120 | H25: 20484 | I25: 20289 | J25: 25913 | K25: 48844 | L25: 38016 | M25: 34940 | N25: 23646 | O25: 29965 | P25: 29943 | Q25: 35934
A26: Short-Term Investments / Marketable Securities | B26: 14359 | C26: 16137 | D26: 18383 | E26: 26287 | F26: 11233 | G26: 20481 | H26: 46671 | I26: 53892 | J26: 40388 | K26: 51713 | L26: 52927 | M26: 27699 | N26: 24658 | O26: 31590 | P26: 35228 | Q26: 18763
A27: Accounts Receivable, Net | B27: 5510 | C27: 5369 | D27: 10930 | E27: 13102 | F27: 17460 | G27: 16849 | H27: 15754 | I27: 17874 | J27: 23186 | K27: 22926 | L27: 16120 | M27: 26278 | N27: 28184 | O27: 29508 | P27: 33410 | Q27: 39777
A28: Inventories | B28: 1051 | C28: 776 | D28: 791 | E28: 1764 | F28: 2111 | G28: 2349 | H28: 2132 | I28: 4855 | J28: 3956 | K28: 4106 | L28: 4061 | M28: 6580 | N28: 4946 | O28: 6331 | P28: 7286 | Q28: 5718
A29: Deferred Tax Assets | B29: 1636 | C29: 2014 | D29: 2583 | E29: 3453 | F29: 4318 | G29: 5546 | H29: 0 | I29: 0 | J29: 0 | K29: 0 | L29: 0 | M29: 0 | N29: 0 | O29: 0 | P29: 0 | Q29: 0
A30: Vendor Non-Trade Receivables | B30: 4414 | C30: 6348 | D30: 7762 | E30: 7539 | F30: 9759 | G30: 13494 | H30: 13545 | I30: 17799 | J30: 25809 | K30: 22878 | L30: 21325 | M30: 25228 | N30: 32748 | O30: 31477 | P30: 32833 | Q30: 33180
A31: Other Current Assets | B31: 3447 | C31: 4529 | D31: 6458 | E31: 6882 | F31: 9806 | G31: 9539 | H31: 8283 | I31: 13936 | J31: 12087 | K31: 12352 | L31: 11264 | M31: 14111 | N31: 21223 | O31: 14695 | P31: 14287 | Q31: 14585
A32: Total Current Assets | B32: =B25+B26+B27+B28+B29+B30+B31 -> 41678 | C32: =C25+C26+C27+C28+C29+C30+C31 -> 44988 | D32: =D25+D26+D27+D28+D29+D30+D31 -> 57653 | E32: =E25+E26+E27+E28+E29+E30+E31 -> 73286 | F32: =F25+F26+F27+F28+F29+F30+F31 -> 68531 | G32: =G25+G26+G27+G28+G29+G30+G31 -> 89378 | H32: =H25+H26+H27+H28+H29+H30+H31 -> 106869 | I32: =I25+I26+I27+I28+I29+I30+I31 -> 128645 | ... Q32: =Q25+Q26+Q27+Q28+Q29+Q30+Q31 -> 147957
A34: Property, Plant & Equipment, Net | B34: 4768 | C34: 7777 | D34: 15452 | E34: 16597 | F34: 20624 | G34: 22471 | H34: 27010 | I34: 33783 | J34: 41304 | K34: 37378 | L34: 36766 | M34: 39440 | N34: 42117 | O34: 43715 | P34: 45680 | Q34: 49834
A35: Long-Term Marketable Securities | B35: 25391 | C35: 55618 | D35: 92122 | E35: 106215 | F35: 130162 | G35: 164065 | H35: 170430 | I35: 194714 | J35: 170799 | K35: 105341 | L35: 100887 | M35: 127877 | N35: 120805 | O35: 100544 | P35: 91479 | Q35: 77723
A36: Goodwill | B36: 741 | C36: 896 | D36: 1135 | E36: 1577 | F36: 4616 | G36: 5116 | H36: 5414 | I36: 5717 | J36: 0 | K36: 0 | L36: 0 | M36: 0 | N36: 0 | O36: 0 | P36: 0 | Q36: 0
A37: Acquired Intangible Assets, Net | B37: 342 | C37: 3536 | D37: 4224 | E37: 4179 | F37: 4142 | G37: 3893 | H37: 3206 | I37: 2298 | J37: 0 | K37: 0 | L37: 0 | M37: 0 | N37: 0 | O37: 0 | P37: 0 | Q37: 0
A38: Other Assets (legacy) | B38: 2263 | C38: 3556 | D38: 5478 | E38: 5146 | F38: 3764 | G38: 5556 | H38: 8757 | I38: 10162 | J38: 0 | K38: 0 | L38: 0 | M38: 0 | N38: 0 | O38: 0 | P38: 0 | Q38: 0
A39: Other Non-Current Assets | B39: 0 | C39: 0 | D39: 0 | E39: 0 | F39: 0 | G39: 0 | H39: 0 | I39: 0 | J39: 22283 | K39: 32978 | L39: 42522 | M39: 48849 | N39: 54428 | O39: 64758 | P39: 74834 | Q39: 83727
A40: Total Non-Current Assets | B40: =B34+B35+B36+B37+B38+B39 -> 33505 | C40: =C34+C35+C36+C37+C38+C39 -> 71383 | D40: =D34+D35+D36+D37+D38+D39 -> 118411 | E40: =E34+E35+E36+E37+E38+E39 -> 133714 | F40: =F34+F35+F36+F37+F38+F39 -> 163308 | G40: =G34+G35+G36+G37+G38+G39 -> 201101 | H40: =H34+H35+H36+H37+H38+H39 -> 214817 | I40: =I34+I35+I36+I37+I38+I39 -> 246674 | ... Q40: =Q34+Q35+Q36+Q37+Q38+Q39 -> 211284
A41: Total Assets | B41: =B32+B40 -> 75183 | C41: =C32+C40 -> 116371 | D41: =D32+D40 -> 176064 | E41: =E32+E40 -> 207000 | F41: =F32+F40 -> 231839 | G41: =G32+G40 -> 290479 | H41: =H32+H40 -> 321686 | I41: =I32+I40 -> 375319 | ... Q41: =Q32+Q40 -> 359241
A43: Short-Term Borrowings / Notes Payable | B43: 0 | C43: 0 | D43: 0 | E43: 0 | F43: 0 | G43: 0 | H43: 0 | I43: 0 | J43: 0 | K43: 0 | L43: 0 | M43: 0 | N43: 0 | O43: 0 | P43: 0 | Q43: 0
A44: Accounts Payable | B44: 12015 | C44: 14632 | D44: 21175 | E44: 22367 | F44: 30196 | G44: 35490 | H44: 37294 | I44: 49049 | J44: 55888 | K44: 46236 | L44: 42296 | M44: 54763 | N44: 64115 | O44: 62611 | P44: 68960 | Q44: 69860
A45: Accrued Expenses | B45: 5723 | C45: 9247 | D45: 11414 | E45: 13856 | F45: 18453 | G45: 25181 | H45: 22027 | I45: 25744 | J45: 0 | K45: 0 | L45: 0 | M45: 0 | N45: 0 | O45: 0 | P45: 0 | Q45: 0
A46: Deferred Revenue - Current | B46: 2984 | C46: 4091 | D46: 5953 | E46: 7435 | F46: 8491 | G46: 8940 | H46: 8080 | I46: 7548 | J46: 7543 | K46: 5522 | L46: 6643 | M46: 7612 | N46: 7912 | O46: 8061 | P46: 8249 | Q46: 9055
A47: Other Current Liabilities | B47: 0 | C47: 0 | D47: 0 | E47: 0 | F47: 0 | G47: 0 | H47: 0 | I47: 0 | J47: 32687 | K47: 37720 | L47: 42684 | M47: 47493 | N47: 60845 | O47: 58829 | P47: 78304 | Q47: 66387
A48: Commercial Paper | B48: 0 | C48: 0 | D48: 0 | E48: 0 | F48: 6308 | G48: 8499 | H48: 8105 | I48: 11977 | J48: 11964 | K48: 5980 | L48: 4996 | M48: 6000 | N48: 9982 | O48: 5985 | P48: 9967 | Q48: 7979
A49: Current Debt / Term Debt | B49: 0 | C49: 0 | D49: 0 | E49: 0 | F49: 0 | G49: 2500 | H49: 3500 | I49: 6496 | J49: 8784 | K49: 10260 | L49: 8773 | M49: 9613 | N49: 11128 | O49: 9822 | P49: 10912 | Q49: 12350
A50: Total Current Liabilities | B50: =SUM(B43:B49) -> 20722 | C50: =SUM(C43:C49) -> 27970 | D50: =SUM(D43:D49) -> 38542 | E50: =SUM(E43:E49) -> 43658 | F50: =SUM(F43:F49) -> 63448 | G50: =SUM(G43:G49) -> 80610 | H50: =SUM(H43:H49) -> 79006 | I50: =SUM(I43:I49) -> 100814 | ... Q50: =SUM(Q43:Q49) -> 165631
...

Sheet Index Analysis
A2: Fiscal Year | B2: 2010 | C2: 2011 | D2: 2012 | E2: 2013 | F2: 2014 | G2: 2015 | H2: 2016 | I2: 2017 | J2: 2018 | K2: 2019 | L2: 2020 | M2: 2021 | N2: 2022 | O2: 2023 | P2: 2024 | Q2: 2025
A4: INCOME STATEMENT
A5: Net Sales / Revenue | B5: 65225 | C5: 108249 | D5: 156508 | E5: 170910 | F5: 182795 | G5: 233715 | H5: 215639 | I5: 229234 | J5: 265595 | K5: 260174 | L5: 274515 | M5: 365817 | N5: 394328 | O5: 383285 | P5: 391035 | Q5: 416161
A6: Total COGS | B6: 39541 | C6: 64431 | D6: 87846 | E6: 106606 | F6: 112258 | G6: 140089 | H6: 131376 | I6: 141048 | J6: 163756 | K6: 161782 | L6: 169559 | M6: 212981 | N6: 223546 | O6: 214137 | P6: 210352 | Q6: 220960
A7: Gross Profit | B7: =B5-B6 -> 25684 | C7: =C5-C6 -> 43818 | D7: =D5-D6 -> 68662 | E7: =E5-E6 -> 64304 | F7: =F5-F6 -> 70537 | G7: =G5-G6 -> 93626 | H7: =H5-H6 -> 84263 | I7: =I5-I6 -> 88186 | ... Q7: =Q5-Q6 -> 195201
A9: Research & Development | B9: 1782 | C9: 2429 | D9: 3381 | E9: 4475 | F9: 6041 | G9: 8067 | H9: 10045 | I9: 11581 | J9: 14236 | K9: 16217 | L9: 18752 | M9: 21914 | N9: 26251 | O9: 29915 | P9: 31370 | Q9: 34550
A10: Selling, General & Administrative | B10: 5517 | C10: 7599 | D10: 10040 | E10: 10830 | F10: 11993 | G10: 14329 | H10: 14194 | I10: 15261 | J10: 16705 | K10: 18245 | L10: 19916 | M10: 21973 | N10: 25094 | O10: 24932 | P10: 26097 | Q10: 27601
A11: Total Operating Expenses | B11: =B9+B10 -> 7299 | C11: =C9+C10 -> 10028 | D11: =D9+D10 -> 13421 | E11: =E9+E10 -> 15305 | F11: =F9+F10 -> 18034 | G11: =G9+G10 -> 22396 | H11: =H9+H10 -> 24239 | I11: =I9+I10 -> 26842 | ... Q11: =Q9+Q10 -> 62151
A12: Operating Income (EBIT) | B12: =B7-B11 -> 18385 | C12: =C7-C11 -> 33790 | D12: =D7-D11 -> 55241 | E12: =E7-E11 -> 48999 | F12: =F7-F11 -> 52503 | G12: =G7-G11 -> 71230 | H12: =H7-H11 -> 60024 | I12: =I7-I11 -> 61344 | ... Q12: =Q7-Q11 -> 133050
A13: % Growth | B13: =IFERROR(B12/#REF!-1,"") | C13: =IFERROR(C12/B12-1,"") -> 0.83791134 | D13: =IFERROR(D12/C12-1,"") -> 0.63483279 | E13: =IFERROR(E12/D12-1,"") -> -0.11299578 | F13: =IFERROR(F12/E12-1,"") -> 0.071511664 | G13: =IFERROR(G12/F12-1,"") -> 0.35668438 | H13: =IFERROR(H12/G12-1,"") -> -0.15732135 | I13: =IFERROR(I12/H12-1,"") -> 0.021991204 | J13: =IFERROR(J12/I12-1,"") -> 0.15574465 | ... Q13: =IFERROR(Q12/P12-1,"") -> 0.079811063
A15: Other Income/(Expense), Net | B15: 155 | C15: 415 | D15: 522 | E15: 1156 | F15: 980 | G15: 1285 | H15: 1348 | I15: 2745 | J15: 2005 | K15: 1807 | L15: 803 | M15: 258 | N15: -334 | O15: -565 | P15: 269 | Q15: -321
A16: Total Other Income/(Expense) | B16: =B15 -> 155 | C16: =C15 -> 415 | D16: =D15 -> 522 | E16: =E15 -> 1156 | F16: =F15 -> 980 | G16: =G15 -> 1285 | H16: =H15 -> 1348 | I16: =I15 -> 2745 | ... Q16: =Q15 -> -321
A19: Income Before Income Taxes | B19: =B12+B16 -> 18540 | C19: =C12+C16 -> 34205 | D19: =D12+D16 -> 55763 | E19: =E12+E16 -> 50155 | F19: =F12+F16 -> 53483 | G19: =G12+G16 -> 72515 | H19: =H12+H16 -> 61372 | I19: =I12+I16 -> 64089 | ... Q19: =Q12+Q16 -> 132729
A20: Provision for Income Taxes | B20: 4527 | C20: 8283 | D20: 14030 | E20: 13118 | F20: 13973 | G20: 19121 | H20: 15685 | I20: 15738 | J20: 13372 | K20: 10481 | L20: 9680 | M20: 14527 | N20: 19300 | O20: 16741 | P20: 29749 | Q20: 20719
A21: Net Income | B21: =B19-B20 -> 14013 | C21: =C19-C20 -> 25922 | D21: =D19-D20 -> 41733 | E21: =E19-E20 -> 37037 | F21: =F19-F20 -> 39510 | G21: =G19-G20 -> 53394 | H21: =H19-H20 -> 45687 | I21: =I19-I20 -> 48351 | ... Q21: =Q19-Q20 -> 112010
A24: BALANCE SHEET
A25: Cash & Cash Equivalents (FY1992 source reports Cash + ST Investments combined) | B25: 11261 | C25: 9815 | D25: 10746 | E25: 14259 | F25: 13844 | G25: 21120 | H25: 20484 | I25: 20289 | J25: 25913 | K25: 48844 | L25: 38016 | M25: 34940 | N25: 23646 | O25: 29965 | P25: 29943 | Q25: 35934
A26: Short-Term Investments / Marketable Securities | B26: 14359 | C26: 16137 | D26: 18383 | E26: 26287 | F26: 11233 | G26: 20481 | H26: 46671 | I26: 53892 | J26: 40388 | K26: 51713 | L26: 52927 | M26: 27699 | N26: 24658 | O26: 31590 | P26: 35228 | Q26: 18763
A27: Accounts Receivable, Net | B27: 5510 | C27: 5369 | D27: 10930 | E27: 13102 | F27: 17460 | G27: 16849 | H27: 15754 | I27: 17874 | J27: 23186 | K27: 22926 | L27: 16120 | M27: 26278 | N27: 28184 | O27: 29508 | P27: 33410 | Q27: 39777
A28: Inventories | B28: 1051 | C28: 776 | D28: 791 | E28: 1764 | F28: 2111 | G28: 2349 | H28: 2132 | I28: 4855 | J28: 3956 | K28: 4106 | L28: 4061 | M28: 6580 | N28: 4946 | O28: 6331 | P28: 7286 | Q28: 5718
A29: Deferred Tax Assets | B29: 1636 | C29: 2014 | D29: 2583 | E29: 3453 | F29: 4318 | G29: 5546 | H29: 0 | I29: 0 | J29: 0 | K29: 0 | L29: 0 | M29: 0 | N29: 0 | O29: 0 | P29: 0 | Q29: 0
A30: Vendor Non-Trade Receivables | B30: 4414 | C30: 6348 | D30: 7762 | E30: 7539 | F30: 9759 | G30: 13494 | H30: 13545 | I30: 17799 | J30: 25809 | K30: 22878 | L30: 21325 | M30: 25228 | N30: 32748 | O30: 31477 | P30: 32833 | Q30: 33180
A31: Other Current Assets | B31: 3447 | C31: 4529 | D31: 6458 | E31: 6882 | F31: 9806 | G31: 9539 | H31: 8283 | I31: 13936 | J31: 12087 | K31: 12352 | L31: 11264 | M31: 14111 | N31: 21223 | O31: 14695 | P31: 14287 | Q31: 14585
A32: Total Current Assets | B32: =B25+B26+B27+B28+B29+B30+B31 -> 41678 | C32: =C25+C26+C27+C28+C29+C30+C31 -> 44988 | D32: =D25+D26+D27+D28+D29+D30+D31 -> 57653 | E32: =E25+E26+E27+E28+E29+E30+E31 -> 73286 | F32: =F25+F26+F27+F28+F29+F30+F31 -> 68531 | G32: =G25+G26+G27+G28+G29+G30+G31 -> 89378 | H32: =H25+H26+H27+H28+H29+H30+H31 -> 106869 | I32: =I25+I26+I27+I28+I29+I30+I31 -> 128645 | ... Q32: =Q25+Q26+Q27+Q28+Q29+Q30+Q31 -> 147957
A34: Property, Plant & Equipment, Net | B34: 4768 | C34: 7777 | D34: 15452 | E34: 16597 | F34: 20624 | G34: 22471 | H34: 27010 | I34: 33783 | J34: 41304 | K34: 37378 | L34: 36766 | M34: 39440 | N34: 42117 | O34: 43715 | P34: 45680 | Q34: 49834
A35: Long-Term Marketable Securities | B35: 25391 | C35: 55618 | D35: 92122 | E35: 106215 | F35: 130162 | G35: 164065 | H35: 170430 | I35: 194714 | J35: 170799 | K35: 105341 | L35: 100887 | M35: 127877 | N35: 120805 | O35: 100544 | P35: 91479 | Q35: 77723
A36: Goodwill | B36: 741 | C36: 896 | D36: 1135 | E36: 1577 | F36: 4616 | G36: 5116 | H36: 5414 | I36: 5717 | J36: 0 | K36: 0 | L36: 0 | M36: 0 | N36: 0 | O36: 0 | P36: 0 | Q36: 0
A37: Acquired Intangible Assets, Net | B37: 342 | C37: 3536 | D37: 4224 | E37: 4179 | F37: 4142 | G37: 3893 | H37: 3206 | I37: 2298 | J37: 0 | K37: 0 | L37: 0 | M37: 0 | N37: 0 | O37: 0 | P37: 0 | Q37: 0
A38: Other Assets (legacy) | B38: 2263 | C38: 3556 | D38: 5478 | E38: 5146 | F38: 3764 | G38: 5556 | H38: 8757 | I38: 10162 | J38: 0 | K38: 0 | L38: 0 | M38: 0 | N38: 0 | O38: 0 | P38: 0 | Q38: 0
A39: Other Non-Current Assets | B39: 0 | C39: 0 | D39: 0 | E39: 0 | F39: 0 | G39: 0 | H39: 0 | I39: 0 | J39: 22283 | K39: 32978 | L39: 42522 | M39: 48849 | N39: 54428 | O39: 64758 | P39: 74834 | Q39: 83727
A40: Total Non-Current Assets | B40: =B34+B35+B36+B37+B38+B39 -> 33505 | C40: =C34+C35+C36+C37+C38+C39 -> 71383 | D40: =D34+D35+D36+D37+D38+D39 -> 118411 | E40: =E34+E35+E36+E37+E38+E39 -> 133714 | F40: =F34+F35+F36+F37+F38+F39 -> 163308 | G40: =G34+G35+G36+G37+G38+G39 -> 201101 | H40: =H34+H35+H36+H37+H38+H39 -> 214817 | I40: =I34+I35+I36+I37+I38+I39 -> 246674 | ... Q40: =Q34+Q35+Q36+Q37+Q38+Q39 -> 211284
A41: Total Assets | B41: =B32+B40 -> 75183 | C41: =C32+C40 -> 116371 | D41: =D32+D40 -> 176064 | E41: =E32+E40 -> 207000 | F41: =F32+F40 -> 231839 | G41: =G32+G40 -> 290479 | H41: =H32+H40 -> 321686 | I41: =I32+I40 -> 375319 | ... Q41: =Q32+Q40 -> 359241
A43: Short-Term Borrowings / Notes Payable | B43: 0 | C43: 0 | D43: 0 | E43: 0 | F43: 0 | G43: 0 | H43: 0 | I43: 0 | J43: 0 | K43: 0 | L43: 0 | M43: 0 | N43: 0 | O43: 0 | P43: 0 | Q43: 0
A44: Accounts Payable | B44: 12015 | C44: 14632 | D44: 21175 | E44: 22367 | F44: 30196 | G44: 35490 | H44: 37294 | I44: 49049 | J44: 55888 | K44: 46236 | L44: 42296 | M44: 54763 | N44: 64115 | O44: 62611 | P44: 68960 | Q44: 69860
A45: Accrued Expenses | B45: 5723 | C45: 9247 | D45: 11414 | E45: 13856 | F45: 18453 | G45: 25181 | H45: 22027 | I45: 25744 | J45: 0 | K45: 0 | L45: 0 | M45: 0 | N45: 0 | O45: 0 | P45: 0 | Q45: 0
A46: Deferred Revenue - Current | B46: 2984 | C46: 4091 | D46: 5953 | E46: 7435 | F46: 8491 | G46: 8940 | H46: 8080 | I46: 7548 | J46: 7543 | K46: 5522 | L46: 6643 | M46: 7612 | N46: 7912 | O46: 8061 | P46: 8249 | Q46: 9055
A47: Other Current Liabilities | B47: 0 | C47: 0 | D47: 0 | E47: 0 | F47: 0 | G47: 0 | H47: 0 | I47: 0 | J47: 32687 | K47: 37720 | L47: 42684 | M47: 47493 | N47: 60845 | O47: 58829 | P47: 78304 | Q47: 66387
A48: Commercial Paper | B48: 0 | C48: 0 | D48: 0 | E48: 0 | F48: 6308 | G48: 8499 | H48: 8105 | I48: 11977 | J48: 11964 | K48: 5980 | L48: 4996 | M48: 6000 | N48: 9982 | O48: 5985 | P48: 9967 | Q48: 7979
A49: Current Debt / Term Debt | B49: 0 | C49: 0 | D49: 0 | E49: 0 | F49: 0 | G49: 2500 | H49: 3500 | I49: 6496 | J49: 8784 | K49: 10260 | L49: 8773 | M49: 9613 | N49: 11128 | O49: 9822 | P49: 10912 | Q49: 12350
A50: Total Current Liabilities | B50: =SUM(B43:B49) -> 20722 | C50: =SUM(C43:C49) -> 27970 | D50: =SUM(D43:D49) -> 38542 | E50: =SUM(E43:E49) -> 43658 | F50: =SUM(F43:F49) -> 63448 | G50: =SUM(G43:G49) -> 80610 | H50: =SUM(H43:H49) -> 79006 | I50: =SUM(I43:I49) -> 100814 | ... Q50: =SUM(Q43:Q49) -> 165631
...

Sheet Financial Analyst
A1: Fiscal Year | B1: 2010 | C1: 2011 | D1: 2012 | E1: 2013 | F1: 2014 | G1: 2015 | H1: 2016 | I1: 2017 | J1: 2018 | K1: 2019 | L1: 2020 | M1: 2021 | N1: 2022 | O1: 2023 | P1: 2024 | Q1: 2025
A3: INCOME STATEMENT
A4: Net Sales / Revenue | B4: 65225 | C4: 108249 | D4: 156508 | E4: 170910 | F4: 182795 | G4: 233715 | H4: 215639 | I4: 229234 | J4: 265595 | K4: 260174 | L4: 274515 | M4: 365817 | N4: 394328 | O4: 383285 | P4: 391035 | Q4: 416161
A5: Total COGS | B5: 39541 | C5: 64431 | D5: 87846 | E5: 106606 | F5: 112258 | G5: 140089 | H5: 131376 | I5: 141048 | J5: 163756 | K5: 161782 | L5: 169559 | M5: 212981 | N5: 223546 | O5: 214137 | P5: 210352 | Q5: 220960
A6: Gross Profit | B6: =B4-B5 -> 25684 | C6: =C4-C5 -> 43818 | D6: =D4-D5 -> 68662 | E6: =E4-E5 -> 64304 | F6: =F4-F5 -> 70537 | G6: =G4-G5 -> 93626 | H6: =H4-H5 -> 84263 | I6: =I4-I5 -> 88186 | ... Q6: =Q4-Q5 -> 195201
A8: Research & Development | B8: 1782 | C8: 2429 | D8: 3381 | E8: 4475 | F8: 6041 | G8: 8067 | H8: 10045 | I8: 11581 | J8: 14236 | K8: 16217 | L8: 18752 | M8: 21914 | N8: 26251 | O8: 29915 | P8: 31370 | Q8: 34550
A9: Selling, General & Administrative | B9: 5517 | C9: 7599 | D9: 10040 | E9: 10830 | F9: 11993 | G9: 14329 | H9: 14194 | I9: 15261 | J9: 16705 | K9: 18245 | L9: 19916 | M9: 21973 | N9: 25094 | O9: 24932 | P9: 26097 | Q9: 27601
A10: Total Operating Expenses | B10: =B8+B9 -> 7299 | C10: =C8+C9 -> 10028 | D10: =D8+D9 -> 13421 | E10: =E8+E9 -> 15305 | F10: =F8+F9 -> 18034 | G10: =G8+G9 -> 22396 | H10: =H8+H9 -> 24239 | I10: =I8+I9 -> 26842 | ... Q10: =Q8+Q9 -> 62151
A11: Operating Income (EBIT) | B11: =B6-B10 -> 18385 | C11: =C6-C10 -> 33790 | D11: =D6-D10 -> 55241 | E11: =E6-E10 -> 48999 | F11: =F6-F10 -> 52503 | G11: =G6-G10 -> 71230 | H11: =H6-H10 -> 60024 | I11: =I6-I10 -> 61344 | ... Q11: =Q6-Q10 -> 133050
A12: % Growth | B12: =IFERROR(B11/#REF!-1,"") | C12: =IFERROR(C11/B11-1,"") -> 0.83791134 | D12: =IFERROR(D11/C11-1,"") -> 0.63483279 | E12: =IFERROR(E11/D11-1,"") -> -0.11299578 | F12: =IFERROR(F11/E11-1,"") -> 0.071511664 | G12: =IFERROR(G11/F11-1,"") -> 0.35668438 | H12: =IFERROR(H11/G11-1,"") -> -0.15732135 | I12: =IFERROR(I11/H11-1,"") -> 0.021991204 | J12: =IFERROR(J11/I11-1,"") -> 0.15574465 | ... Q12: =IFERROR(Q11/P11-1,"") -> 0.079811063
A14: Other Income/(Expense), Net | B14: 155 | C14: 415 | D14: 522 | E14: 1156 | F14: 980 | G14: 1285 | H14: 1348 | I14: 2745 | J14: 2005 | K14: 1807 | L14: 803 | M14: 258 | N14: -334 | O14: -565 | P14: 269 | Q14: -321
A15: Total Other Income/(Expense) | B15: =B14 -> 155 | C15: =C14 -> 415 | D15: =D14 -> 522 | E15: =E14 -> 1156 | F15: =F14 -> 980 | G15: =G14 -> 1285 | H15: =H14 -> 1348 | I15: =I14 -> 2745 | ... Q15: =Q14 -> -321
A18: Income Before Income Taxes | B18: =B11+B15 -> 18540 | C18: =C11+C15 -> 34205 | D18: =D11+D15 -> 55763 | E18: =E11+E15 -> 50155 | F18: =F11+F15 -> 53483 | G18: =G11+G15 -> 72515 | H18: =H11+H15 -> 61372 | I18: =I11+I15 -> 64089 | ... Q18: =Q11+Q15 -> 132729
A19: Provision for Income Taxes | B19: 4527 | C19: 8283 | D19: 14030 | E19: 13118 | F19: 13973 | G19: 19121 | H19: 15685 | I19: 15738 | J19: 13372 | K19: 10481 | L19: 9680 | M19: 14527 | N19: 19300 | O19: 16741 | P19: 29749 | Q19: 20719
A20: Net Income | B20: =B18-B19 -> 14013 | C20: =C18-C19 -> 25922 | D20: =D18-D19 -> 41733 | E20: =E18-E19 -> 37037 | F20: =F18-F19 -> 39510 | G20: =G18-G19 -> 53394 | H20: =H18-H19 -> 45687 | I20: =I18-I19 -> 48351 | ... Q20: =Q18-Q19 -> 112010
A23: Shares Used - Basic (000s) | B23: 909461 | C23: 924258 | D23: 934818 | E23: 925331 | F23: 6085572 | G23: 5753421 | H23: 5470820 | I23: 5217242 | J23: 4955377 | K23: 4617834 | L23: 17352119 | M23: 16701272 | N23: 16215963 | O23: 15744231 | P23: 15343783 | Q23: 14948500
A24: Shares Used - Diluted (000s) | B24: 924712 | C24: 936645 | D24: 945355 | E24: 931662 | F24: 6122663 | G24: 5793069 | H24: 5500281 | I24: 5251692 | J24: 5000109 | K24: 4648913 | L24: 17528214 | M24: 16864919 | N24: 16325819 | O24: 15812547 | P24: 15408095 | Q24: 15004697
A25: Cash Dividends Declared per Share | B25: 0 | C25: 0 | D25: 0.38 | E25: 1.64 | F25: 1.82 | G25: 1.98 | H25: 2.18 | I25: 2.4 | J25: 0 | K25: 0 | L25: 0 | M25: 0 | N25: 0 | O25: 0 | P25: 0 | Q25: 0
A28: BALANCE SHEET
A29: Cash & Cash Equivalents (FY1992 source reports Cash + ST Investments combined) | B29: 11261 | C29: 9815 | D29: 10746 | E29: 14259 | F29: 13844 | G29: 21120 | H29: 20484 | I29: 20289 | J29: 25913 | K29: 48844 | L29: 38016 | M29: 34940 | N29: 23646 | O29: 29965 | P29: 29943 | Q29: 35934
A30: Short-Term Investments / Marketable Securities | B30: 14359 | C30: 16137 | D30: 18383 | E30: 26287 | F30: 11233 | G30: 20481 | H30: 46671 | I30: 53892 | J30: 40388 | K30: 51713 | L30: 52927 | M30: 27699 | N30: 24658 | O30: 31590 | P30: 35228 | Q30: 18763
A31: Accounts Receivable, Net | B31: 5510 | C31: 5369 | D31: 10930 | E31: 13102 | F31: 17460 | G31: 16849 | H31: 15754 | I31: 17874 | J31: 23186 | K31: 22926 | L31: 16120 | M31: 26278 | N31: 28184 | O31: 29508 | P31: 33410 | Q31: 39777
A32: Inventories | B32: 1051 | C32: 776 | D32: 791 | E32: 1764 | F32: 2111 | G32: 2349 | H32: 2132 | I32: 4855 | J32: 3956 | K32: 4106 | L32: 4061 | M32: 6580 | N32: 4946 | O32: 6331 | P32: 7286 | Q32: 5718
A33: Deferred Tax Assets | B33: 1636 | C33: 2014 | D33: 2583 | E33: 3453 | F33: 4318 | G33: 5546 | H33: 0 | I33: 0 | J33: 0 | K33: 0 | L33: 0 | M33: 0 | N33: 0 | O33: 0 | P33: 0 | Q33: 0
A34: Vendor Non-Trade Receivables | B34: 4414 | C34: 6348 | D34: 7762 | E34: 7539 | F34: 9759 | G34: 13494 | H34: 13545 | I34: 17799 | J34: 25809 | K34: 22878 | L34: 21325 | M34: 25228 | N34: 32748 | O34: 31477 | P34: 32833 | Q34: 33180
A35: Other Current Assets | B35: 3447 | C35: 4529 | D35: 6458 | E35: 6882 | F35: 9806 | G35: 9539 | H35: 8283 | I35: 13936 | J35: 12087 | K35: 12352 | L35: 11264 | M35: 14111 | N35: 21223 | O35: 14695 | P35: 14287 | Q35: 14585
A36: Total Current Assets | B36: =B29+B30+B31+B32+B33+B34+B35 -> 41678 | C36: =C29+C30+C31+C32+C33+C34+C35 -> 44988 | D36: =D29+D30+D31+D32+D33+D34+D35 -> 57653 | E36: =E29+E30+E31+E32+E33+E34+E35 -> 73286 | F36: =F29+F30+F31+F32+F33+F34+F35 -> 68531 | G36: =G29+G30+G31+G32+G33+G34+G35 -> 89378 | H36: =H29+H30+H31+H32+H33+H34+H35 -> 106869 | I36: =I29+I30+I31+I32+I33+I34+I35 -> 128645 | ... Q36: =Q29+Q30+Q31+Q32+Q33+Q34+Q35 -> 147957
A38: Property, Plant & Equipment, Net | B38: 4768 | C38: 7777 | D38: 15452 | E38: 16597 | F38: 20624 | G38: 22471 | H38: 27010 | I38: 33783 | J38: 41304 | K38: 37378 | L38: 36766 | M38: 39440 | N38: 42117 | O38: 43715 | P38: 45680 | Q38: 49834
A39: Long-Term Marketable Securities | B39: 25391 | C39: 55618 | D39: 92122 | E39: 106215 | F39: 130162 | G39: 164065 | H39: 170430 | I39: 194714 | J39: 170799 | K39: 105341 | L39: 100887 | M39: 127877 | N39: 120805 | O39: 100544 | P39: 91479 | Q39: 77723
A40: Goodwill | B40: 741 | C40: 896 | D40: 1135 | E40: 1577 | F40: 4616 | G40: 5116 | H40: 5414 | I40: 5717 | J40: 0 | K40: 0 | L40: 0 | M40: 0 | N40: 0 | O40: 0 | P40: 0 | Q40: 0
A41: Acquired Intangible Assets, Net | B41: 342 | C41: 3536 | D41: 4224 | E41: 4179 | F41: 4142 | G41: 3893 | H41: 3206 | I41: 2298 | J41: 0 | K41: 0 | L41: 0 | M41: 0 | N41: 0 | O41: 0 | P41: 0 | Q41: 0
A42: Other Assets (legacy) | B42: 2263 | C42: 3556 | D42: 5478 | E42: 5146 | F42: 3764 | G42: 5556 | H42: 8757 | I42: 10162 | J42: 0 | K42: 0 | L42: 0 | M42: 0 | N42: 0 | O42: 0 | P42: 0 | Q42: 0
A43: Other Non-Current Assets | B43: 0 | C43: 0 | D43: 0 | E43: 0 | F43: 0 | G43: 0 | H43: 0 | I43: 0 | J43: 22283 | K43: 32978 | L43: 42522 | M43: 48849 | N43: 54428 | O43: 64758 | P43: 74834 | Q43: 83727
A44: Total Non-Current Assets | B44: =B38+B39+B40+B41+B42+B43 -> 33505 | C44: =C38+C39+C40+C41+C42+C43 -> 71383 | D44: =D38+D39+D40+D41+D42+D43 -> 118411 | E44: =E38+E39+E40+E41+E42+E43 -> 133714 | F44: =F38+F39+F40+F41+F42+F43 -> 163308 | G44: =G38+G39+G40+G41+G42+G43 -> 201101 | H44: =H38+H39+H40+H41+H42+H43 -> 214817 | I44: =I38+I39+I40+I41+I42+I43 -> 246674 | ... Q44: =Q38+Q39+Q40+Q41+Q42+Q43 -> 211284
A45: Total Assets | B45: =B36+B44 -> 75183 | C45: =C36+C44 -> 116371 | D45: =D36+D44 -> 176064 | E45: =E36+E44 -> 207000 | F45: =F36+F44 -> 231839 | G45: =G36+G44 -> 290479 | H45: =H36+H44 -> 321686 | I45: =I36+I44 -> 375319 | ... Q45: =Q36+Q44 -> 359241
A47: Short-Term Borrowings / Notes Payable | B47: 0 | C47: 0 | D47: 0 | E47: 0 | F47: 0 | G47: 0 | H47: 0 | I47: 0 | J47: 0 | K47: 0 | L47: 0 | M47: 0 | N47: 0 | O47: 0 | P47: 0 | Q47: 0
A48: Accounts Payable | B48: 12015 | C48: 14632 | D48: 21175 | E48: 22367 | F48: 30196 | G48: 35490 | H48: 37294 | I48: 49049 | J48: 55888 | K48: 46236 | L48: 42296 | M48: 54763 | N48: 64115 | O48: 62611 | P48: 68960 | Q48: 69860
A49: Accrued Expenses | B49: 5723 | C49: 9247 | D49: 11414 | E49: 13856 | F49: 18453 | G49: 25181 | H49: 22027 | I49: 25744 | J49: 0 | K49: 0 | L49: 0 | M49: 0 | N49: 0 | O49: 0 | P49: 0 | Q49: 0
A50: Deferred Revenue - Current | B50: 2984 | C50: 4091 | D50: 5953 | E50: 7435 | F50: 8491 | G50: 8940 | H50: 8080 | I50: 7548 | J50: 7543 | K50: 5522 | L50: 6643 | M50: 7612 | N50: 7912 | O50: 8061 | P50: 8249 | Q50: 9055
A51: Other Current Liabilities | B51: 0 | C51: 0 | D51: 0 | E51: 0 | F51: 0 | G51: 0 | H51: 0 | I51: 0 | J51: 32687 | K51: 37720 | L51: 42684 | M51: 47493 | N51: 60845 | O51: 58829 | P51: 78304 | Q51: 66387
...

Sheet Investment Ratios
A1: Fiscal Year | B1: 2010 | C1: 2011 | D1: 2012 | E1: 2013 | F1: 2014 | G1: 2015 | H1: 2016 | I1: 2017 | J1: 2018 | K1: 2019 | L1: 2020 | M1: 2021 | N1: 2022 | O1: 2023 | P1: 2024 | Q1: 2025
A3: INCOME STATEMENT
A4: Net Sales / Revenue | B4: 65225 | C4: 108249 | D4: 156508 | E4: 170910 | F4: 182795 | G4: 233715 | H4: 215639 | I4: 229234 | J4: 265595 | K4: 260174 | L4: 274515 | M4: 365817 | N4: 394328 | O4: 383285 | P4: 391035 | Q4: 416161
A5: Total COGS | B5: 39541 | C5: 64431 | D5: 87846 | E5: 106606 | F5: 112258 | G5: 140089 | H5: 131376 | I5: 141048 | J5: 163756 | K5: 161782 | L5: 169559 | M5: 212981 | N5: 223546 | O5: 214137 | P5: 210352 | Q5: 220960
A6: Gross Profit | B6: =B4-B5 -> 25684 | C6: =C4-C5 -> 43818 | D6: =D4-D5 -> 68662 | E6: =E4-E5 -> 64304 | F6: =F4-F5 -> 70537 | G6: =G4-G5 -> 93626 | H6: =H4-H5 -> 84263 | I6: =I4-I5 -> 88186 | ... Q6: =Q4-Q5 -> 195201
A8: Research & Development | B8: 1782 | C8: 2429 | D8: 3381 | E8: 4475 | F8: 6041 | G8: 8067 | H8: 10045 | I8: 11581 | J8: 14236 | K8: 16217 | L8: 18752 | M8: 21914 | N8: 26251 | O8: 29915 | P8: 31370 | Q8: 34550
A9: Selling, General & Administrative | B9: 5517 | C9: 7599 | D9: 10040 | E9: 10830 | F9: 11993 | G9: 14329 | H9: 14194 | I9: 15261 | J9: 16705 | K9: 18245 | L9: 19916 | M9: 21973 | N9: 25094 | O9: 24932 | P9: 26097 | Q9: 27601
A10: Total Operating Expenses | B10: =B8+B9 -> 7299 | C10: =C8+C9 -> 10028 | D10: =D8+D9 -> 13421 | E10: =E8+E9 -> 15305 | F10: =F8+F9 -> 18034 | G10: =G8+G9 -> 22396 | H10: =H8+H9 -> 24239 | I10: =I8+I9 -> 26842 | ... Q10: =Q8+Q9 -> 62151
A11: Operating Income (EBIT) | B11: =B6-B10 -> 18385 | C11: =C6-C10 -> 33790 | D11: =D6-D10 -> 55241 | E11: =E6-E10 -> 48999 | F11: =F6-F10 -> 52503 | G11: =G6-G10 -> 71230 | H11: =H6-H10 -> 60024 | I11: =I6-I10 -> 61344 | ... Q11: =Q6-Q10 -> 133050
A12: % Growth | B12: =IFERROR(B11/#REF!-1,"") | C12: =IFERROR(C11/B11-1,"") -> 0.83791134 | D12: =IFERROR(D11/C11-1,"") -> 0.63483279 | E12: =IFERROR(E11/D11-1,"") -> -0.11299578 | F12: =IFERROR(F11/E11-1,"") -> 0.071511664 | G12: =IFERROR(G11/F11-1,"") -> 0.35668438 | H12: =IFERROR(H11/G11-1,"") -> -0.15732135 | I12: =IFERROR(I11/H11-1,"") -> 0.021991204 | J12: =IFERROR(J11/I11-1,"") -> 0.15574465 | ... Q12: =IFERROR(Q11/P11-1,"") -> 0.079811063
A14: Other Income/(Expense), Net | B14: 155 | C14: 415 | D14: 522 | E14: 1156 | F14: 980 | G14: 1285 | H14: 1348 | I14: 2745 | J14: 2005 | K14: 1807 | L14: 803 | M14: 258 | N14: -334 | O14: -565 | P14: 269 | Q14: -321
A15: Total Other Income/(Expense) | B15: =B14 -> 155 | C15: =C14 -> 415 | D15: =D14 -> 522 | E15: =E14 -> 1156 | F15: =F14 -> 980 | G15: =G14 -> 1285 | H15: =H14 -> 1348 | I15: =I14 -> 2745 | ... Q15: =Q14 -> -321
A18: Income Before Income Taxes | B18: =B11+B15 -> 18540 | C18: =C11+C15 -> 34205 | D18: =D11+D15 -> 55763 | E18: =E11+E15 -> 50155 | F18: =F11+F15 -> 53483 | G18: =G11+G15 -> 72515 | H18: =H11+H15 -> 61372 | I18: =I11+I15 -> 64089 | ... Q18: =Q11+Q15 -> 132729
A19: Provision for Income Taxes | B19: 4527 | C19: 8283 | D19: 14030 | E19: 13118 | F19: 13973 | G19: 19121 | H19: 15685 | I19: 15738 | J19: 13372 | K19: 10481 | L19: 9680 | M19: 14527 | N19: 19300 | O19: 16741 | P19: 29749 | Q19: 20719
A20: Net Income | B20: =B18-B19 -> 14013 | C20: =C18-C19 -> 25922 | D20: =D18-D19 -> 41733 | E20: =E18-E19 -> 37037 | F20: =F18-F19 -> 39510 | G20: =G18-G19 -> 53394 | H20: =H18-H19 -> 45687 | I20: =I18-I19 -> 48351 | ... Q20: =Q18-Q19 -> 112010
A23: Shares Used - Basic (000s) | B23: 909461 | C23: 924258 | D23: 934818 | E23: 925331 | F23: 6085572 | G23: 5753421 | H23: 5470820 | I23: 5217242 | J23: 4955377 | K23: 4617834 | L23: 17352119 | M23: 16701272 | N23: 16215963 | O23: 15744231 | P23: 15343783 | Q23: 14948500
A24: Shares Used - Diluted (000s) | B24: 924712 | C24: 936645 | D24: 945355 | E24: 931662 | F24: 6122663 | G24: 5793069 | H24: 5500281 | I24: 5251692 | J24: 5000109 | K24: 4648913 | L24: 17528214 | M24: 16864919 | N24: 16325819 | O24: 15812547 | P24: 15408095 | Q24: 15004697
A25: Cash Dividends Declared per Share | B25: 0 | C25: 0 | D25: 0.38 | E25: 1.64 | F25: 1.82 | G25: 1.98 | H25: 2.18 | I25: 2.4 | J25: 0 | K25: 0 | L25: 0 | M25: 0 | N25: 0 | O25: 0 | P25: 0 | Q25: 0
A28: BALANCE SHEET
A29: Cash & Cash Equivalents (FY1992 source reports Cash + ST Investments combined) | B29: 11261 | C29: 9815 | D29: 10746 | E29: 14259 | F29: 13844 | G29: 21120 | H29: 20484 | I29: 20289 | J29: 25913 | K29: 48844 | L29: 38016 | M29: 34940 | N29: 23646 | O29: 29965 | P29: 29943 | Q29: 35934
A30: Short-Term Investments / Marketable Securities | B30: 14359 | C30: 16137 | D30: 18383 | E30: 26287 | F30: 11233 | G30: 20481 | H30: 46671 | I30: 53892 | J30: 40388 | K30: 51713 | L30: 52927 | M30: 27699 | N30: 24658 | O30: 31590 | P30: 35228 | Q30: 18763
A31: Accounts Receivable, Net | B31: 5510 | C31: 5369 | D31: 10930 | E31: 13102 | F31: 17460 | G31: 16849 | H31: 15754 | I31: 17874 | J31: 23186 | K31: 22926 | L31: 16120 | M31: 26278 | N31: 28184 | O31: 29508 | P31: 33410 | Q31: 39777
A32: Inventories | B32: 1051 | C32: 776 | D32: 791 | E32: 1764 | F32: 2111 | G32: 2349 | H32: 2132 | I32: 4855 | J32: 3956 | K32: 4106 | L32: 4061 | M32: 6580 | N32: 4946 | O32: 6331 | P32: 7286 | Q32: 5718
A33: Deferred Tax Assets | B33: 1636 | C33: 2014 | D33: 2583 | E33: 3453 | F33: 4318 | G33: 5546 | H33: 0 | I33: 0 | J33: 0 | K33: 0 | L33: 0 | M33: 0 | N33: 0 | O33: 0 | P33: 0 | Q33: 0
A34: Vendor Non-Trade Receivables | B34: 4414 | C34: 6348 | D34: 7762 | E34: 7539 | F34: 9759 | G34: 13494 | H34: 13545 | I34: 17799 | J34: 25809 | K34: 22878 | L34: 21325 | M34: 25228 | N34: 32748 | O34: 31477 | P34: 32833 | Q34: 33180
A35: Other Current Assets | B35: 3447 | C35: 4529 | D35: 6458 | E35: 6882 | F35: 9806 | G35: 9539 | H35: 8283 | I35: 13936 | J35: 12087 | K35: 12352 | L35: 11264 | M35: 14111 | N35: 21223 | O35: 14695 | P35: 14287 | Q35: 14585
A36: Total Current Assets | B36: =B29+B30+B31+B32+B33+B34+B35 -> 41678 | C36: =C29+C30+C31+C32+C33+C34+C35 -> 44988 | D36: =D29+D30+D31+D32+D33+D34+D35 -> 57653 | E36: =E29+E30+E31+E32+E33+E34+E35 -> 73286 | F36: =F29+F30+F31+F32+F33+F34+F35 -> 68531 | G36: =G29+G30+G31+G32+G33+G34+G35 -> 89378 | H36: =H29+H30+H31+H32+H33+H34+H35 -> 106869 | I36: =I29+I30+I31+I32+I33+I34+I35 -> 128645 | ... Q36: =Q29+Q30+Q31+Q32+Q33+Q34+Q35 -> 147957
A38: Property, Plant & Equipment, Net | B38: 4768 | C38: 7777 | D38: 15452 | E38: 16597 | F38: 20624 | G38: 22471 | H38: 27010 | I38: 33783 | J38: 41304 | K38: 37378 | L38: 36766 | M38: 39440 | N38: 42117 | O38: 43715 | P38: 45680 | Q38: 49834
A39: Long-Term Marketable Securities | B39: 25391 | C39: 55618 | D39: 92122 | E39: 106215 | F39: 130162 | G39: 164065 | H39: 170430 | I39: 194714 | J39: 170799 | K39: 105341 | L39: 100887 | M39: 127877 | N39: 120805 | O39: 100544 | P39: 91479 | Q39: 77723
A40: Goodwill | B40: 741 | C40: 896 | D40: 1135 | E40: 1577 | F40: 4616 | G40: 5116 | H40: 5414 | I40: 5717 | J40: 0 | K40: 0 | L40: 0 | M40: 0 | N40: 0 | O40: 0 | P40: 0 | Q40: 0
A41: Acquired Intangible Assets, Net | B41: 342 | C41: 3536 | D41: 4224 | E41: 4179 | F41: 4142 | G41: 3893 | H41: 3206 | I41: 2298 | J41: 0 | K41: 0 | L41: 0 | M41: 0 | N41: 0 | O41: 0 | P41: 0 | Q41: 0
A42: Other Assets (legacy) | B42: 2263 | C42: 3556 | D42: 5478 | E42: 5146 | F42: 3764 | G42: 5556 | H42: 8757 | I42: 10162 | J42: 0 | K42: 0 | L42: 0 | M42: 0 | N42: 0 | O42: 0 | P42: 0 | Q42: 0
A43: Other Non-Current Assets | B43: 0 | C43: 0 | D43: 0 | E43: 0 | F43: 0 | G43: 0 | H43: 0 | I43: 0 | J43: 22283 | K43: 32978 | L43: 42522 | M43: 48849 | N43: 54428 | O43: 64758 | P43: 74834 | Q43: 83727
A44: Total Non-Current Assets | B44: =B38+B39+B40+B41+B42+B43 -> 33505 | C44: =C38+C39+C40+C41+C42+C43 -> 71383 | D44: =D38+D39+D40+D41+D42+D43 -> 118411 | E44: =E38+E39+E40+E41+E42+E43 -> 133714 | F44: =F38+F39+F40+F41+F42+F43 -> 163308 | G44: =G38+G39+G40+G41+G42+G43 -> 201101 | H44: =H38+H39+H40+H41+H42+H43 -> 214817 | I44: =I38+I39+I40+I41+I42+I43 -> 246674 | ... Q44: =Q38+Q39+Q40+Q41+Q42+Q43 -> 211284
A45: Total Assets | B45: =B36+B44 -> 75183 | C45: =C36+C44 -> 116371 | D45: =D36+D44 -> 176064 | E45: =E36+E44 -> 207000 | F45: =F36+F44 -> 231839 | G45: =G36+G44 -> 290479 | H45: =H36+H44 -> 321686 | I45: =I36+I44 -> 375319 | ... Q45: =Q36+Q44 -> 359241
A47: Short-Term Borrowings / Notes Payable | B47: 0 | C47: 0 | D47: 0 | E47: 0 | F47: 0 | G47: 0 | H47: 0 | I47: 0 | J47: 0 | K47: 0 | L47: 0 | M47: 0 | N47: 0 | O47: 0 | P47: 0 | Q47: 0
A48: Accounts Payable | B48: 12015 | C48: 14632 | D48: 21175 | E48: 22367 | F48: 30196 | G48: 35490 | H48: 37294 | I48: 49049 | J48: 55888 | K48: 46236 | L48: 42296 | M48: 54763 | N48: 64115 | O48: 62611 | P48: 68960 | Q48: 69860
A49: Accrued Expenses | B49: 5723 | C49: 9247 | D49: 11414 | E49: 13856 | F49: 18453 | G49: 25181 | H49: 22027 | I49: 25744 | J49: 0 | K49: 0 | L49: 0 | M49: 0 | N49: 0 | O49: 0 | P49: 0 | Q49: 0
A50: Deferred Revenue - Current | B50: 2984 | C50: 4091 | D50: 5953 | E50: 7435 | F50: 8491 | G50: 8940 | H50: 8080 | I50: 7548 | J50: 7543 | K50: 5522 | L50: 6643 | M50: 7612 | N50: 7912 | O50: 8061 | P50: 8249 | Q50: 9055
A51: Other Current Liabilities | B51: 0 | C51: 0 | D51: 0 | E51: 0 | F51: 0 | G51: 0 | H51: 0 | I51: 0 | J51: 32687 | K51: 37720 | L51: 42684 | M51: 47493 | N51: 60845 | O51: 58829 | P51: 78304 | Q51: 66387
...
